{
    "registryname": "core",
    "localizedname": "§b核心构造器",
    "failure-action": "decrease",
    "requires-blueprint": false,
    "color": "000000",
    "parts": [
        {
            "x": 0,
            "y": 1,
            "z": 0,
            "elements": [
                "minecraft:carpet@7"
            ]
        },
        {
            "x": 1,
            "y": 0,
            "z": 0,
            "elements": [
                "minecraft:carpet@7"
            ]
        },
        {
            "x": -1,
            "y": 0,
            "z": 0,
            "elements": [
                "minecraft:carpet@7"
            ]
        },
        {
            "x": 0,
            "y": 0,
            "z": 1,
            "elements": [
                "minecraft:carpet@7"
            ]
        },
        {
            "x": 0,
            "y": 0,
            "z": -1,
            "elements": [
                "minecraft:carpet@7"
            ]
        },
        {
            "x": -3,
            "y": 6,
            "z": 7,
            "elements": [
                "compactmachines3:wall@0"
            ]
        },
        {
            "x": 0,
            "y": -2,
            "z": 0,
            "elements": [
                "modularmachinery:blockoutputbus",
                "modularmachinery:blockmeitemoutputbus"
            ]
        },
        {
            "x": 3,
            "y": 6,
            "z": -4,
            "elements": [
                "compactmachines3:wall@0"
            ]
        },
        {
            "x": 2,
            "y": -1,
            "z": -5,
            "elements": [
                "compactmachines3:wallbreakable@0"
            ]
        },
        {
            "x": -7,
            "y": -5,
            "z": -7,
            "elements": [
                "compactmachines3:wall@0"
            ]
        },
        {
            "x": 6,
            "y": 4,
            "z": 7,
            "elements": [
                "compactmachines3:wall@0"
            ]
        },
        {
            "x": 2,
            "y": -7,
            "z": -7,
            "elements": [
                "compactmachines3:wall@0"
            ]
        },
        {
            "x": -7,
            "y": -5,
            "z": 4,
            "elements": [
                "compactmachines3:wall@0"
            ]
        },
        {
            "x": -2,
            "y": 4,
            "z": 0,
            "elements": [
                "compactmachines3:wallbreakable@0"
            ]
        },
        {
            "x": 7,
            "y": 4,
            "z": 2,
            "elements": [
                "compactmachines3:wall@0"
            ]
        },
        {
            "x": -5,
            "y": 6,
            "z": 5,
            "elements": [
                "compactmachines3:wall@0"
            ]
        },
        {
            "x": -3,
            "y": 6,
            "z": 0,
            "elements": [
                "compactmachines3:wall@0"
            ]
        },
        {
            "x": -7,
            "y": -6,
            "z": -7,
            "elements": [
                "compactmachines3:wall@0"
            ]
        },
        {
            "x": -6,
            "y": 1,
            "z": -1,
            "elements": [
                "compactmachines3:wallbreakable@0"
            ]
        },
        {
            "x": 2,
            "y": -6,
            "z": 0,
            "elements": [
                "compactmachines3:wallbreakable@0"
            ]
        },
        {
            "x": 3,
            "y": -8,
            "z": 0,
            "elements": [
                "compactmachines3:wall@0"
            ]
        },
        {
            "x": 6,
            "y": 5,
            "z": 7,
            "elements": [
                "compactmachines3:wall@0"
            ]
        },
        {
            "x": 2,
            "y": -8,
            "z": -7,
            "elements": [
                "compactmachines3:wall@0"
            ]
        },
        {
            "x": 1,
            "y": -8,
            "z": 5,
            "elements": [
                "compactmachines3:wall@0"
            ]
        },
        {
            "x": -4,
            "y": -8,
            "z": -4,
            "elements": [
                "compactmachines3:wall@0"
            ]
        },
        {
            "x": -7,
            "y": -6,
            "z": -4,
            "elements": [
                "compactmachines3:wall@0"
            ]
        },
        {
            "x": 7,
            "y": 5,
            "z": 2,
            "elements": [
                "compactmachines3:wall@0"
            ]
        },
        {
            "x": 6,
            "y": 6,
            "z": 3,
            "elements": [
                "compactmachines3:wall@0"
            ]
        },
        {
            "x": -7,
            "y": -7,
            "z": -3,
            "elements": [
                "compactmachines3:wall@0"
            ]
        },
        {
            "x": 7,
            "y": 6,
            "z": 2,
            "elements": [
                "compactmachines3:wall@0"
            ]
        },
        {
            "x": -2,
            "y": 2,
            "z": 0,
            "elements": [
                "compactmachines3:wallbreakable@0"
            ]
        },
        {
            "x": -7,
            "y": -5,
            "z": -3,
            "elements": [
                "compactmachines3:wall@0"
            ]
        },
        {
            "x": -2,
            "y": 0,
            "z": 5,
            "elements": [
                "compactmachines3:wallbreakable@0"
            ]
        },
        {
            "x": -4,
            "y": 6,
            "z": 5,
            "elements": [
                "compactmachines3:wall@0"
            ]
        },
        {
            "x": -4,
            "y": 6,
            "z": 0,
            "elements": [
                "compactmachines3:wall@0"
            ]
        },
        {
            "x": 6,
            "y": 2,
            "z": 7,
            "elements": [
                "compactmachines3:wall@0"
            ]
        },
        {
            "x": 5,
            "y": -3,
            "z": 1,
            "elements": [
                "compactmachines3:wallbreakable@0"
            ]
        },
        {
            "x": -7,
            "y": -3,
            "z": -7,
            "elements": [
                "compactmachines3:wall@0"
            ]
        },
        {
            "x": 1,
            "y": -3,
            "z": -5,
            "elements": [
                "compactmachines3:wallbreakable@0"
            ]
        },
        {
            "x": 2,
            "y": -8,
            "z": 0,
            "elements": [
                "compactmachines3:wall@0"
            ]
        },
        {
            "x": -7,
            "y": -4,
            "z": -7,
            "elements": [
                "compactmachines3:wall@0"
            ]
        },
        {
            "x": 6,
            "y": 3,
            "z": 7,
            "elements": [
                "compactmachines3:wall@0"
            ]
        },
        {
            "x": 2,
            "y": -8,
            "z": 5,
            "elements": [
                "compactmachines3:wall@0"
            ]
        },
        {
            "x": -1,
            "y": -8,
            "z": -4,
            "elements": [
                "compactmachines3:wall@0"
            ]
        },
        {
            "x": -7,
            "y": -3,
            "z": 4,
            "elements": [
                "compactmachines3:wall@0"
            ]
        },
        {
            "x": -7,
            "y": -4,
            "z": -4,
            "elements": [
                "compactmachines3:wall@0"
            ]
        },
        {
            "x": -4,
            "y": -7,
            "z": -7,
            "elements": [
                "compactmachines3:wall@0"
            ]
        },
        {
            "x": 5,
            "y": 6,
            "z": -4,
            "elements": [
                "compactmachines3:wall@0"
            ]
        },
        {
            "x": 3,
            "y": 6,
            "z": 7,
            "elements": [
                "compactmachines3:wall@0"
            ]
        },
        {
            "x": -7,
            "y": -4,
            "z": -1,
            "elements": [
                "compactmachines3:wall@0"
            ]
        },
        {
            "x": -3,
            "y": 6,
            "z": 5,
            "elements": [
                "compactmachines3:wall@0"
            ]
        },
        {
            "x": 0,
            "y": 6,
            "z": 3,
            "elements": [
                "compactmachines3:wall@0"
            ]
        },
        {
            "x": 0,
            "y": 1,
            "z": -5,
            "elements": [
                "compactmachines3:wallbreakable@0"
            ]
        },
        {
            "x": -7,
            "y": -2,
            "z": -4,
            "elements": [
                "compactmachines3:wall@0"
            ]
        },
        {
            "x": -3,
            "y": -8,
            "z": 3,
            "elements": [
                "compactmachines3:wall@0"
            ]
        },
        {
            "x": -7,
            "y": -3,
            "z": 1,
            "elements": [
                "compactmachines3:wall@0"
            ]
        },
        {
            "x": -5,
            "y": 6,
            "z": 0,
            "elements": [
                "compactmachines3:wall@0"
            ]
        },
        {
            "x": -4,
            "y": -8,
            "z": -7,
            "elements": [
                "compactmachines3:wall@0"
            ]
        },
        {
            "x": -7,
            "y": -4,
            "z": 1,
            "elements": [
                "compactmachines3:wall@0"
            ]
        },
        {
            "x": -7,
            "y": -3,
            "z": -1,
            "elements": [
                "compactmachines3:wall@0"
            ]
        },
        {
            "x": 3,
            "y": -8,
            "z": 5,
            "elements": [
                "compactmachines3:wall@0"
            ]
        },
        {
            "x": 1,
            "y": -8,
            "z": 0,
            "elements": [
                "compactmachines3:wall@0"
            ]
        },
        {
            "x": 6,
            "y": 6,
            "z": -4,
            "elements": [
                "compactmachines3:wall@0"
            ]
        },
        {
            "x": -6,
            "y": 6,
            "z": 5,
            "elements": [
                "compactmachines3:wall@0"
            ]
        },
        {
            "x": -7,
            "y": -7,
            "z": 4,
            "elements": [
                "compactmachines3:wall@0"
            ]
        },
        {
            "x": -7,
            "y": -2,
            "z": -1,
            "elements": [
                "compactmachines3:wall@0"
            ]
        },
        {
            "x": 6,
            "y": 1,
            "z": 1,
            "elements": [
                "compactmachines3:wallbreakable@0"
            ]
        },
        {
            "x": -7,
            "y": -1,
            "z": 1,
            "elements": [
                "compactmachines3:wall@0"
            ]
        },
        {
            "x": -7,
            "y": -1,
            "z": -1,
            "elements": [
                "compactmachines3:wall@0"
            ]
        },
        {
            "x": -7,
            "y": -8,
            "z": -7,
            "elements": [
                "compactmachines3:wall@0"
            ]
        },
        {
            "x": -1,
            "y": -3,
            "z": -5,
            "elements": [
                "compactmachines3:wallbreakable@0"
            ]
        },
        {
            "x": -2,
            "y": -4,
            "z": 0,
            "elements": [
                "compactmachines3:wallbreakable@0"
            ]
        },
        {
            "x": -2,
            "y": 6,
            "z": 0,
            "elements": [
                "compactmachines3:wall@0"
            ]
        },
        {
            "x": 4,
            "y": -8,
            "z": 0,
            "elements": [
                "compactmachines3:wall@0"
            ]
        },
        {
            "x": 0,
            "y": -8,
            "z": 5,
            "elements": [
                "compactmachines3:wall@0"
            ]
        },
        {
            "x": -3,
            "y": -8,
            "z": -4,
            "elements": [
                "compactmachines3:wall@0"
            ]
        },
        {
            "x": 6,
            "y": 1,
            "z": -1,
            "elements": [
                "compactmachines3:wallbreakable@0"
            ]
        },
        {
            "x": -7,
            "y": -2,
            "z": 1,
            "elements": [
                "compactmachines3:wall@0"
            ]
        },
        {
            "x": 6,
            "y": 6,
            "z": 7,
            "elements": [
                "compactmachines3:wall@0"
            ]
        },
        {
            "x": -7,
            "y": -7,
            "z": -7,
            "elements": [
                "compactmachines3:wall@0"
            ]
        },
        {
            "x": -7,
            "y": 0,
            "z": 5,
            "elements": [
                "compactmachines3:wall@0"
            ]
        },
        {
            "x": -4,
            "y": -8,
            "z": -6,
            "elements": [
                "compactmachines3:wall@0"
            ]
        },
        {
            "x": -7,
            "y": -8,
            "z": 1,
            "elements": [
                "compactmachines3:wall@0"
            ]
        },
        {
            "x": -7,
            "y": -3,
            "z": -6,
            "elements": [
                "compactmachines3:wall@0"
            ]
        },
        {
            "x": 5,
            "y": -1,
            "z": 7,
            "elements": [
                "compactmachines3:wall@0"
            ]
        },
        {
            "x": -1,
            "y": 6,
            "z": 5,
            "elements": [
                "compactmachines3:wall@0"
            ]
        },
        {
            "x": -6,
            "y": 0,
            "z": -7,
            "elements": [
                "compactmachines3:wall@0"
            ]
        },
        {
            "x": 2,
            "y": -1,
            "z": 4,
            "elements": [
                "compactmachines3:wallbreakable@0"
            ]
        },
        {
            "x": -7,
            "y": 6,
            "z": 0,
            "elements": [
                "compactmachines3:wall@0"
            ]
        },
        {
            "x": 2,
            "y": 4,
            "z": 0,
            "elements": [
                "compactmachines3:wallbreakable@0"
            ]
        },
        {
            "x": -4,
            "y": -3,
            "z": -7,
            "elements": [
                "compactmachines3:wall@0"
            ]
        },
        {
            "x": 7,
            "y": -8,
            "z": 0,
            "elements": [
                "compactmachines3:wall@0"
            ]
        },
        {
            "x": 3,
            "y": 2,
            "z": 7,
            "elements": [
                "compactmachines3:wall@0"
            ]
        },
        {
            "x": 5,
            "y": -2,
            "z": 7,
            "elements": [
                "compactmachines3:wall@0"
            ]
        },
        {
            "x": 0,
            "y": 1,
            "z": 4,
            "elements": [
                "compactmachines3:wallbreakable@0"
            ]
        },
        {
            "x": -3,
            "y": -8,
            "z": 5,
            "elements": [
                "compactmachines3:wall@0"
            ]
        },
        {
            "x": -6,
            "y": 1,
            "z": -7,
            "elements": [
                "compactmachines3:wall@0"
            ]
        },
        {
            "x": -7,
            "y": 2,
            "z": 5,
            "elements": [
                "compactmachines3:wall@0"
            ]
        },
        {
            "x": -7,
            "y": -7,
            "z": 1,
            "elements": [
                "compactmachines3:wall@0"
            ]
        },
        {
            "x": 6,
            "y": 6,
            "z": -1,
            "elements": [
                "compactmachines3:wall@0"
            ]
        },
        {
            "x": 7,
            "y": -1,
            "z": -3,
            "elements": [
                "compactmachines3:wall@0"
            ]
        },
        {
            "x": 3,
            "y": 6,
            "z": 6,
            "elements": [
                "compactmachines3:wall@0"
            ]
        },
        {
            "x": 3,
            "y": 3,
            "z": 7,
            "elements": [
                "compactmachines3:wall@0"
            ]
        },
        {
            "x": -4,
            "y": -4,
            "z": -7,
            "elements": [
                "compactmachines3:wall@0"
            ]
        },
        {
            "x": 3,
            "y": 4,
            "z": 7,
            "elements": [
                "compactmachines3:wall@0"
            ]
        },
        {
            "x": -4,
            "y": -5,
            "z": -7,
            "elements": [
                "compactmachines3:wall@0"
            ]
        },
        {
            "x": 0,
            "y": 6,
            "z": 7,
            "elements": [
                "compactmachines3:wall@0"
            ]
        },
        {
            "x": -1,
            "y": -7,
            "z": -7,
            "elements": [
                "compactmachines3:wall@0"
            ]
        },
        {
            "x": 0,
            "y": 6,
            "z": 5,
            "elements": [
                "compactmachines3:wall@0"
            ]
        },
        {
            "x": -4,
            "y": -8,
            "z": 1,
            "elements": [
                "compactmachines3:wall@0"
            ]
        },
        {
            "x": 2,
            "y": 2,
            "z": 0,
            "elements": [
                "compactmachines3:wallbreakable@0"
            ]
        },
        {
            "x": 3,
            "y": 6,
            "z": -1,
            "elements": [
                "compactmachines3:wall@0"
            ]
        },
        {
            "x": 7,
            "y": -6,
            "z": 0,
            "elements": [
                "compactmachines3:wall@0"
            ]
        },
        {
            "x": -7,
            "y": -5,
            "z": 1,
            "elements": [
                "compactmachines3:wall@0"
            ]
        },
        {
            "x": 6,
            "y": -8,
            "z": 0,
            "elements": [
                "compactmachines3:wall@0"
            ]
        },
        {
            "x": 2,
            "y": 0,
            "z": 5,
            "elements": [
                "compactmachines3:wallbreakable@0"
            ]
        },
        {
            "x": -1,
            "y": -8,
            "z": -7,
            "elements": [
                "compactmachines3:wall@0"
            ]
        },
        {
            "x": 3,
            "y": 5,
            "z": 7,
            "elements": [
                "compactmachines3:wall@0"
            ]
        },
        {
            "x": -2,
            "y": -8,
            "z": 5,
            "elements": [
                "compactmachines3:wall@0"
            ]
        },
        {
            "x": -4,
            "y": -6,
            "z": -7,
            "elements": [
                "compactmachines3:wall@0"
            ]
        },
        {
            "x": -7,
            "y": -6,
            "z": 1,
            "elements": [
                "compactmachines3:wall@0"
            ]
        },
        {
            "x": 7,
            "y": -3,
            "z": -3,
            "elements": [
                "compactmachines3:wall@0"
            ]
        },
        {
            "x": 0,
            "y": 5,
            "z": 7,
            "elements": [
                "compactmachines3:wall@0"
            ]
        },
        {
            "x": 0,
            "y": 4,
            "z": 7,
            "elements": [
                "compactmachines3:wall@0"
            ]
        },
        {
            "x": 6,
            "y": 1,
            "z": 7,
            "elements": [
                "compactmachines3:wall@0"
            ]
        },
        {
            "x": 6,
            "y": 0,
            "z": 7,
            "elements": [
                "compactmachines3:wall@0"
            ]
        },
        {
            "x": 7,
            "y": -4,
            "z": 0,
            "elements": [
                "compactmachines3:wall@0"
            ]
        },
        {
            "x": 3,
            "y": 0,
            "z": 7,
            "elements": [
                "compactmachines3:wall@0"
            ]
        },
        {
            "x": 2,
            "y": -1,
            "z": 7,
            "elements": [
                "compactmachines3:wall@0"
            ]
        },
        {
            "x": 5,
            "y": -5,
            "z": 7,
            "elements": [
                "compactmachines3:wall@0"
            ]
        },
        {
            "x": -7,
            "y": 6,
            "z": 5,
            "elements": [
                "compactmachines3:wall@0"
            ]
        },
        {
            "x": -7,
            "y": -1,
            "z": -7,
            "elements": [
                "compactmachines3:wall@0"
            ]
        },
        {
            "x": -6,
            "y": 4,
            "z": -7,
            "elements": [
                "compactmachines3:wall@0"
            ]
        },
        {
            "x": -7,
            "y": -3,
            "z": -3,
            "elements": [
                "compactmachines3:wall@0"
            ]
        },
        {
            "x": 5,
            "y": -3,
            "z": 7,
            "elements": [
                "compactmachines3:wall@0"
            ]
        },
        {
            "x": 5,
            "y": -6,
            "z": 7,
            "elements": [
                "compactmachines3:wall@0"
            ]
        },
        {
            "x": 5,
            "y": -3,
            "z": -1,
            "elements": [
                "compactmachines3:wallbreakable@0"
            ]
        },
        {
            "x": 0,
            "y": 6,
            "z": -1,
            "elements": [
                "compactmachines3:wall@0"
            ]
        },
        {
            "x": -7,
            "y": -1,
            "z": 4,
            "elements": [
                "compactmachines3:wall@0"
            ]
        },
        {
            "x": -1,
            "y": -5,
            "z": -7,
            "elements": [
                "compactmachines3:wall@0"
            ]
        },
        {
            "x": -1,
            "y": 6,
            "z": 0,
            "elements": [
                "compactmachines3:wall@0"
            ]
        },
        {
            "x": 2,
            "y": -8,
            "z": -4,
            "elements": [
                "compactmachines3:wall@0"
            ]
        },
        {
            "x": -7,
            "y": -1,
            "z": -3,
            "elements": [
                "compactmachines3:wall@0"
            ]
        },
        {
            "x": 0,
            "y": -3,
            "z": -5,
            "elements": [
                "compactmachines3:wallbreakable@0"
            ]
        },
        {
            "x": -6,
            "y": -8,
            "z": 3,
            "elements": [
                "compactmachines3:wall@0"
            ]
        },
        {
            "x": 7,
            "y": -8,
            "z": 5,
            "elements": [
                "compactmachines3:wall@0"
            ]
        },
        {
            "x": -1,
            "y": -6,
            "z": -7,
            "elements": [
                "compactmachines3:wall@0"
            ]
        },
        {
            "x": -4,
            "y": -1,
            "z": -7,
            "elements": [
                "compactmachines3:wall@0"
            ]
        },
        {
            "x": -1,
            "y": -8,
            "z": 1,
            "elements": [
                "compactmachines3:wall@0"
            ]
        },
        {
            "x": 3,
            "y": 1,
            "z": -1,
            "elements": [
                "compactmachines3:wallbreakable@0"
            ]
        },
        {
            "x": -3,
            "y": -8,
            "z": 0,
            "elements": [
                "compactmachines3:wall@0"
            ]
        },
        {
            "x": -6,
            "y": 5,
            "z": -7,
            "elements": [
                "compactmachines3:wall@0"
            ]
        },
        {
            "x": 7,
            "y": 1,
            "z": -5,
            "elements": [
                "compactmachines3:wall@0"
            ]
        },
        {
            "x": -7,
            "y": -2,
            "z": -7,
            "elements": [
                "compactmachines3:wall@0"
            ]
        },
        {
            "x": -2,
            "y": -2,
            "z": 5,
            "elements": [
                "compactmachines3:wallbreakable@0"
            ]
        },
        {
            "x": 3,
            "y": 6,
            "z": 3,
            "elements": [
                "compactmachines3:wall@0"
            ]
        },
        {
            "x": -7,
            "y": -1,
            "z": -6,
            "elements": [
                "compactmachines3:wall@0"
            ]
        },
        {
            "x": 1,
            "y": 1,
            "z": -5,
            "elements": [
                "compactmachines3:wallbreakable@0"
            ]
        },
        {
            "x": -3,
            "y": 0,
            "z": -7,
            "elements": [
                "compactmachines3:wall@0"
            ]
        },
        {
            "x": -6,
            "y": 2,
            "z": -7,
            "elements": [
                "compactmachines3:wall@0"
            ]
        },
        {
            "x": 0,
            "y": 2,
            "z": 7,
            "elements": [
                "compactmachines3:wall@0"
            ]
        },
        {
            "x": -1,
            "y": -3,
            "z": -7,
            "elements": [
                "compactmachines3:wall@0"
            ]
        },
        {
            "x": -4,
            "y": -3,
            "z": 1,
            "elements": [
                "compactmachines3:wallbreakable@0"
            ]
        },
        {
            "x": 2,
            "y": -2,
            "z": 7,
            "elements": [
                "compactmachines3:wall@0"
            ]
        },
        {
            "x": -7,
            "y": 4,
            "z": 5,
            "elements": [
                "compactmachines3:wall@0"
            ]
        },
        {
            "x": -1,
            "y": -8,
            "z": -6,
            "elements": [
                "compactmachines3:wall@0"
            ]
        },
        {
            "x": -6,
            "y": 1,
            "z": 1,
            "elements": [
                "compactmachines3:wallbreakable@0"
            ]
        },
        {
            "x": -7,
            "y": -2,
            "z": -6,
            "elements": [
                "compactmachines3:wall@0"
            ]
        },
        {
            "x": -3,
            "y": 1,
            "z": -7,
            "elements": [
                "compactmachines3:wall@0"
            ]
        },
        {
            "x": 2,
            "y": 6,
            "z": 0,
            "elements": [
                "compactmachines3:wall@0"
            ]
        },
        {
            "x": 0,
            "y": 3,
            "z": 7,
            "elements": [
                "compactmachines3:wall@0"
            ]
        },
        {
            "x": 3,
            "y": 1,
            "z": 7,
            "elements": [
                "compactmachines3:wall@0"
            ]
        },
        {
            "x": 0,
            "y": -8,
            "z": 0,
            "elements": [
                "compactmachines3:wall@0"
            ]
        },
        {
            "x": -4,
            "y": -2,
            "z": -7,
            "elements": [
                "compactmachines3:wall@0"
            ]
        },
        {
            "x": 4,
            "y": -8,
            "z": 5,
            "elements": [
                "compactmachines3:wall@0"
            ]
        },
        {
            "x": 5,
            "y": -4,
            "z": 7,
            "elements": [
                "compactmachines3:wall@0"
            ]
        },
        {
            "x": -1,
            "y": -4,
            "z": -7,
            "elements": [
                "compactmachines3:wall@0"
            ]
        },
        {
            "x": -6,
            "y": 3,
            "z": -7,
            "elements": [
                "compactmachines3:wall@0"
            ]
        },
        {
            "x": -6,
            "y": 6,
            "z": -4,
            "elements": [
                "compactmachines3:wall@0"
            ]
        },
        {
            "x": 0,
            "y": 6,
            "z": 6,
            "elements": [
                "compactmachines3:wall@0"
            ]
        },
        {
            "x": 7,
            "y": -6,
            "z": 5,
            "elements": [
                "compactmachines3:wall@0"
            ]
        },
        {
            "x": 3,
            "y": 6,
            "z": 5,
            "elements": [
                "compactmachines3:wall@0"
            ]
        },
        {
            "x": -7,
            "y": -4,
            "z": 3,
            "elements": [
                "compactmachines3:wall@0"
            ]
        },
        {
            "x": -2,
            "y": 6,
            "z": 3,
            "elements": [
                "compactmachines3:wall@0"
            ]
        },
        {
            "x": -7,
            "y": 3,
            "z": 4,
            "elements": [
                "compactmachines3:wall@0"
            ]
        },
        {
            "x": -1,
            "y": -8,
            "z": 3,
            "elements": [
                "compactmachines3:wall@0"
            ]
        },
        {
            "x": 7,
            "y": 2,
            "z": 0,
            "elements": [
                "compactmachines3:wall@0"
            ]
        },
        {
            "x": -7,
            "y": -8,
            "z": 5,
            "elements": [
                "compactmachines3:wall@0"
            ]
        },
        {
            "x": -7,
            "y": 1,
            "z": -3,
            "elements": [
                "compactmachines3:wall@0"
            ]
        },
        {
            "x": 4,
            "y": -8,
            "z": -4,
            "elements": [
                "compactmachines3:wall@0"
            ]
        },
        {
            "x": -4,
            "y": -8,
            "z": 3,
            "elements": [
                "compactmachines3:wall@0"
            ]
        },
        {
            "x": -5,
            "y": -8,
            "z": 0,
            "elements": [
                "compactmachines3:wall@0"
            ]
        },
        {
            "x": -7,
            "y": 0,
            "z": 0,
            "elements": [
                "compactmachines3:wall@0"
            ]
        },
        {
            "x": -5,
            "y": 6,
            "z": -4,
            "elements": [
                "compactmachines3:wall@0"
            ]
        },
        {
            "x": 7,
            "y": -2,
            "z": 0,
            "elements": [
                "compactmachines3:wall@0"
            ]
        },
        {
            "x": 7,
            "y": -4,
            "z": 5,
            "elements": [
                "compactmachines3:wall@0"
            ]
        },
        {
            "x": -7,
            "y": 5,
            "z": 4,
            "elements": [
                "compactmachines3:wall@0"
            ]
        },
        {
            "x": 1,
            "y": 6,
            "z": 3,
            "elements": [
                "compactmachines3:wall@0"
            ]
        },
        {
            "x": -7,
            "y": -2,
            "z": 3,
            "elements": [
                "compactmachines3:wall@0"
            ]
        },
        {
            "x": 0,
            "y": 6,
            "z": -4,
            "elements": [
                "compactmachines3:wall@0"
            ]
        },
        {
            "x": -1,
            "y": 1,
            "z": 4,
            "elements": [
                "compactmachines3:wallbreakable@0"
            ]
        },
        {
            "x": -7,
            "y": -3,
            "z": -5,
            "elements": [
                "compactmachines3:wall@0"
            ]
        },
        {
            "x": 7,
            "y": -8,
            "z": -4,
            "elements": [
                "compactmachines3:wall@0"
            ]
        },
        {
            "x": 1,
            "y": -3,
            "z": 4,
            "elements": [
                "compactmachines3:wallbreakable@0"
            ]
        },
        {
            "x": 7,
            "y": 4,
            "z": 0,
            "elements": [
                "compactmachines3:wall@0"
            ]
        },
        {
            "x": -7,
            "y": -1,
            "z": -5,
            "elements": [
                "compactmachines3:wall@0"
            ]
        },
        {
            "x": 4,
            "y": 6,
            "z": 0,
            "elements": [
                "compactmachines3:wall@0"
            ]
        },
        {
            "x": -2,
            "y": -1,
            "z": -3,
            "elements": [
                "compactmachines3:wallbreakable@0"
            ]
        },
        {
            "x": 7,
            "y": 6,
            "z": -6,
            "elements": [
                "compactmachines3:wall@0"
            ]
        },
        {
            "x": -7,
            "y": 3,
            "z": -3,
            "elements": [
                "compactmachines3:wall@0"
            ]
        },
        {
            "x": 5,
            "y": -8,
            "z": 3,
            "elements": [
                "compactmachines3:wall@0"
            ]
        },
        {
            "x": -7,
            "y": 5,
            "z": -3,
            "elements": [
                "compactmachines3:wall@0"
            ]
        },
        {
            "x": 6,
            "y": -8,
            "z": -4,
            "elements": [
                "compactmachines3:wall@0"
            ]
        },
        {
            "x": 7,
            "y": -7,
            "z": -3,
            "elements": [
                "compactmachines3:wall@0"
            ]
        },
        {
            "x": -7,
            "y": -6,
            "z": -6,
            "elements": [
                "compactmachines3:wall@0"
            ]
        },
        {
            "x": 7,
            "y": -2,
            "z": 5,
            "elements": [
                "compactmachines3:wall@0"
            ]
        },
        {
            "x": 0,
            "y": -3,
            "z": 4,
            "elements": [
                "compactmachines3:wallbreakable@0"
            ]
        },
        {
            "x": 7,
            "y": -5,
            "z": -3,
            "elements": [
                "compactmachines3:wall@0"
            ]
        },
        {
            "x": 2,
            "y": 0,
            "z": -4,
            "elements": [
                "compactmachines3:wallbreakable@0"
            ]
        },
        {
            "x": -3,
            "y": 6,
            "z": -4,
            "elements": [
                "compactmachines3:wall@0"
            ]
        },
        {
            "x": -7,
            "y": -5,
            "z": -6,
            "elements": [
                "compactmachines3:wall@0"
            ]
        },
        {
            "x": 6,
            "y": -8,
            "z": 3,
            "elements": [
                "compactmachines3:wall@0"
            ]
        },
        {
            "x": 2,
            "y": 6,
            "z": 5,
            "elements": [
                "compactmachines3:wall@0"
            ]
        },
        {
            "x": 2,
            "y": -2,
            "z": 5,
            "elements": [
                "compactmachines3:wallbreakable@0"
            ]
        },
        {
            "x": -7,
            "y": 4,
            "z": 0,
            "elements": [
                "compactmachines3:wall@0"
            ]
        },
        {
            "x": 7,
            "y": 0,
            "z": 0,
            "elements": [
                "compactmachines3:wall@0"
            ]
        },
        {
            "x": -7,
            "y": -4,
            "z": -6,
            "elements": [
                "compactmachines3:wall@0"
            ]
        },
        {
            "x": 2,
            "y": -2,
            "z": -4,
            "elements": [
                "compactmachines3:wallbreakable@0"
            ]
        },
        {
            "x": -1,
            "y": -3,
            "z": 4,
            "elements": [
                "compactmachines3:wallbreakable@0"
            ]
        },
        {
            "x": 5,
            "y": -8,
            "z": -4,
            "elements": [
                "compactmachines3:wall@0"
            ]
        },
        {
            "x": -2,
            "y": -1,
            "z": 4,
            "elements": [
                "compactmachines3:wallbreakable@0"
            ]
        },
        {
            "x": -2,
            "y": 6,
            "z": -4,
            "elements": [
                "compactmachines3:wall@0"
            ]
        },
        {
            "x": 5,
            "y": 6,
            "z": 5,
            "elements": [
                "compactmachines3:wall@0"
            ]
        },
        {
            "x": -7,
            "y": 2,
            "z": 0,
            "elements": [
                "compactmachines3:wall@0"
            ]
        },
        {
            "x": -1,
            "y": 6,
            "z": -4,
            "elements": [
                "compactmachines3:wall@0"
            ]
        },
        {
            "x": -6,
            "y": 6,
            "z": 3,
            "elements": [
                "compactmachines3:wall@0"
            ]
        },
        {
            "x": 3,
            "y": -8,
            "z": 3,
            "elements": [
                "compactmachines3:wall@0"
            ]
        },
        {
            "x": 1,
            "y": 6,
            "z": 0,
            "elements": [
                "compactmachines3:wall@0"
            ]
        },
        {
            "x": -2,
            "y": -6,
            "z": 0,
            "elements": [
                "compactmachines3:wallbreakable@0"
            ]
        },
        {
            "x": 0,
            "y": -8,
            "z": -4,
            "elements": [
                "compactmachines3:wall@0"
            ]
        },
        {
            "x": 5,
            "y": -8,
            "z": 5,
            "elements": [
                "compactmachines3:wall@0"
            ]
        },
        {
            "x": -7,
            "y": -7,
            "z": -1,
            "elements": [
                "compactmachines3:wall@0"
            ]
        },
        {
            "x": 6,
            "y": 6,
            "z": 1,
            "elements": [
                "compactmachines3:wall@0"
            ]
        },
        {
            "x": 2,
            "y": -2,
            "z": 3,
            "elements": [
                "compactmachines3:wallbreakable@0"
            ]
        },
        {
            "x": -7,
            "y": -8,
            "z": -6,
            "elements": [
                "compactmachines3:wall@0"
            ]
        },
        {
            "x": -3,
            "y": 6,
            "z": 3,
            "elements": [
                "compactmachines3:wall@0"
            ]
        },
        {
            "x": -7,
            "y": -6,
            "z": -1,
            "elements": [
                "compactmachines3:wall@0"
            ]
        },
        {
            "x": 0,
            "y": -8,
            "z": 3,
            "elements": [
                "compactmachines3:wall@0"
            ]
        },
        {
            "x": 6,
            "y": 6,
            "z": 6,
            "elements": [
                "compactmachines3:wall@0"
            ]
        },
        {
            "x": -7,
            "y": -4,
            "z": 2,
            "elements": [
                "compactmachines3:wall@0"
            ]
        },
        {
            "x": 3,
            "y": -8,
            "z": -4,
            "elements": [
                "compactmachines3:wall@0"
            ]
        },
        {
            "x": 7,
            "y": -2,
            "z": -4,
            "elements": [
                "compactmachines3:wall@0"
            ]
        },
        {
            "x": -7,
            "y": -7,
            "z": -6,
            "elements": [
                "compactmachines3:wall@0"
            ]
        },
        {
            "x": -1,
            "y": -3,
            "z": -3,
            "elements": [
                "compactmachines3:wallbreakable@0"
            ]
        },
        {
            "x": -2,
            "y": -8,
            "z": 0,
            "elements": [
                "compactmachines3:wall@0"
            ]
        },
        {
            "x": -7,
            "y": -8,
            "z": -1,
            "elements": [
                "compactmachines3:wall@0"
            ]
        },
        {
            "x": -4,
            "y": 6,
            "z": -4,
            "elements": [
                "compactmachines3:wall@0"
            ]
        },
        {
            "x": 2,
            "y": -1,
            "z": -3,
            "elements": [
                "compactmachines3:wallbreakable@0"
            ]
        },
        {
            "x": -7,
            "y": -2,
            "z": 5,
            "elements": [
                "compactmachines3:wall@0"
            ]
        },
        {
            "x": -7,
            "y": -5,
            "z": -1,
            "elements": [
                "compactmachines3:wall@0"
            ]
        },
        {
            "x": -7,
            "y": -5,
            "z": 2,
            "elements": [
                "compactmachines3:wall@0"
            ]
        },
        {
            "x": 7,
            "y": -6,
            "z": -4,
            "elements": [
                "compactmachines3:wall@0"
            ]
        },
        {
            "x": 3,
            "y": 6,
            "z": -2,
            "elements": [
                "compactmachines3:wall@0"
            ]
        },
        {
            "x": -4,
            "y": 6,
            "z": 3,
            "elements": [
                "compactmachines3:wall@0"
            ]
        },
        {
            "x": 1,
            "y": -8,
            "z": 3,
            "elements": [
                "compactmachines3:wall@0"
            ]
        },
        {
            "x": -1,
            "y": -8,
            "z": 5,
            "elements": [
                "compactmachines3:wall@0"
            ]
        },
        {
            "x": 0,
            "y": -3,
            "z": -3,
            "elements": [
                "compactmachines3:wallbreakable@0"
            ]
        },
        {
            "x": -7,
            "y": -6,
            "z": 2,
            "elements": [
                "compactmachines3:wall@0"
            ]
        },
        {
            "x": 7,
            "y": 6,
            "z": 0,
            "elements": [
                "compactmachines3:wall@0"
            ]
        },
        {
            "x": -4,
            "y": -8,
            "z": 2,
            "elements": [
                "compactmachines3:wall@0"
            ]
        },
        {
            "x": -7,
            "y": -4,
            "z": 5,
            "elements": [
                "compactmachines3:wall@0"
            ]
        },
        {
            "x": -2,
            "y": 0,
            "z": 3,
            "elements": [
                "compactmachines3:wallbreakable@0"
            ]
        },
        {
            "x": -7,
            "y": 6,
            "z": -4,
            "elements": [
                "compactmachines3:wall@0"
            ]
        },
        {
            "x": -7,
            "y": -3,
            "z": 2,
            "elements": [
                "compactmachines3:wall@0"
            ]
        },
        {
            "x": -1,
            "y": 1,
            "z": -3,
            "elements": [
                "compactmachines3:wallbreakable@0"
            ]
        },
        {
            "x": 2,
            "y": 6,
            "z": -4,
            "elements": [
                "compactmachines3:wall@0"
            ]
        },
        {
            "x": 1,
            "y": 1,
            "z": 4,
            "elements": [
                "compactmachines3:wallbreakable@0"
            ]
        },
        {
            "x": -7,
            "y": -2,
            "z": 2,
            "elements": [
                "compactmachines3:wall@0"
            ]
        },
        {
            "x": -7,
            "y": -7,
            "z": 2,
            "elements": [
                "compactmachines3:wall@0"
            ]
        },
        {
            "x": -2,
            "y": -2,
            "z": -4,
            "elements": [
                "compactmachines3:wallbreakable@0"
            ]
        },
        {
            "x": 6,
            "y": 6,
            "z": -2,
            "elements": [
                "compactmachines3:wall@0"
            ]
        },
        {
            "x": -5,
            "y": 6,
            "z": 3,
            "elements": [
                "compactmachines3:wall@0"
            ]
        },
        {
            "x": 2,
            "y": -8,
            "z": 3,
            "elements": [
                "compactmachines3:wall@0"
            ]
        },
        {
            "x": 7,
            "y": -4,
            "z": -4,
            "elements": [
                "compactmachines3:wall@0"
            ]
        },
        {
            "x": -2,
            "y": 0,
            "z": -4,
            "elements": [
                "compactmachines3:wallbreakable@0"
            ]
        },
        {
            "x": -4,
            "y": -8,
            "z": 5,
            "elements": [
                "compactmachines3:wall@0"
            ]
        },
        {
            "x": 1,
            "y": -3,
            "z": -3,
            "elements": [
                "compactmachines3:wallbreakable@0"
            ]
        },
        {
            "x": -7,
            "y": -6,
            "z": 5,
            "elements": [
                "compactmachines3:wall@0"
            ]
        },
        {
            "x": -7,
            "y": -1,
            "z": 2,
            "elements": [
                "compactmachines3:wall@0"
            ]
        },
        {
            "x": 6,
            "y": 0,
            "z": -2,
            "elements": [
                "compactmachines3:wallbreakable@0"
            ]
        },
        {
            "x": 0,
            "y": 1,
            "z": -3,
            "elements": [
                "compactmachines3:wallbreakable@0"
            ]
        },
        {
            "x": -7,
            "y": -8,
            "z": 2,
            "elements": [
                "compactmachines3:wall@0"
            ]
        },
        {
            "x": 1,
            "y": -1,
            "z": 7,
            "elements": [
                "compactmachines3:wall@0"
            ]
        },
        {
            "x": 1,
            "y": 6,
            "z": -2,
            "elements": [
                "compactmachines3:wall@0"
            ]
        },
        {
            "x": 7,
            "y": -3,
            "z": -1,
            "elements": [
                "compactmachines3:wall@0"
            ]
        },
        {
            "x": -2,
            "y": 0,
            "z": -7,
            "elements": [
                "compactmachines3:wall@0"
            ]
        },
        {
            "x": 0,
            "y": 5,
            "z": 2,
            "elements": [
                "compactmachines3:wallbreakable@0"
            ]
        },
        {
            "x": -3,
            "y": -8,
            "z": 1,
            "elements": [
                "compactmachines3:wall@0"
            ]
        },
        {
            "x": -1,
            "y": -6,
            "z": -2,
            "elements": [
                "compactmachines3:wallbreakable@0"
            ]
        },
        {
            "x": -7,
            "y": 0,
            "z": -4,
            "elements": [
                "compactmachines3:wall@0"
            ]
        },
        {
            "x": -1,
            "y": 3,
            "z": 7,
            "elements": [
                "compactmachines3:wall@0"
            ]
        },
        {
            "x": -7,
            "y": 1,
            "z": 7,
            "elements": [
                "compactmachines3:wall@0"
            ]
        },
        {
            "x": 7,
            "y": -2,
            "z": 6,
            "elements": [
                "compactmachines3:wall@0"
            ]
        },
        {
            "x": 6,
            "y": -2,
            "z": -7,
            "elements": [
                "compactmachines3:wall@0"
            ]
        },
        {
            "x": 7,
            "y": 0,
            "z": 4,
            "elements": [
                "compactmachines3:wall@0"
            ]
        },
        {
            "x": 5,
            "y": -2,
            "z": -2,
            "elements": [
                "compactmachines3:wallbreakable@0"
            ]
        },
        {
            "x": -5,
            "y": -5,
            "z": 7,
            "elements": [
                "compactmachines3:wall@0"
            ]
        },
        {
            "x": 4,
            "y": 4,
            "z": -7,
            "elements": [
                "compactmachines3:wall@0"
            ]
        },
        {
            "x": 4,
            "y": -7,
            "z": 7,
            "elements": [
                "compactmachines3:wall@0"
            ]
        },
        {
            "x": 3,
            "y": 0,
            "z": -2,
            "elements": [
                "compactmachines3:wallbreakable@0"
            ]
        },
        {
            "x": -1,
            "y": 6,
            "z": 6,
            "elements": [
                "compactmachines3:wall@0"
            ]
        },
        {
            "x": -4,
            "y": -1,
            "z": 2,
            "elements": [
                "compactmachines3:wallbreakable@0"
            ]
        },
        {
            "x": -5,
            "y": 6,
            "z": -7,
            "elements": [
                "compactmachines3:wall@0"
            ]
        },
        {
            "x": 7,
            "y": 1,
            "z": 4,
            "elements": [
                "compactmachines3:wall@0"
            ]
        },
        {
            "x": 7,
            "y": 5,
            "z": -1,
            "elements": [
                "compactmachines3:wall@0"
            ]
        },
        {
            "x": 0,
            "y": -4,
            "z": -7,
            "elements": [
                "compactmachines3:wall@0"
            ]
        },
        {
            "x": 5,
            "y": 1,
            "z": -1,
            "elements": [
                "compactmachines3:wallbreakable@0"
            ]
        },
        {
            "x": -1,
            "y": -8,
            "z": -2,
            "elements": [
                "compactmachines3:wall@0"
            ]
        },
        {
            "x": 1,
            "y": 4,
            "z": -2,
            "elements": [
                "compactmachines3:wallbreakable@0"
            ]
        },
        {
            "x": -6,
            "y": 6,
            "z": -2,
            "elements": [
                "compactmachines3:wall@0"
            ]
        },
        {
            "x": 7,
            "y": 4,
            "z": 1,
            "elements": [
                "compactmachines3:wall@0"
            ]
        },
        {
            "x": 0,
            "y": 6,
            "z": -2,
            "elements": [
                "compactmachines3:wall@0"
            ]
        },
        {
            "x": -1,
            "y": -7,
            "z": 2,
            "elements": [
                "compactmachines3:wallbreakable@0"
            ]
        },
        {
            "x": -7,
            "y": 3,
            "z": -4,
            "elements": [
                "compactmachines3:wall@0"
            ]
        },
        {
            "x": 7,
            "y": 0,
            "z": -7,
            "elements": [
                "compactmachines3:wall@0"
            ]
        },
        {
            "x": 7,
            "y": -1,
            "z": -1,
            "elements": [
                "compactmachines3:wall@0"
            ]
        },
        {
            "x": -4,
            "y": -2,
            "z": -2,
            "elements": [
                "compactmachines3:wallbreakable@0"
            ]
        },
        {
            "x": 1,
            "y": 6,
            "z": 4,
            "elements": [
                "compactmachines3:wall@0"
            ]
        },
        {
            "x": -1,
            "y": 5,
            "z": 7,
            "elements": [
                "compactmachines3:wall@0"
            ]
        },
        {
            "x": -5,
            "y": -3,
            "z": 7,
            "elements": [
                "compactmachines3:wall@0"
            ]
        },
        {
            "x": 7,
            "y": 2,
            "z": 4,
            "elements": [
                "compactmachines3:wall@0"
            ]
        },
        {
            "x": 4,
            "y": 2,
            "z": -7,
            "elements": [
                "compactmachines3:wall@0"
            ]
        },
        {
            "x": 3,
            "y": -8,
            "z": -7,
            "elements": [
                "compactmachines3:wall@0"
            ]
        },
        {
            "x": -7,
            "y": 4,
            "z": -4,
            "elements": [
                "compactmachines3:wall@0"
            ]
        },
        {
            "x": 4,
            "y": 0,
            "z": -2,
            "elements": [
                "compactmachines3:wallbreakable@0"
            ]
        },
        {
            "x": -5,
            "y": -1,
            "z": 2,
            "elements": [
                "compactmachines3:wallbreakable@0"
            ]
        },
        {
            "x": 0,
            "y": -6,
            "z": -7,
            "elements": [
                "compactmachines3:wall@0"
            ]
        },
        {
            "x": 7,
            "y": -1,
            "z": 7,
            "elements": [
                "compactmachines3:wall@0"
            ]
        },
        {
            "x": 2,
            "y": 6,
            "z": 6,
            "elements": [
                "compactmachines3:wall@0"
            ]
        },
        {
            "x": 2,
            "y": 5,
            "z": -1,
            "elements": [
                "compactmachines3:wallbreakable@0"
            ]
        },
        {
            "x": 4,
            "y": -3,
            "z": 7,
            "elements": [
                "compactmachines3:wall@0"
            ]
        },
        {
            "x": -5,
            "y": 2,
            "z": -7,
            "elements": [
                "compactmachines3:wall@0"
            ]
        },
        {
            "x": -5,
            "y": -8,
            "z": 1,
            "elements": [
                "compactmachines3:wall@0"
            ]
        },
        {
            "x": 0,
            "y": -2,
            "z": -7,
            "elements": [
                "compactmachines3:wall@0"
            ]
        },
        {
            "x": -1,
            "y": 1,
            "z": 7,
            "elements": [
                "compactmachines3:wall@0"
            ]
        },
        {
            "x": -5,
            "y": -1,
            "z": 7,
            "elements": [
                "compactmachines3:wall@0"
            ]
        },
        {
            "x": 7,
            "y": 0,
            "z": 1,
            "elements": [
                "compactmachines3:wall@0"
            ]
        },
        {
            "x": 4,
            "y": 6,
            "z": 4,
            "elements": [
                "compactmachines3:wall@0"
            ]
        },
        {
            "x": 0,
            "y": 1,
            "z": 2,
            "elements": [
                "contenttweaker:memory_matrix@0"
            ]
        },
        {
            "x": 2,
            "y": -1,
            "z": 2,
            "elements": [
                "contenttweaker:memory_matrix@0"
            ]
        },
        {
            "x": 4,
            "y": 0,
            "z": -7,
            "elements": [
                "compactmachines3:wall@0"
            ]
        },
        {
            "x": -3,
            "y": 0,
            "z": -2,
            "elements": [
                "compactmachines3:wallbreakable@0"
            ]
        },
        {
            "x": -4,
            "y": 5,
            "z": 7,
            "elements": [
                "compactmachines3:wall@0"
            ]
        },
        {
            "x": 5,
            "y": 6,
            "z": 6,
            "elements": [
                "compactmachines3:wall@0"
            ]
        },
        {
            "x": -2,
            "y": -8,
            "z": -4,
            "elements": [
                "compactmachines3:wall@0"
            ]
        },
        {
            "x": -2,
            "y": 4,
            "z": -7,
            "elements": [
                "compactmachines3:wall@0"
            ]
        },
        {
            "x": 1,
            "y": -5,
            "z": 7,
            "elements": [
                "compactmachines3:wall@0"
            ]
        },
        {
            "x": -7,
            "y": 3,
            "z": 7,
            "elements": [
                "compactmachines3:wall@0"
            ]
        },
        {
            "x": 2,
            "y": 1,
            "z": 7,
            "elements": [
                "compactmachines3:wall@0"
            ]
        },
        {
            "x": 4,
            "y": 6,
            "z": 1,
            "elements": [
                "compactmachines3:wall@0"
            ]
        },
        {
            "x": -3,
            "y": -2,
            "z": -7,
            "elements": [
                "compactmachines3:wall@0"
            ]
        },
        {
            "x": 3,
            "y": -6,
            "z": -7,
            "elements": [
                "compactmachines3:wall@0"
            ]
        },
        {
            "x": -4,
            "y": 1,
            "z": 7,
            "elements": [
                "compactmachines3:wall@0"
            ]
        },
        {
            "x": -2,
            "y": -1,
            "z": 7,
            "elements": [
                "compactmachines3:wall@0"
            ]
        },
        {
            "x": 7,
            "y": 1,
            "z": -1,
            "elements": [
                "compactmachines3:wall@0"
            ]
        },
        {
            "x": 1,
            "y": -3,
            "z": 7,
            "elements": [
                "compactmachines3:wall@0"
            ]
        },
        {
            "x": 4,
            "y": -5,
            "z": 7,
            "elements": [
                "compactmachines3:wall@0"
            ]
        },
        {
            "x": 2,
            "y": 0,
            "z": 6,
            "elements": [
                "compactmachines3:wallbreakable@0"
            ]
        },
        {
            "x": 0,
            "y": 3,
            "z": 2,
            "elements": [
                "compactmachines3:wallbreakable@0"
            ]
        },
        {
            "x": 5,
            "y": -1,
            "z": 2,
            "elements": [
                "compactmachines3:wallbreakable@0"
            ]
        },
        {
            "x": 3,
            "y": -2,
            "z": -7,
            "elements": [
                "compactmachines3:wall@0"
            ]
        },
        {
            "x": -6,
            "y": -8,
            "z": 1,
            "elements": [
                "compactmachines3:wall@0"
            ]
        },
        {
            "x": 6,
            "y": -4,
            "z": -7,
            "elements": [
                "compactmachines3:wall@0"
            ]
        },
        {
            "x": 5,
            "y": -8,
            "z": -2,
            "elements": [
                "compactmachines3:wall@0"
            ]
        },
        {
            "x": -1,
            "y": -4,
            "z": -2,
            "elements": [
                "compactmachines3:wallbreakable@0"
            ]
        },
        {
            "x": 7,
            "y": 2,
            "z": 1,
            "elements": [
                "compactmachines3:wall@0"
            ]
        },
        {
            "x": -5,
            "y": 4,
            "z": -7,
            "elements": [
                "compactmachines3:wall@0"
            ]
        },
        {
            "x": -2,
            "y": 2,
            "z": -7,
            "elements": [
                "compactmachines3:wall@0"
            ]
        },
        {
            "x": -6,
            "y": 0,
            "z": -2,
            "elements": [
                "compactmachines3:wallbreakable@0"
            ]
        },
        {
            "x": 1,
            "y": 0,
            "z": -7,
            "elements": [
                "compactmachines3:wall@0"
            ]
        },
        {
            "x": 0,
            "y": -3,
            "z": -6,
            "elements": [
                "compactmachines3:wallbreakable@0"
            ]
        },
        {
            "x": 2,
            "y": -2,
            "z": -2,
            "elements": [
                "contenttweaker:memory_matrix@0"
            ]
        },
        {
            "x": -7,
            "y": 2,
            "z": -4,
            "elements": [
                "compactmachines3:wall@0"
            ]
        },
        {
            "x": 7,
            "y": 3,
            "z": -1,
            "elements": [
                "compactmachines3:wall@0"
            ]
        },
        {
            "x": 7,
            "y": -7,
            "z": 7,
            "elements": [
                "compactmachines3:wall@0"
            ]
        },
        {
            "x": -4,
            "y": 3,
            "z": 7,
            "elements": [
                "compactmachines3:wall@0"
            ]
        },
        {
            "x": 2,
            "y": -3,
            "z": 2,
            "elements": [
                "compactmachines3:wallbreakable@0"
            ]
        },
        {
            "x": 3,
            "y": -4,
            "z": -7,
            "elements": [
                "compactmachines3:wall@0"
            ]
        },
        {
            "x": 2,
            "y": -8,
            "z": -2,
            "elements": [
                "compactmachines3:wall@0"
            ]
        },
        {
            "x": -4,
            "y": 6,
            "z": 6,
            "elements": [
                "compactmachines3:wall@0"
            ]
        },
        {
            "x": -7,
            "y": 5,
            "z": 7,
            "elements": [
                "compactmachines3:wall@0"
            ]
        },
        {
            "x": -7,
            "y": 1,
            "z": -4,
            "elements": [
                "compactmachines3:wall@0"
            ]
        },
        {
            "x": 6,
            "y": -6,
            "z": -7,
            "elements": [
                "compactmachines3:wall@0"
            ]
        },
        {
            "x": -7,
            "y": 3,
            "z": -1,
            "elements": [
                "compactmachines3:wall@0"
            ]
        },
        {
            "x": -1,
            "y": 3,
            "z": 2,
            "elements": [
                "compactmachines3:wallbreakable@0"
            ]
        },
        {
            "x": 0,
            "y": -4,
            "z": -2,
            "elements": [
                "compactmachines3:wallbreakable@0"
            ]
        },
        {
            "x": -2,
            "y": 1,
            "z": 2,
            "elements": [
                "compactmachines3:wallbreakable@0"
            ]
        },
        {
            "x": 7,
            "y": -5,
            "z": 7,
            "elements": [
                "compactmachines3:wall@0"
            ]
        },
        {
            "x": 1,
            "y": 0,
            "z": 1,
            "elements": [
                "draconicevolution:draconic_block@0"
            ]
        },
        {
            "x": -2,
            "y": -8,
            "z": -7,
            "elements": [
                "compactmachines3:wall@0"
            ]
        },
        {
            "x": -1,
            "y": -3,
            "z": 2,
            "elements": [
                "contenttweaker:memory_matrix@0"
            ]
        },
        {
            "x": -2,
            "y": 6,
            "z": 1,
            "elements": [
                "compactmachines3:wall@0"
            ]
        },
        {
            "x": -3,
            "y": -6,
            "z": -7,
            "elements": [
                "compactmachines3:wall@0"
            ]
        },
        {
            "x": 2,
            "y": 5,
            "z": 7,
            "elements": [
                "compactmachines3:wall@0"
            ]
        },
        {
            "x": -5,
            "y": -3,
            "z": -1,
            "elements": [
                "compactmachines3:wallbreakable@0"
            ]
        },
        {
            "x": 0,
            "y": 2,
            "z": -2,
            "elements": [
                "compactmachines3:wallbreakable@0"
            ]
        },
        {
            "x": 3,
            "y": -8,
            "z": -2,
            "elements": [
                "compactmachines3:wall@0"
            ]
        },
        {
            "x": 7,
            "y": 6,
            "z": -7,
            "elements": [
                "compactmachines3:wall@0"
            ]
        },
        {
            "x": 7,
            "y": -3,
            "z": 7,
            "elements": [
                "compactmachines3:wall@0"
            ]
        },
        {
            "x": -5,
            "y": 0,
            "z": -7,
            "elements": [
                "compactmachines3:wall@0"
            ]
        },
        {
            "x": 4,
            "y": -1,
            "z": 7,
            "elements": [
                "compactmachines3:wall@0"
            ]
        },
        {
            "x": 2,
            "y": 3,
            "z": 7,
            "elements": [
                "compactmachines3:wall@0"
            ]
        },
        {
            "x": 5,
            "y": 1,
            "z": 7,
            "elements": [
                "compactmachines3:wall@0"
            ]
        },
        {
            "x": 1,
            "y": -4,
            "z": -2,
            "elements": [
                "compactmachines3:wallbreakable@0"
            ]
        },
        {
            "x": -7,
            "y": -6,
            "z": 6,
            "elements": [
                "compactmachines3:wall@0"
            ]
        },
        {
            "x": -2,
            "y": -3,
            "z": -1,
            "elements": [
                "contenttweaker:memory_matrix@0"
            ]
        },
        {
            "x": -4,
            "y": -8,
            "z": 6,
            "elements": [
                "compactmachines3:wall@0"
            ]
        },
        {
            "x": -1,
            "y": 1,
            "z": 2,
            "elements": [
                "contenttweaker:memory_matrix@0"
            ]
        },
        {
            "x": -5,
            "y": -8,
            "z": -3,
            "elements": [
                "compactmachines3:wall@0"
            ]
        },
        {
            "x": -7,
            "y": 1,
            "z": -1,
            "elements": [
                "compactmachines3:wall@0"
            ]
        },
        {
            "x": -5,
            "y": 6,
            "z": 1,
            "elements": [
                "compactmachines3:wall@0"
            ]
        },
        {
            "x": -7,
            "y": -7,
            "z": 7,
            "elements": [
                "compactmachines3:wall@0"
            ]
        },
        {
            "x": 7,
            "y": -8,
            "z": 6,
            "elements": [
                "compactmachines3:wall@0"
            ]
        },
        {
            "x": -7,
            "y": -4,
            "z": 6,
            "elements": [
                "compactmachines3:wall@0"
            ]
        },
        {
            "x": -2,
            "y": 4,
            "z": 1,
            "elements": [
                "compactmachines3:wallbreakable@0"
            ]
        },
        {
            "x": 0,
            "y": -3,
            "z": 2,
            "elements": [
                "contenttweaker:memory_matrix@0"
            ]
        },
        {
            "x": -1,
            "y": 2,
            "z": -2,
            "elements": [
                "compactmachines3:wallbreakable@0"
            ]
        },
        {
            "x": 1,
            "y": -5,
            "z": 2,
            "elements": [
                "compactmachines3:wallbreakable@0"
            ]
        },
        {
            "x": 4,
            "y": -8,
            "z": -2,
            "elements": [
                "compactmachines3:wall@0"
            ]
        },
        {
            "x": 6,
            "y": 6,
            "z": -7,
            "elements": [
                "compactmachines3:wall@0"
            ]
        },
        {
            "x": -6,
            "y": -2,
            "z": -7,
            "elements": [
                "compactmachines3:wall@0"
            ]
        },
        {
            "x": -5,
            "y": -8,
            "z": -4,
            "elements": [
                "compactmachines3:wall@0"
            ]
        },
        {
            "x": -7,
            "y": -8,
            "z": 6,
            "elements": [
                "compactmachines3:wall@0"
            ]
        },
        {
            "x": -3,
            "y": 6,
            "z": -2,
            "elements": [
                "compactmachines3:wall@0"
            ]
        },
        {
            "x": -3,
            "y": -4,
            "z": -7,
            "elements": [
                "compactmachines3:wall@0"
            ]
        },
        {
            "x": 4,
            "y": 6,
            "z": 3,
            "elements": [
                "compactmachines3:wall@0"
            ]
        },
        {
            "x": -4,
            "y": 1,
            "z": -1,
            "elements": [
                "compactmachines3:wallbreakable@0"
            ]
        },
        {
            "x": 7,
            "y": 6,
            "z": 1,
            "elements": [
                "compactmachines3:wall@0"
            ]
        },
        {
            "x": 1,
            "y": -6,
            "z": -2,
            "elements": [
                "compactmachines3:wallbreakable@0"
            ]
        },
        {
            "x": 1,
            "y": 3,
            "z": 2,
            "elements": [
                "compactmachines3:wallbreakable@0"
            ]
        },
        {
            "x": 5,
            "y": 3,
            "z": 7,
            "elements": [
                "compactmachines3:wall@0"
            ]
        },
        {
            "x": 7,
            "y": 4,
            "z": 4,
            "elements": [
                "compactmachines3:wall@0"
            ]
        },
        {
            "x": -2,
            "y": -1,
            "z": 2,
            "elements": [
                "contenttweaker:memory_matrix@0"
            ]
        },
        {
            "x": -6,
            "y": -4,
            "z": -7,
            "elements": [
                "compactmachines3:wall@0"
            ]
        },
        {
            "x": 0,
            "y": -8,
            "z": -7,
            "elements": [
                "compactmachines3:wall@0"
            ]
        },
        {
            "x": 7,
            "y": 5,
            "z": -6,
            "elements": [
                "compactmachines3:wall@0"
            ]
        },
        {
            "x": -2,
            "y": -8,
            "z": -3,
            "elements": [
                "compactmachines3:wall@0"
            ]
        },
        {
            "x": -2,
            "y": -5,
            "z": -1,
            "elements": [
                "compactmachines3:wallbreakable@0"
            ]
        },
        {
            "x": 3,
            "y": -2,
            "z": -2,
            "elements": [
                "compactmachines3:wallbreakable@0"
            ]
        },
        {
            "x": 7,
            "y": -7,
            "z": -1,
            "elements": [
                "compactmachines3:wall@0"
            ]
        },
        {
            "x": 1,
            "y": -3,
            "z": 2,
            "elements": [
                "contenttweaker:memory_matrix@0"
            ]
        },
        {
            "x": 7,
            "y": 2,
            "z": -7,
            "elements": [
                "compactmachines3:wall@0"
            ]
        },
        {
            "x": -7,
            "y": 5,
            "z": -1,
            "elements": [
                "compactmachines3:wall@0"
            ]
        },
        {
            "x": 7,
            "y": 3,
            "z": 4,
            "elements": [
                "compactmachines3:wall@0"
            ]
        },
        {
            "x": 1,
            "y": -8,
            "z": -2,
            "elements": [
                "compactmachines3:wall@0"
            ]
        },
        {
            "x": 2,
            "y": 3,
            "z": -1,
            "elements": [
                "compactmachines3:wallbreakable@0"
            ]
        },
        {
            "x": 7,
            "y": -6,
            "z": 6,
            "elements": [
                "compactmachines3:wall@0"
            ]
        },
        {
            "x": -7,
            "y": 0,
            "z": -3,
            "elements": [
                "compactmachines3:wall@0"
            ]
        },
        {
            "x": 1,
            "y": -7,
            "z": 2,
            "elements": [
                "compactmachines3:wallbreakable@0"
            ]
        },
        {
            "x": -2,
            "y": 6,
            "z": -2,
            "elements": [
                "compactmachines3:wall@0"
            ]
        },
        {
            "x": 7,
            "y": 6,
            "z": 4,
            "elements": [
                "compactmachines3:wall@0"
            ]
        },
        {
            "x": -7,
            "y": -6,
            "z": 3,
            "elements": [
                "compactmachines3:wall@0"
            ]
        },
        {
            "x": 7,
            "y": -5,
            "z": -1,
            "elements": [
                "compactmachines3:wall@0"
            ]
        },
        {
            "x": 1,
            "y": 1,
            "z": 2,
            "elements": [
                "contenttweaker:memory_matrix@0"
            ]
        },
        {
            "x": -2,
            "y": -2,
            "z": -2,
            "elements": [
                "contenttweaker:memory_matrix@0"
            ]
        },
        {
            "x": 5,
            "y": 5,
            "z": 7,
            "elements": [
                "compactmachines3:wall@0"
            ]
        },
        {
            "x": 6,
            "y": -8,
            "z": 1,
            "elements": [
                "compactmachines3:wall@0"
            ]
        },
        {
            "x": 4,
            "y": -3,
            "z": -1,
            "elements": [
                "compactmachines3:wallbreakable@0"
            ]
        },
        {
            "x": -3,
            "y": -8,
            "z": -7,
            "elements": [
                "compactmachines3:wall@0"
            ]
        },
        {
            "x": -2,
            "y": 0,
            "z": -2,
            "elements": [
                "contenttweaker:memory_matrix@0"
            ]
        },
        {
            "x": 1,
            "y": -8,
            "z": -4,
            "elements": [
                "compactmachines3:wall@0"
            ]
        },
        {
            "x": -6,
            "y": -6,
            "z": -7,
            "elements": [
                "compactmachines3:wall@0"
            ]
        },
        {
            "x": 1,
            "y": 1,
            "z": 7,
            "elements": [
                "compactmachines3:wall@0"
            ]
        },
        {
            "x": -7,
            "y": -1,
            "z": 7,
            "elements": [
                "compactmachines3:wall@0"
            ]
        },
        {
            "x": -5,
            "y": -7,
            "z": 7,
            "elements": [
                "compactmachines3:wall@0"
            ]
        },
        {
            "x": 7,
            "y": -4,
            "z": 6,
            "elements": [
                "compactmachines3:wall@0"
            ]
        },
        {
            "x": 7,
            "y": 5,
            "z": 4,
            "elements": [
                "compactmachines3:wall@0"
            ]
        },
        {
            "x": 4,
            "y": 6,
            "z": -7,
            "elements": [
                "compactmachines3:wall@0"
            ]
        },
        {
            "x": 1,
            "y": 2,
            "z": -2,
            "elements": [
                "compactmachines3:wallbreakable@0"
            ]
        },
        {
            "x": -2,
            "y": -3,
            "z": 2,
            "elements": [
                "compactmachines3:wallbreakable@0"
            ]
        },
        {
            "x": -1,
            "y": -5,
            "z": 2,
            "elements": [
                "compactmachines3:wallbreakable@0"
            ]
        },
        {
            "x": 1,
            "y": 6,
            "z": 1,
            "elements": [
                "compactmachines3:wall@0"
            ]
        },
        {
            "x": 0,
            "y": 4,
            "z": -2,
            "elements": [
                "compactmachines3:wallbreakable@0"
            ]
        },
        {
            "x": 7,
            "y": 4,
            "z": -7,
            "elements": [
                "compactmachines3:wall@0"
            ]
        },
        {
            "x": -5,
            "y": 6,
            "z": -2,
            "elements": [
                "compactmachines3:wall@0"
            ]
        },
        {
            "x": -2,
            "y": -7,
            "z": -1,
            "elements": [
                "compactmachines3:wallbreakable@0"
            ]
        },
        {
            "x": 2,
            "y": -3,
            "z": 7,
            "elements": [
                "compactmachines3:wall@0"
            ]
        },
        {
            "x": -7,
            "y": -7,
            "z": 3,
            "elements": [
                "compactmachines3:wall@0"
            ]
        },
        {
            "x": -7,
            "y": 3,
            "z": -5,
            "elements": [
                "compactmachines3:wall@0"
            ]
        },
        {
            "x": 7,
            "y": -4,
            "z": -7,
            "elements": [
                "compactmachines3:wall@0"
            ]
        },
        {
            "x": 6,
            "y": 6,
            "z": -3,
            "elements": [
                "compactmachines3:wall@0"
            ]
        },
        {
            "x": -2,
            "y": -2,
            "z": -7,
            "elements": [
                "compactmachines3:wall@0"
            ]
        },
        {
            "x": 2,
            "y": 1,
            "z": -1,
            "elements": [
                "contenttweaker:memory_matrix@0"
            ]
        },
        {
            "x": 2,
            "y": -4,
            "z": 1,
            "elements": [
                "compactmachines3:wallbreakable@0"
            ]
        },
        {
            "x": 3,
            "y": -5,
            "z": 7,
            "elements": [
                "compactmachines3:wall@0"
            ]
        },
        {
            "x": 7,
            "y": 0,
            "z": 3,
            "elements": [
                "compactmachines3:wall@0"
            ]
        },
        {
            "x": -4,
            "y": 4,
            "z": -7,
            "elements": [
                "compactmachines3:wall@0"
            ]
        },
        {
            "x": 6,
            "y": 0,
            "z": -7,
            "elements": [
                "compactmachines3:wall@0"
            ]
        },
        {
            "x": -3,
            "y": 2,
            "z": -7,
            "elements": [
                "compactmachines3:wall@0"
            ]
        },
        {
            "x": -5,
            "y": -8,
            "z": 6,
            "elements": [
                "compactmachines3:wall@0"
            ]
        },
        {
            "x": 7,
            "y": -6,
            "z": -2,
            "elements": [
                "compactmachines3:wall@0"
            ]
        },
        {
            "x": 1,
            "y": 5,
            "z": 7,
            "elements": [
                "compactmachines3:wall@0"
            ]
        },
        {
            "x": -2,
            "y": 5,
            "z": 7,
            "elements": [
                "compactmachines3:wall@0"
            ]
        },
        {
            "x": -6,
            "y": 1,
            "z": 7,
            "elements": [
                "compactmachines3:wall@0"
            ]
        },
        {
            "x": 5,
            "y": 6,
            "z": 0,
            "elements": [
                "compactmachines3:wall@0"
            ]
        },
        {
            "x": 7,
            "y": 3,
            "z": -6,
            "elements": [
                "compactmachines3:wall@0"
            ]
        },
        {
            "x": -7,
            "y": 4,
            "z": -2,
            "elements": [
                "compactmachines3:wall@0"
            ]
        },
        {
            "x": 0,
            "y": 1,
            "z": -6,
            "elements": [
                "compactmachines3:wallbreakable@0"
            ]
        },
        {
            "x": -6,
            "y": 6,
            "z": 1,
            "elements": [
                "compactmachines3:wall@0"
            ]
        },
        {
            "x": 1,
            "y": -6,
            "z": -7,
            "elements": [
                "compactmachines3:wall@0"
            ]
        },
        {
            "x": 0,
            "y": -1,
            "z": 7,
            "elements": [
                "compactmachines3:wall@0"
            ]
        },
        {
            "x": -7,
            "y": 2,
            "z": -5,
            "elements": [
                "compactmachines3:wall@0"
            ]
        },
        {
            "x": -4,
            "y": -7,
            "z": 7,
            "elements": [
                "compactmachines3:wall@0"
            ]
        },
        {
            "x": 5,
            "y": -8,
            "z": 1,
            "elements": [
                "compactmachines3:wall@0"
            ]
        },
        {
            "x": -7,
            "y": 5,
            "z": -5,
            "elements": [
                "compactmachines3:wall@0"
            ]
        },
        {
            "x": 5,
            "y": 6,
            "z": -5,
            "elements": [
                "compactmachines3:wall@0"
            ]
        },
        {
            "x": 3,
            "y": 6,
            "z": -7,
            "elements": [
                "compactmachines3:wall@0"
            ]
        },
        {
            "x": -1,
            "y": 0,
            "z": -7,
            "elements": [
                "compactmachines3:wall@0"
            ]
        },
        {
            "x": 5,
            "y": -2,
            "z": -7,
            "elements": [
                "compactmachines3:wall@0"
            ]
        },
        {
            "x": 4,
            "y": 6,
            "z": 5,
            "elements": [
                "compactmachines3:wall@0"
            ]
        },
        {
            "x": -3,
            "y": 1,
            "z": -1,
            "elements": [
                "compactmachines3:wallbreakable@0"
            ]
        },
        {
            "x": -5,
            "y": 5,
            "z": 7,
            "elements": [
                "compactmachines3:wall@0"
            ]
        },
        {
            "x": 7,
            "y": -8,
            "z": -2,
            "elements": [
                "compactmachines3:wall@0"
            ]
        },
        {
            "x": 3,
            "y": -3,
            "z": 7,
            "elements": [
                "compactmachines3:wall@0"
            ]
        },
        {
            "x": 2,
            "y": -5,
            "z": 7,
            "elements": [
                "compactmachines3:wall@0"
            ]
        },
        {
            "x": 2,
            "y": -2,
            "z": 6,
            "elements": [
                "compactmachines3:wallbreakable@0"
            ]
        },
        {
            "x": -6,
            "y": -8,
            "z": 5,
            "elements": [
                "compactmachines3:wall@0"
            ]
        },
        {
            "x": 7,
            "y": 2,
            "z": 3,
            "elements": [
                "compactmachines3:wall@0"
            ]
        },
        {
            "x": -3,
            "y": 4,
            "z": -7,
            "elements": [
                "compactmachines3:wall@0"
            ]
        },
        {
            "x": -4,
            "y": 2,
            "z": -7,
            "elements": [
                "compactmachines3:wall@0"
            ]
        },
        {
            "x": -4,
            "y": 0,
            "z": -2,
            "elements": [
                "compactmachines3:wallbreakable@0"
            ]
        },
        {
            "x": 3,
            "y": -1,
            "z": 2,
            "elements": [
                "compactmachines3:wallbreakable@0"
            ]
        },
        {
            "x": 2,
            "y": -3,
            "z": -1,
            "elements": [
                "contenttweaker:memory_matrix@0"
            ]
        },
        {
            "x": 4,
            "y": -2,
            "z": -2,
            "elements": [
                "compactmachines3:wallbreakable@0"
            ]
        },
        {
            "x": -7,
            "y": 4,
            "z": -5,
            "elements": [
                "compactmachines3:wall@0"
            ]
        },
        {
            "x": -2,
            "y": -8,
            "z": -5,
            "elements": [
                "compactmachines3:wall@0"
            ]
        },
        {
            "x": 1,
            "y": 3,
            "z": 7,
            "elements": [
                "compactmachines3:wall@0"
            ]
        },
        {
            "x": -7,
            "y": -8,
            "z": 3,
            "elements": [
                "compactmachines3:wall@0"
            ]
        },
        {
            "x": -2,
            "y": 3,
            "z": 7,
            "elements": [
                "compactmachines3:wall@0"
            ]
        },
        {
            "x": -6,
            "y": 6,
            "z": -7,
            "elements": [
                "compactmachines3:wall@0"
            ]
        },
        {
            "x": 5,
            "y": -7,
            "z": 7,
            "elements": [
                "compactmachines3:wall@0"
            ]
        },
        {
            "x": -7,
            "y": 6,
            "z": -2,
            "elements": [
                "compactmachines3:wall@0"
            ]
        },
        {
            "x": -6,
            "y": -8,
            "z": 0,
            "elements": [
                "compactmachines3:wall@0"
            ]
        },
        {
            "x": 1,
            "y": -4,
            "z": -7,
            "elements": [
                "compactmachines3:wall@0"
            ]
        },
        {
            "x": 0,
            "y": -8,
            "z": 1,
            "elements": [
                "compactmachines3:wall@0"
            ]
        },
        {
            "x": -1,
            "y": 6,
            "z": 1,
            "elements": [
                "compactmachines3:wall@0"
            ]
        },
        {
            "x": 3,
            "y": -1,
            "z": 7,
            "elements": [
                "compactmachines3:wall@0"
            ]
        },
        {
            "x": 7,
            "y": 1,
            "z": 3,
            "elements": [
                "compactmachines3:wall@0"
            ]
        },
        {
            "x": 0,
            "y": -7,
            "z": 2,
            "elements": [
                "compactmachines3:wallbreakable@0"
            ]
        },
        {
            "x": 0,
            "y": -1,
            "z": -1,
            "elements": [
                "modularmachinery:blockinputbus@0"
            ]
        },
        {
            "x": -1,
            "y": 0,
            "z": 1,
            "elements": [
                "draconicevolution:draconic_block@0"
            ]
        },
        {
            "x": -1,
            "y": -3,
            "z": -6,
            "elements": [
                "compactmachines3:wallbreakable@0"
            ]
        },
        {
            "x": -1,
            "y": 6,
            "z": -2,
            "elements": [
                "compactmachines3:wall@0"
            ]
        },
        {
            "x": -1,
            "y": -2,
            "z": 1,
            "elements": [
                "draconicevolution:draconic_block@0"
            ]
        },
        {
            "x": -4,
            "y": 0,
            "z": -7,
            "elements": [
                "compactmachines3:wall@0"
            ]
        },
        {
            "x": 7,
            "y": 4,
            "z": 3,
            "elements": [
                "compactmachines3:wall@0"
            ]
        },
        {
            "x": -4,
            "y": -3,
            "z": 7,
            "elements": [
                "compactmachines3:wall@0"
            ]
        },
        {
            "x": -7,
            "y": -5,
            "z": 7,
            "elements": [
                "compactmachines3:wall@0"
            ]
        },
        {
            "x": -2,
            "y": 2,
            "z": 1,
            "elements": [
                "compactmachines3:wallbreakable@0"
            ]
        },
        {
            "x": 3,
            "y": 2,
            "z": -7,
            "elements": [
                "compactmachines3:wall@0"
            ]
        },
        {
            "x": 2,
            "y": -7,
            "z": 7,
            "elements": [
                "compactmachines3:wall@0"
            ]
        },
        {
            "x": -3,
            "y": 6,
            "z": 6,
            "elements": [
                "compactmachines3:wall@0"
            ]
        },
        {
            "x": -7,
            "y": 0,
            "z": 6,
            "elements": [
                "compactmachines3:wall@0"
            ]
        },
        {
            "x": 7,
            "y": 3,
            "z": 3,
            "elements": [
                "compactmachines3:wall@0"
            ]
        },
        {
            "x": -4,
            "y": 6,
            "z": 1,
            "elements": [
                "compactmachines3:wall@0"
            ]
        },
        {
            "x": 2,
            "y": -6,
            "z": 1,
            "elements": [
                "compactmachines3:wallbreakable@0"
            ]
        },
        {
            "x": -3,
            "y": 6,
            "z": -7,
            "elements": [
                "compactmachines3:wall@0"
            ]
        },
        {
            "x": 7,
            "y": -2,
            "z": -2,
            "elements": [
                "compactmachines3:wall@0"
            ]
        },
        {
            "x": -6,
            "y": -1,
            "z": 2,
            "elements": [
                "compactmachines3:wallbreakable@0"
            ]
        },
        {
            "x": 2,
            "y": -5,
            "z": -1,
            "elements": [
                "compactmachines3:wallbreakable@0"
            ]
        },
        {
            "x": 4,
            "y": -8,
            "z": -7,
            "elements": [
                "compactmachines3:wall@0"
            ]
        },
        {
            "x": 5,
            "y": 0,
            "z": -2,
            "elements": [
                "compactmachines3:wallbreakable@0"
            ]
        },
        {
            "x": 4,
            "y": -8,
            "z": 6,
            "elements": [
                "compactmachines3:wall@0"
            ]
        },
        {
            "x": 0,
            "y": -5,
            "z": 2,
            "elements": [
                "compactmachines3:wallbreakable@0"
            ]
        },
        {
            "x": -2,
            "y": 3,
            "z": -1,
            "elements": [
                "compactmachines3:wallbreakable@0"
            ]
        },
        {
            "x": 3,
            "y": -8,
            "z": 1,
            "elements": [
                "compactmachines3:wall@0"
            ]
        },
        {
            "x": 6,
            "y": 4,
            "z": -7,
            "elements": [
                "compactmachines3:wall@0"
            ]
        },
        {
            "x": -4,
            "y": 6,
            "z": -2,
            "elements": [
                "compactmachines3:wall@0"
            ]
        },
        {
            "x": -2,
            "y": -4,
            "z": -7,
            "elements": [
                "compactmachines3:wall@0"
            ]
        },
        {
            "x": -7,
            "y": -2,
            "z": 6,
            "elements": [
                "compactmachines3:wall@0"
            ]
        },
        {
            "x": -1,
            "y": 4,
            "z": -2,
            "elements": [
                "compactmachines3:wallbreakable@0"
            ]
        },
        {
            "x": -6,
            "y": 5,
            "z": 7,
            "elements": [
                "compactmachines3:wall@0"
            ]
        },
        {
            "x": 7,
            "y": -1,
            "z": -5,
            "elements": [
                "compactmachines3:wall@0"
            ]
        },
        {
            "x": -5,
            "y": 3,
            "z": 7,
            "elements": [
                "compactmachines3:wall@0"
            ]
        },
        {
            "x": -6,
            "y": 3,
            "z": 7,
            "elements": [
                "compactmachines3:wall@0"
            ]
        },
        {
            "x": -2,
            "y": 1,
            "z": 7,
            "elements": [
                "compactmachines3:wall@0"
            ]
        },
        {
            "x": -3,
            "y": 1,
            "z": 7,
            "elements": [
                "compactmachines3:wall@0"
            ]
        },
        {
            "x": 2,
            "y": 6,
            "z": -2,
            "elements": [
                "compactmachines3:wall@0"
            ]
        },
        {
            "x": -5,
            "y": 1,
            "z": 7,
            "elements": [
                "compactmachines3:wall@0"
            ]
        },
        {
            "x": -7,
            "y": -3,
            "z": 7,
            "elements": [
                "compactmachines3:wall@0"
            ]
        },
        {
            "x": -4,
            "y": -5,
            "z": 7,
            "elements": [
                "compactmachines3:wall@0"
            ]
        },
        {
            "x": 5,
            "y": -8,
            "z": 6,
            "elements": [
                "compactmachines3:wall@0"
            ]
        },
        {
            "x": -2,
            "y": -8,
            "z": 6,
            "elements": [
                "compactmachines3:wall@0"
            ]
        },
        {
            "x": 7,
            "y": 5,
            "z": 3,
            "elements": [
                "compactmachines3:wall@0"
            ]
        },
        {
            "x": -3,
            "y": -1,
            "z": 2,
            "elements": [
                "compactmachines3:wallbreakable@0"
            ]
        },
        {
            "x": -3,
            "y": 6,
            "z": 1,
            "elements": [
                "compactmachines3:wall@0"
            ]
        },
        {
            "x": 7,
            "y": -4,
            "z": -2,
            "elements": [
                "compactmachines3:wall@0"
            ]
        },
        {
            "x": 1,
            "y": -8,
            "z": -7,
            "elements": [
                "compactmachines3:wall@0"
            ]
        },
        {
            "x": 3,
            "y": 4,
            "z": -7,
            "elements": [
                "compactmachines3:wall@0"
            ]
        },
        {
            "x": 2,
            "y": 0,
            "z": -2,
            "elements": [
                "contenttweaker:memory_matrix@0"
            ]
