{
    "registryname": "jingti",
    "localizedname": "§b晶体催生仓总控",
    "failure-action": "decrease",
    "requires-blueprint": false,
    "color": "000000",
    "parts": [
        {
            "x": -5,
            "y": 4,
            "z": 10,
            "elements": [
                "appliedenergistics2:sky_stone_brick_stairs@7"
            ]
        },
        {
            "x": -3,
            "y": -2,
            "z": 5,
            "elements": [
                "appliedenergistics2:sky_stone_brick_stairs@3"
            ]
        },
        {
            "x": 5,
            "y": 4,
            "z": 8,
            "elements": [
                "appliedenergistics2:smooth_sky_stone_block@0"
            ]
        },
        {
            "x": -1,
            "y": 2,
            "z": 0,
            "elements": [
                "appliedenergistics2:controller@0"
            ]
        },
        {
            "x": 0,
            "y": -2,
            "z": 0,
            "elements": [
                "modularmachinery:blockfluidinputhatch",
                "modularmachinery:blockmefluidinputbus",
                "modularmachinery:blockmepatternprovider"
            ]
        },
        {
            "x": 6,
            "y": 4,
            "z": 7,
            "elements": [
                "appliedenergistics2:sky_stone_brick_stairs@5"
            ]
        },
        {
            "x": -4,
            "y": -2,
            "z": 10,
            "elements": [
                "appliedenergistics2:sky_stone_brick_stairs@3"
            ]
        },
        {
            "x": 3,
            "y": -2,
            "z": 9,
            "elements": [
                "appliedenergistics2:smooth_sky_stone_block@0"
            ]
        },
        {
            "x": 5,
            "y": -2,
            "z": 1,
            "elements": [
                "appliedenergistics2:sky_stone_brick_stairs@2"
            ]
        },
        {
            "x": -4,
            "y": 4,
            "z": 5,
            "elements": [
                "appliedenergistics2:sky_stone_brick_stairs@7"
            ]
        },
        {
            "x": 0,
            "y": -1,
            "z": 0,
            "elements": [
                "appliedenergistics2:cable_bus@0"
            ]
        },
        {
            "x": -1,
            "y": 1,
            "z": 0,
            "elements": [
                "appliedenergistics2:controller@0"
            ]
        },
        {
            "x": 5,
            "y": 3,
            "z": 8,
            "elements": [
                "enderio:block_dark_fused_quartz@0"
            ]
        },
        {
            "x": -6,
            "y": 4,
            "z": 10,
            "elements": [
                "appliedenergistics2:sky_stone_brick_stairs@4"
            ]
        },
        {
            "x": 1,
            "y": 0,
            "z": 0,
            "elements": [
                "appliedenergistics2:cable_bus@0"
            ]
        },
        {
            "x": -4,
            "y": -2,
            "z": 5,
            "elements": [
                "appliedenergistics2:sky_stone_brick_stairs@3"
            ]
        },
        {
            "x": 1,
            "y": -2,
            "z": 0,
            "elements": [
                "appliedenergistics2:controller@0"
            ]
        },
        {
            "x": -2,
            "y": 2,
            "z": 0,
            "elements": [
                "modularmachinery:blockcasing@5"
            ]
        },
        {
            "x": 6,
            "y": 4,
            "z": 3,
            "elements": [
                "appliedenergistics2:sky_stone_brick_stairs@5"
            ]
        },
        {
            "x": 6,
            "y": 4,
            "z": 4,
            "elements": [
                "appliedenergistics2:sky_stone_brick_stairs@5"
            ]
        },
        {
            "x": 5,
            "y": 1,
            "z": 8,
            "elements": [
                "enderio:block_dark_fused_quartz@0"
            ]
        },
        {
            "x": 1,
            "y": -1,
            "z": 0,
            "elements": [
                "appliedenergistics2:controller@0"
            ]
        },
        {
            "x": -5,
            "y": 4,
            "z": 5,
            "elements": [
                "appliedenergistics2:sky_stone_brick_stairs@7"
            ]
        },
        {
            "x": 2,
            "y": 4,
            "z": 1,
            "elements": [
                "appliedenergistics2:sky_stone_brick_stairs@4"
            ]
        },
        {
            "x": -5,
            "y": -2,
            "z": 10,
            "elements": [
                "appliedenergistics2:sky_stone_brick_stairs@3"
            ]
        },
        {
            "x": -2,
            "y": 1,
            "z": 0,
            "elements": [
                "appliedenergistics2:controller@0"
            ]
        },
        {
            "x": -6,
            "y": -2,
            "z": 6,
            "elements": [
                "appliedenergistics2:sky_stone_brick_stairs@0"
            ]
        },
        {
            "x": 4,
            "y": 0,
            "z": 9,
            "elements": [
                "enderio:block_dark_fused_quartz@0"
            ]
        },
        {
            "x": 5,
            "y": 2,
            "z": 8,
            "elements": [
                "enderio:block_dark_fused_quartz@0"
            ]
        },
        {
            "x": 3,
            "y": -1,
            "z": 9,
            "elements": [
                "astralsorcery:blockblackmarble@2"
            ]
        },
        {
            "x": 2,
            "y": 0,
            "z": 0,
            "elements": [
                "modularmachinery:blockinputbus",
                "modularmachinery:blockmeiteminputbus",
                "modularmachinery:blockmepatternprovider"
            ]
        },
        {
            "x": 3,
            "y": 1,
            "z": 3,
            "elements": [
                "enderio:block_dark_fused_quartz@0"
            ]
        },
        {
            "x": 3,
            "y": 3,
            "z": 4,
            "elements": [
                "astralsorcery:blockblackmarble@2"
            ]
        },
        {
            "x": -2,
            "y": -2,
            "z": 0,
            "elements": [
                "modularmachinery:blockcasing@5"
            ]
        },
        {
            "x": 1,
            "y": 2,
            "z": 0,
            "elements": [
                "appliedenergistics2:controller@0"
            ]
        },
        {
            "x": -1,
            "y": -2,
            "z": 5,
            "elements": [
                "appliedenergistics2:sky_stone_small_brick_slab@0"
            ]
        },
        {
            "x": -2,
            "y": -2,
            "z": 10,
            "elements": [
                "appliedenergistics2:sky_stone_brick_stairs@1"
            ]
        },
        {
            "x": 3,
            "y": 4,
            "z": 4,
            "elements": [
                "appliedenergistics2:smooth_sky_stone_block@0"
            ]
        },
        {
            "x": -6,
            "y": 4,
            "z": 5,
            "elements": [
                "appliedenergistics2:sky_stone_brick_stairs@7"
            ]
        },
        {
            "x": -2,
            "y": -1,
            "z": 0,
            "elements": [
                "appliedenergistics2:controller@0"
            ]
        },
        {
            "x": 1,
            "y": 1,
            "z": 0,
            "elements": [
                "appliedenergistics2:controller@0"
            ]
        },
        {
            "x": 5,
            "y": 4,
            "z": 1,
            "elements": [
                "appliedenergistics2:sky_stone_brick_stairs@6"
            ]
        },
        {
            "x": -1,
            "y": 0,
            "z": 0,
            "elements": [
                "appliedenergistics2:cable_bus@0"
            ]
        },
        {
            "x": -6,
            "y": -2,
            "z": 5,
            "elements": [
                "appliedenergistics2:sky_stone_brick_stairs@3"
            ]
        },
        {
            "x": 2,
            "y": -1,
            "z": 3,
            "elements": [
                "appliedenergistics2:cable_bus@0"
            ]
        },
        {
            "x": -4,
            "y": 4,
            "z": 10,
            "elements": [
                "appliedenergistics2:sky_stone_brick_stairs@7"
            ]
        },
        {
            "x": 5,
            "y": -1,
            "z": 4,
            "elements": [
                "astralsorcery:blockblackmarble@2"
            ]
        },
        {
            "x": -3,
            "y": 4,
            "z": 5,
            "elements": [
                "appliedenergistics2:sky_stone_brick_stairs@7"
            ]
        },
        {
            "x": 3,
            "y": 0,
            "z": 3,
            "elements": [
                "enderio:block_dark_fused_quartz@0"
            ]
        },
        {
            "x": 0,
            "y": -2,
            "z": 6,
            "elements": [
                "appliedenergistics2:sky_stone_small_brick_slab@0"
            ]
        },
        {
            "x": 0,
            "y": -1,
            "z": 6,
            "elements": [
                "appliedenergistics2:cable_bus@0"
            ]
        },
        {
            "x": -6,
            "y": -2,
            "z": 3,
            "elements": [
                "appliedenergistics2:sky_stone_brick_stairs@0"
            ]
        },
        {
            "x": 1,
            "y": -2,
            "z": 5,
            "elements": [
                "appliedenergistics2:sky_stone_small_brick_slab@0"
            ]
        },
        {
            "x": 5,
            "y": -1,
            "z": 7,
            "elements": [
                "astralsorcery:blockblackmarble@2"
            ]
        },
        {
            "x": 2,
            "y": -2,
            "z": 4,
            "elements": [
                "appliedenergistics2:sky_stone_brick_stairs@0"
            ]
        },
        {
            "x": 3,
            "y": -2,
            "z": 6,
            "elements": [
                "appliedenergistics2:sky_stone_brick_stairs@2"
            ]
        },
        {
            "x": -3,
            "y": 3,
            "z": 4,
            "elements": [
                "astralsorcery:blockblackmarble@2"
            ]
        },
        {
            "x": 3,
            "y": 2,
            "z": 7,
            "elements": [
                "astralsorcery:blockblackmarble@2"
            ]
        },
        {
            "x": -3,
            "y": 4,
            "z": 4,
            "elements": [
                "appliedenergistics2:smooth_sky_stone_block@0"
            ]
        },
        {
            "x": 5,
            "y": -2,
            "z": 7,
            "elements": [
                "appliedenergistics2:smooth_sky_stone_block@0"
            ]
        },
        {
            "x": 4,
            "y": 4,
            "z": 6,
            "elements": [
                "appliedenergistics2:sky_stone_brick_stairs@6"
            ]
        },
        {
            "x": 5,
            "y": -2,
            "z": 4,
            "elements": [
                "appliedenergistics2:smooth_sky_stone_block@0"
            ]
        },
        {
            "x": 4,
            "y": 1,
            "z": 7,
            "elements": [
                "enderio:block_dark_fused_quartz@0"
            ]
        },
        {
            "x": 3,
            "y": 0,
            "z": 4,
            "elements": [
                "astralsorcery:blockblackmarble@2"
            ]
        },
        {
            "x": 3,
            "y": 3,
            "z": 7,
            "elements": [
                "astralsorcery:blockblackmarble@2"
            ]
        },
        {
            "x": 3,
            "y": 4,
            "z": 7,
            "elements": [
                "appliedenergistics2:smooth_sky_stone_block@0"
            ]
        },
        {
            "x": -3,
            "y": 0,
            "z": 4,
            "elements": [
                "astralsorcery:blockblackmarble@2"
            ]
        },
        {
            "x": 2,
            "y": 2,
            "z": 0,
            "elements": [
                "modularmachinery:blockcasing@5"
            ]
        },
        {
            "x": 6,
            "y": -2,
            "z": 6,
            "elements": [
                "appliedenergistics2:sky_stone_brick_stairs@2"
            ]
        },
        {
            "x": -1,
            "y": -2,
            "z": 10,
            "elements": [
                "appliedenergistics2:sky_stone_small_brick_slab@0"
            ]
        },
        {
            "x": 3,
            "y": 1,
            "z": 4,
            "elements": [
                "astralsorcery:blockblackmarble@2"
            ]
        },
        {
            "x": 3,
            "y": 2,
            "z": 3,
            "elements": [
                "enderio:block_dark_fused_quartz@0"
            ]
        },
        {
            "x": 0,
            "y": -2,
            "z": 9,
            "elements": [
                "appliedenergistics2:sky_stone_small_brick_slab@0"
            ]
        },
        {
            "x": -4,
            "y": -1,
            "z": 4,
            "elements": [
                "enderio:block_dark_fused_quartz@0"
            ]
        },
        {
            "x": 3,
            "y": 2,
            "z": 4,
            "elements": [
                "astralsorcery:blockblackmarble@2"
            ]
        },
        {
            "x": 5,
            "y": -2,
            "z": 3,
            "elements": [
                "appliedenergistics2:smooth_sky_stone_block@0"
            ]
        },
        {
            "x": -2,
            "y": 4,
            "z": 9,
            "elements": [
                "appliedenergistics2:sky_stone_brick_stairs@5"
            ]
        },
        {
            "x": 2,
            "y": 1,
            "z": 0,
            "elements": [
                "appliedenergistics2:controller@0"
            ]
        },
        {
            "x": -6,
            "y": 4,
            "z": 4,
            "elements": [
                "appliedenergistics2:sky_stone_brick_stairs@4"
            ]
        },
        {
            "x": -2,
            "y": 0,
            "z": 0,
            "elements": [
                "modularmachinery:blockoutputbus",
                "modularmachinery:blockmeitemoutputbus",
                "modularmachinery:blockmepatternprovider"
            ]
        },
        {
            "x": 5,
            "y": -1,
            "z": 3,
            "elements": [
                "enderio:block_dark_fused_quartz@0"
            ]
        },
        {
            "x": -4,
            "y": -2,
            "z": 4,
            "elements": [
                "appliedenergistics2:smooth_sky_stone_block@0"
            ]
        },
        {
            "x": -5,
            "y": -2,
            "z": 5,
            "elements": [
                "appliedenergistics2:sky_stone_brick_stairs@3"
            ]
        },
        {
            "x": 4,
            "y": 1,
            "z": 9,
            "elements": [
                "enderio:block_dark_fused_quartz@0"
            ]
        },
        {
            "x": -3,
            "y": 4,
            "z": 10,
            "elements": [
                "appliedenergistics2:sky_stone_brick_stairs@7"
            ]
        },
        {
            "x": 3,
            "y": 4,
            "z": 3,
            "elements": [
                "appliedenergistics2:smooth_sky_stone_block@0"
            ]
        },
        {
            "x": 5,
            "y": -2,
            "z": 6,
            "elements": [
                "appliedenergistics2:sky_stone_brick_stairs@2"
            ]
        },
        {
            "x": 4,
            "y": 2,
            "z": 9,
            "elements": [
                "enderio:block_dark_fused_quartz@0"
            ]
        },
        {
            "x": 2,
            "y": -2,
            "z": 10,
            "elements": [
                "appliedenergistics2:sky_stone_brick_stairs@3"
            ]
        },
        {
            "x": 3,
            "y": 0,
            "z": 7,
            "elements": [
                "astralsorcery:blockblackmarble@2"
            ]
        },
        {
            "x": -4,
            "y": -2,
            "z": 1,
            "elements": [
                "appliedenergistics2:sky_stone_brick_stairs@2"
            ]
        },
        {
            "x": 3,
            "y": 3,
            "z": 3,
            "elements": [
                "enderio:block_dark_fused_quartz@0"
            ]
        },
        {
            "x": -2,
            "y": -2,
            "z": 5,
            "elements": [
                "appliedenergistics2:sky_stone_brick_stairs@1"
            ]
        },
        {
            "x": 6,
            "y": -2,
            "z": 9,
            "elements": [
                "appliedenergistics2:sky_stone_brick_stairs@1"
            ]
        },
        {
            "x": 4,
            "y": 3,
            "z": 9,
            "elements": [
                "enderio:block_dark_fused_quartz@0"
            ]
        },
        {
            "x": 2,
            "y": -2,
            "z": 7,
            "elements": [
                "appliedenergistics2:sky_stone_brick_stairs@0"
            ]
        },
        {
            "x": 3,
            "y": 1,
            "z": 7,
            "elements": [
                "astralsorcery:blockblackmarble@2"
            ]
        },
        {
            "x": 3,
            "y": 4,
            "z": 6,
            "elements": [
                "appliedenergistics2:sky_stone_brick_stairs@6"
            ]
        },
        {
            "x": 4,
            "y": 4,
            "z": 9,
            "elements": [
                "appliedenergistics2:smooth_sky_stone_block@0"
            ]
        },
        {
            "x": 3,
            "y": -1,
            "z": 3,
            "elements": [
                "enderio:block_dark_fused_quartz@0"
            ]
        },
        {
            "x": -5,
            "y": -2,
            "z": 9,
            "elements": [
                "appliedenergistics2:smooth_sky_stone_block@0"
            ]
        },
        {
            "x": -2,
            "y": -2,
            "z": 4,
            "elements": [
                "appliedenergistics2:sky_stone_brick_stairs@1"
            ]
        },
        {
            "x": 2,
            "y": -1,
            "z": 8,
            "elements": [
                "appliedenergistics2:cable_bus@0"
            ]
        },
        {
            "x": -5,
            "y": 3,
            "z": 9,
            "elements": [
                "astralsorcery:blockblackmarble@2"
            ]
        },
        {
            "x": -4,
            "y": 0,
            "z": 4,
            "elements": [
                "enderio:block_dark_fused_quartz@0"
            ]
        },
        {
            "x": 5,
            "y": -2,
            "z": 5,
            "elements": [
                "appliedenergistics2:sky_stone_brick_stairs@3"
            ]
        },
        {
            "x": -4,
            "y": 1,
            "z": 4,
            "elements": [
                "enderio:block_dark_fused_quartz@0"
            ]
        },
        {
            "x": 6,
            "y": -2,
            "z": 3,
            "elements": [
                "appliedenergistics2:sky_stone_brick_stairs@1"
            ]
        },
        {
            "x": -3,
            "y": 0,
            "z": 9,
            "elements": [
                "astralsorcery:blockblackmarble@2"
            ]
        },
        {
            "x": 4,
            "y": 2,
            "z": 3,
            "elements": [
                "astralsorcery:fluidblockliquidstarlight@0"
            ]
        },
        {
            "x": -3,
            "y": 3,
            "z": 8,
            "elements": [
                "enderio:block_dark_fused_quartz@0"
            ]
        },
        {
            "x": 4,
            "y": -1,
            "z": 2,
            "elements": [
                "enderio:block_dark_fused_quartz@0"
            ]
        },
        {
            "x": -4,
            "y": -1,
            "z": 9,
            "elements": [
                "enderio:block_dark_fused_quartz@0"
            ]
        },
        {
            "x": 4,
            "y": 0,
            "z": 3,
            "elements": [
                "astralsorcery:fluidblockliquidstarlight@0"
            ]
        },
        {
            "x": -5,
            "y": -1,
            "z": 4,
            "elements": [
                "astralsorcery:blockblackmarble@2"
            ]
        },
        {
            "x": 5,
            "y": -2,
            "z": 8,
            "elements": [
                "appliedenergistics2:smooth_sky_stone_block@0"
            ]
        },
        {
            "x": -5,
            "y": 4,
            "z": 9,
            "elements": [
                "appliedenergistics2:smooth_sky_stone_block@0"
            ]
        },
        {
            "x": 3,
            "y": 0,
            "z": 8,
            "elements": [
                "enderio:block_dark_fused_quartz@0"
            ]
        },
        {
            "x": -4,
            "y": 2,
            "z": 4,
            "elements": [
                "enderio:block_dark_fused_quartz@0"
            ]
        },
        {
            "x": -3,
            "y": 4,
            "z": 8,
            "elements": [
                "appliedenergistics2:smooth_sky_stone_block@0"
            ]
        },
        {
            "x": 4,
            "y": 1,
            "z": 3,
            "elements": [
                "astralsorcery:fluidblockliquidstarlight@0"
            ]
        },
        {
            "x": 4,
            "y": -2,
            "z": 2,
            "elements": [
                "appliedenergistics2:smooth_sky_stone_block@0"
            ]
        },
        {
            "x": -5,
            "y": 3,
            "z": 3,
            "elements": [
                "enderio:block_dark_fused_quartz@0"
            ]
        },
        {
            "x": -4,
            "y": -2,
            "z": 9,
            "elements": [
                "appliedenergistics2:smooth_sky_stone_block@0"
            ]
        },
        {
            "x": -3,
            "y": 1,
            "z": 8,
            "elements": [
                "enderio:block_dark_fused_quartz@0"
            ]
        },
        {
            "x": 3,
            "y": 4,
            "z": 5,
            "elements": [
                "appliedenergistics2:sky_stone_brick_stairs@7"
            ]
        },
        {
            "x": 1,
            "y": -2,
            "z": 4,
            "elements": [
                "appliedenergistics2:sky_stone_small_brick_slab@0"
            ]
        },
        {
            "x": 5,
            "y": -1,
            "z": 8,
            "elements": [
                "enderio:block_dark_fused_quartz@0"
            ]
        },
        {
            "x": -5,
            "y": 2,
            "z": 9,
            "elements": [
                "astralsorcery:blockblackmarble@2"
            ]
        },
        {
            "x": 4,
            "y": -2,
            "z": 5,
            "elements": [
                "appliedenergistics2:sky_stone_brick_stairs@3"
            ]
        },
        {
            "x": 0,
            "y": -1,
            "z": 3,
            "elements": [
                "appliedenergistics2:cable_bus@0"
            ]
        },
        {
            "x": -2,
            "y": 4,
            "z": 4,
            "elements": [
                "appliedenergistics2:sky_stone_brick_stairs@5"
            ]
        },
        {
            "x": -4,
            "y": 0,
            "z": 9,
            "elements": [
                "enderio:block_dark_fused_quartz@0"
            ]
        },
        {
            "x": -1,
            "y": -2,
            "z": 8,
            "elements": [
                "appliedenergistics2:sky_stone_small_brick_slab@0"
            ]
        },
        {
            "x": -2,
            "y": 4,
            "z": 3,
            "elements": [
                "appliedenergistics2:sky_stone_brick_stairs@5"
            ]
        },
        {
            "x": 2,
            "y": -2,
            "z": 8,
            "elements": [
                "appliedenergistics2:sky_stone_brick_stairs@0"
            ]
        },
        {
            "x": -3,
            "y": 2,
            "z": 8,
            "elements": [
                "enderio:block_dark_fused_quartz@0"
            ]
        },
        {
            "x": -5,
            "y": -1,
            "z": 9,
            "elements": [
                "astralsorcery:blockblackmarble@2"
            ]
        },
        {
            "x": -6,
            "y": 4,
            "z": 9,
            "elements": [
                "appliedenergistics2:sky_stone_brick_stairs@4"
            ]
        },
        {
            "x": 3,
            "y": -2,
            "z": 10,
            "elements": [
                "appliedenergistics2:sky_stone_brick_stairs@3"
            ]
        },
        {
            "x": -5,
            "y": 1,
            "z": 9,
            "elements": [
                "astralsorcery:blockblackmarble@2"
            ]
        },
        {
            "x": 5,
            "y": 3,
            "z": 2,
            "elements": [
                "astralsorcery:blockblackmarble@2"
            ]
        },
        {
            "x": -5,
            "y": 0,
            "z": 9,
            "elements": [
                "astralsorcery:blockblackmarble@2"
            ]
        },
        {
            "x": -3,
            "y": -2,
            "z": 9,
            "elements": [
                "appliedenergistics2:smooth_sky_stone_block@0"
            ]
        },
        {
            "x": 4,
            "y": 4,
            "z": 7,
            "elements": [
                "appliedenergistics2:smooth_sky_stone_block@0"
            ]
        },
        {
            "x": 0,
            "y": -2,
            "z": 4,
            "elements": [
                "appliedenergistics2:sky_stone_small_brick_slab@0"
            ]
        },
        {
            "x": -3,
            "y": 3,
            "z": 9,
            "elements": [
                "astralsorcery:blockblackmarble@2"
            ]
        },
        {
            "x": 5,
            "y": 4,
            "z": 2,
            "elements": [
                "appliedenergistics2:smooth_sky_stone_block@0"
            ]
        },
        {
            "x": 2,
            "y": 4,
            "z": 5,
            "elements": [
                "appliedenergistics2:sky_stone_brick_stairs@7"
            ]
        },
        {
            "x": -5,
            "y": 1,
            "z": 3,
            "elements": [
                "enderio:block_dark_fused_quartz@0"
            ]
        },
        {
            "x": -5,
            "y": 3,
            "z": 4,
            "elements": [
                "astralsorcery:blockblackmarble@2"
            ]
        },
        {
            "x": -3,
            "y": 4,
            "z": 9,
            "elements": [
                "appliedenergistics2:smooth_sky_stone_block@0"
            ]
        },
        {
            "x": -5,
            "y": 4,
            "z": 4,
            "elements": [
                "appliedenergistics2:smooth_sky_stone_block@0"
            ]
        },
        {
            "x": 6,
            "y": -2,
            "z": 10,
            "elements": [
                "appliedenergistics2:sky_stone_brick_stairs@1"
            ]
        },
        {
            "x": 2,
            "y": 4,
            "z": 2,
            "elements": [
                "appliedenergistics2:sky_stone_brick_stairs@4"
            ]
        },
        {
            "x": -3,
            "y": -1,
            "z": 4,
            "elements": [
                "astralsorcery:blockblackmarble@2"
            ]
        },
        {
            "x": 5,
            "y": 2,
            "z": 2,
            "elements": [
                "astralsorcery:blockblackmarble@2"
            ]
        },
        {
            "x": -5,
            "y": 2,
            "z": 3,
            "elements": [
                "enderio:block_dark_fused_quartz@0"
            ]
        },
        {
            "x": -4,
            "y": -2,
            "z": 3,
            "elements": [
                "appliedenergistics2:smooth_sky_stone_block@0"
            ]
        },
        {
            "x": 4,
            "y": 4,
            "z": 10,
            "elements": [
                "appliedenergistics2:sky_stone_brick_stairs@7"
            ]
        },
        {
            "x": 6,
            "y": 4,
            "z": 6,
            "elements": [
                "appliedenergistics2:sky_stone_brick_stairs@5"
            ]
        },
        {
            "x": -1,
            "y": -2,
            "z": 4,
            "elements": [
                "appliedenergistics2:sky_stone_small_brick_slab@0"
            ]
        },
        {
            "x": -1,
            "y": -1,
            "z": 8,
            "elements": [
                "appliedenergistics2:cable_bus@0"
            ]
        },
        {
            "x": 5,
            "y": 1,
            "z": 2,
            "elements": [
                "astralsorcery:blockblackmarble@2"
            ]
        },
        {
            "x": 6,
            "y": 4,
            "z": 8,
            "elements": [
                "appliedenergistics2:sky_stone_brick_stairs@5"
            ]
        },
        {
            "x": 2,
            "y": -2,
            "z": 5,
            "elements": [
                "appliedenergistics2:sky_stone_brick_stairs@3"
            ]
        },
        {
            "x": -6,
            "y": -2,
            "z": 9,
            "elements": [
                "appliedenergistics2:sky_stone_brick_stairs@0"
            ]
        },
        {
            "x": 5,
            "y": 4,
            "z": 5,
            "elements": [
                "appliedenergistics2:sky_stone_brick_stairs@7"
            ]
        },
        {
            "x": -3,
            "y": 2,
            "z": 9,
            "elements": [
                "astralsorcery:blockblackmarble@2"
            ]
        },
        {
            "x": -3,
            "y": 1,
            "z": 4,
            "elements": [
                "astralsorcery:blockblackmarble@2"
            ]
        },
        {
            "x": 4,
            "y": 2,
            "z": 7,
            "elements": [
                "enderio:block_dark_fused_quartz@0"
            ]
        },
        {
            "x": -4,
            "y": 3,
            "z": 4,
            "elements": [
                "enderio:block_dark_fused_quartz@0"
            ]
        },
        {
            "x": 4,
            "y": 3,
            "z": 7,
            "elements": [
                "enderio:block_dark_fused_quartz@0"
            ]
        },
        {
            "x": -3,
            "y": -1,
            "z": 9,
            "elements": [
                "astralsorcery:blockblackmarble@2"
            ]
        },
        {
            "x": -4,
            "y": 4,
            "z": 4,
            "elements": [
                "appliedenergistics2:smooth_sky_stone_block@0"
            ]
        },
        {
            "x": 6,
            "y": -2,
            "z": 7,
            "elements": [
                "appliedenergistics2:sky_stone_brick_stairs@1"
            ]
        },
        {
            "x": -5,
            "y": 0,
            "z": 3,
            "elements": [
                "enderio:block_dark_fused_quartz@0"
            ]
        },
        {
            "x": 5,
            "y": 0,
            "z": 2,
            "elements": [
                "astralsorcery:blockblackmarble@2"
            ]
        },
        {
            "x": -3,
            "y": 1,
            "z": 9,
            "elements": [
                "astralsorcery:blockblackmarble@2"
            ]
        },
        {
            "x": 3,
            "y": -2,
            "z": 3,
            "elements": [
                "appliedenergistics2:smooth_sky_stone_block@0"
            ]
        },
        {
            "x": -3,
            "y": 2,
            "z": 4,
            "elements": [
                "astralsorcery:blockblackmarble@2"
            ]
        },
        {
            "x": -3,
            "y": 1,
            "z": 3,
            "elements": [
                "enderio:block_dark_fused_quartz@0"
            ]
        },
        {
            "x": -1,
            "y": -1,
            "z": 3,
            "elements": [
                "appliedenergistics2:cable_bus@0"
            ]
        },
        {
            "x": -3,
            "y": 4,
            "z": 3,
            "elements": [
                "appliedenergistics2:smooth_sky_stone_block@0"
            ]
        },
        {
            "x": -6,
            "y": -2,
            "z": 4,
            "elements": [
                "appliedenergistics2:sky_stone_brick_stairs@0"
            ]
        },
        {
            "x": -3,
            "y": 2,
            "z": 3,
            "elements": [
                "enderio:block_dark_fused_quartz@0"
            ]
        },
        {
            "x": -6,
            "y": 4,
            "z": 3,
            "elements": [
                "appliedenergistics2:sky_stone_brick_stairs@4"
            ]
        },
        {
            "x": 0,
            "y": -2,
            "z": 10,
            "elements": [
                "appliedenergistics2:sky_stone_small_brick_slab@0"
            ]
        },
        {
            "x": 2,
            "y": -2,
            "z": 3,
            "elements": [
                "appliedenergistics2:sky_stone_brick_stairs@0"
            ]
        },
        {
            "x": -3,
            "y": -2,
            "z": 4,
            "elements": [
                "appliedenergistics2:smooth_sky_stone_block@0"
            ]
        },
        {
            "x": -2,
            "y": 4,
            "z": 10,
            "elements": [
                "appliedenergistics2:sky_stone_brick_stairs@5"
            ]
        },
        {
            "x": -5,
            "y": 1,
            "z": 4,
            "elements": [
                "astralsorcery:blockblackmarble@2"
            ]
        },
        {
            "x": -4,
            "y": -1,
            "z": 3,
            "elements": [
                "astralsorcery:fluidblockliquidstarlight@0"
            ]
        },
        {
            "x": 2,
            "y": 4,
            "z": 4,
            "elements": [
                "appliedenergistics2:sky_stone_brick_stairs@4"
            ]
        },
        {
            "x": -5,
            "y": 2,
            "z": 4,
            "elements": [
                "astralsorcery:blockblackmarble@2"
            ]
        },
        {
            "x": -3,
            "y": 0,
            "z": 3,
            "elements": [
                "enderio:block_dark_fused_quartz@0"
            ]
        },
        {
            "x": -3,
            "y": -2,
            "z": 3,
            "elements": [
                "appliedenergistics2:smooth_sky_stone_block@0"
            ]
        },
        {
            "x": 6,
            "y": 4,
            "z": 1,
            "elements": [
                "appliedenergistics2:sky_stone_brick_stairs@6"
            ]
        },
        {
            "x": -4,
            "y": 3,
            "z": 3,
            "elements": [
                "astralsorcery:fluidblockliquidstarlight@0"
            ]
        },
        {
            "x": 3,
            "y": 4,
            "z": 8,
            "elements": [
                "appliedenergistics2:smooth_sky_stone_block@0"
            ]
        },
        {
            "x": 0,
            "y": -1,
            "z": 4,
            "elements": [
                "appliedenergistics2:cable_bus@0"
            ]
        },
        {
            "x": 3,
            "y": 3,
            "z": 8,
            "elements": [
                "enderio:block_dark_fused_quartz@0"
            ]
        },
        {
            "x": -3,
            "y": -1,
            "z": 3,
            "elements": [
                "enderio:block_dark_fused_quartz@0"
            ]
        },
        {
            "x": -4,
            "y": 2,
            "z": 9,
            "elements": [
                "enderio:block_dark_fused_quartz@0"
            ]
        },
        {
            "x": -6,
            "y": -2,
            "z": 10,
            "elements": [
                "appliedenergistics2:sky_stone_brick_stairs@3"
            ]
        },
        {
            "x": -5,
            "y": 4,
            "z": 3,
            "elements": [
                "appliedenergistics2:smooth_sky_stone_block@0"
            ]
        },
        {
            "x": 1,
            "y": -2,
            "z": 9,
            "elements": [
                "appliedenergistics2:sky_stone_small_brick_slab@0"
            ]
        },
        {
            "x": 3,
            "y": -2,
            "z": 4,
            "elements": [
                "appliedenergistics2:smooth_sky_stone_block@0"
            ]
        },
        {
            "x": -4,
            "y": 1,
            "z": 9,
            "elements": [
                "enderio:block_dark_fused_quartz@0"
            ]
        },
        {
            "x": 0,
            "y": -2,
            "z": 3,
            "elements": [
                "appliedenergistics2:sky_stone_small_brick_slab@0"
            ]
        },
        {
            "x": -2,
            "y": -2,
            "z": 9,
            "elements": [
                "appliedenergistics2:sky_stone_brick_stairs@1"
            ]
        },
        {
            "x": -3,
            "y": 3,
            "z": 3,
            "elements": [
                "enderio:block_dark_fused_quartz@0"
            ]
        },
        {
            "x": -4,
            "y": 3,
            "z": 9,
            "elements": [
                "enderio:block_dark_fused_quartz@0"
            ]
        },
        {
            "x": -5,
            "y": 0,
            "z": 4,
            "elements": [
                "astralsorcery:blockblackmarble@2"
            ]
        },
        {
            "x": -2,
            "y": -1,
            "z": 3,
            "elements": [
                "appliedenergistics2:cable_bus@0"
            ]
        },
        {
            "x": -3,
            "y": -2,
            "z": 10,
            "elements": [
                "appliedenergistics2:sky_stone_brick_stairs@3"
            ]
        },
        {
            "x": -4,
            "y": 4,
            "z": 3,
            "elements": [
                "modularmachinery:blockcasing@1"
            ]
        },
        {
            "x": 3,
            "y": 1,
            "z": 8,
            "elements": [
                "enderio:block_dark_fused_quartz@0"
            ]
        },
        {
            "x": -4,
            "y": 4,
            "z": 9,
            "elements": [
                "appliedenergistics2:smooth_sky_stone_block@0"
            ]
        },
        {
            "x": -1,
            "y": -2,
            "z": 3,
            "elements": [
                "appliedenergistics2:sky_stone_small_brick_slab@0"
            ]
        },
        {
            "x": 3,
            "y": 2,
            "z": 8,
            "elements": [
                "enderio:block_dark_fused_quartz@0"
            ]
        },
        {
            "x": 3,
            "y": 3,
            "z": 2,
            "elements": [
                "astralsorcery:blockblackmarble@2"
            ]
        },
        {
            "x": 4,
            "y": 1,
            "z": 4,
            "elements": [
                "enderio:block_dark_fused_quartz@0"
            ]
        },
        {
            "x": -4,
            "y": -2,
            "z": 2,
            "elements": [
                "appliedenergistics2:smooth_sky_stone_block@0"
            ]
        },
        {
            "x": -6,
            "y": -2,
            "z": 8,
            "elements": [
                "appliedenergistics2:sky_stone_brick_stairs@0"
            ]
        },
        {
            "x": 3,
            "y": 3,
            "z": 9,
            "elements": [
                "astralsorcery:blockblackmarble@2"
            ]
        },
        {
            "x": -5,
            "y": -1,
            "z": 3,
            "elements": [
                "enderio:block_dark_fused_quartz@0"
            ]
        },
        {
            "x": 4,
            "y": 2,
            "z": 4,
            "elements": [
                "enderio:block_dark_fused_quartz@0"
            ]
        },
        {
            "x": 3,
            "y": 2,
            "z": 2,
            "elements": [
                "astralsorcery:blockblackmarble@2"
            ]
        },
        {
            "x": -2,
            "y": -2,
            "z": 3,
            "elements": [
                "appliedenergistics2:sky_stone_brick_stairs@1"
            ]
        },
        {
            "x": 5,
            "y": 0,
            "z": 9,
            "elements": [
                "astralsorcery:blockblackmarble@2"
            ]
        },
        {
            "x": -4,
            "y": -1,
            "z": 2,
            "elements": [
                "enderio:block_dark_fused_quartz@0"
            ]
        },
        {
            "x": 4,
            "y": -1,
            "z": 9,
            "elements": [
                "enderio:block_dark_fused_quartz@0"
            ]
        },
        {
            "x": -4,
            "y": 0,
            "z": 3,
            "elements": [
                "astralsorcery:fluidblockliquidstarlight@0"
            ]
        },
        {
            "x": -6,
            "y": -2,
            "z": 1,
            "elements": [
                "appliedenergistics2:sky_stone_brick_stairs@2"
            ]
        },
        {
            "x": 1,
            "y": -2,
            "z": 7,
            "elements": [
                "appliedenergistics2:sky_stone_small_brick_slab@0"
            ]
        },
        {
            "x": 3,
            "y": 4,
            "z": 9,
            "elements": [
                "appliedenergistics2:smooth_sky_stone_block@0"
            ]
        },
        {
            "x": -4,
            "y": 1,
            "z": 3,
            "elements": [
                "astralsorcery:fluidblockliquidstarlight@0"
            ]
        },
        {
            "x": 3,
            "y": 1,
            "z": 9,
            "elements": [
                "astralsorcery:blockblackmarble@2"
            ]
        },
        {
            "x": -5,
            "y": -2,
            "z": 2,
            "elements": [
                "appliedenergistics2:smooth_sky_stone_block@0"
            ]
        },
        {
            "x": 3,
            "y": -1,
            "z": 4,
            "elements": [
                "astralsorcery:blockblackmarble@2"
            ]
        },
        {
            "x": 3,
            "y": 1,
            "z": 2,
            "elements": [
                "astralsorcery:blockblackmarble@2"
            ]
        },
        {
            "x": 4,
            "y": -2,
            "z": 9,
            "elements": [
                "appliedenergistics2:smooth_sky_stone_block@0"
            ]
        },
        {
            "x": -5,
            "y": 0,
            "z": 8,
            "elements": [
                "enderio:block_dark_fused_quartz@0"
            ]
        },
        {
            "x": 3,
            "y": 2,
            "z": 9,
            "elements": [
                "astralsorcery:blockblackmarble@2"
            ]
        },
        {
            "x": -5,
            "y": -1,
            "z": 2,
            "elements": [
                "astralsorcery:blockblackmarble@2"
            ]
        },
        {
            "x": -4,
            "y": 2,
            "z": 3,
            "elements": [
                "astralsorcery:fluidblockliquidstarlight@0"
            ]
        },
        {
            "x": 5,
            "y": 4,
            "z": 6,
            "elements": [
                "appliedenergistics2:sky_stone_brick_stairs@6"
            ]
        },
        {
            "x": 4,
            "y": -2,
            "z": 4,
            "elements": [
                "appliedenergistics2:smooth_sky_stone_block@0"
            ]
        },
        {
            "x": 3,
            "y": 0,
            "z": 2,
            "elements": [
                "astralsorcery:blockblackmarble@2"
            ]
        },
        {
            "x": 4,
            "y": 0,
            "z": 4,
            "elements": [
                "enderio:block_dark_fused_quartz@0"
            ]
        },
        {
            "x": 1,
            "y": -2,
            "z": 3,
            "elements": [
                "appliedenergistics2:sky_stone_small_brick_slab@0"
            ]
        },
        {
            "x": 2,
            "y": 4,
            "z": 9,
            "elements": [
                "appliedenergistics2:sky_stone_brick_stairs@4"
            ]
        },
        {
            "x": 0,
            "y": -1,
            "z": 8,
            "elements": [
                "appliedenergistics2:cable_bus@0"
            ]
        },
        {
            "x": 2,
            "y": -2,
            "z": 2,
            "elements": [
                "appliedenergistics2:sky_stone_brick_stairs@0"
            ]
        },
        {
            "x": 1,
            "y": -1,
            "z": 3,
            "elements": [
                "appliedenergistics2:cable_bus@0"
            ]
        },
        {
            "x": 5,
            "y": -2,
            "z": 9,
            "elements": [
                "appliedenergistics2:smooth_sky_stone_block@0"
            ]
        },
        {
            "x": -5,
            "y": -1,
            "z": 7,
            "elements": [
                "astralsorcery:blockblackmarble@2"
            ]
        },
        {
            "x": 3,
            "y": 0,
            "z": 9,
            "elements": [
                "astralsorcery:blockblackmarble@2"
            ]
        },
        {
            "x": -4,
            "y": 4,
            "z": 7,
            "elements": [
                "appliedenergistics2:smooth_sky_stone_block@0"
            ]
        },
        {
            "x": -3,
            "y": 3,
            "z": 2,
            "elements": [
                "astralsorcery:blockblackmarble@2"
            ]
        },
        {
            "x": 4,
            "y": -1,
            "z": 4,
            "elements": [
                "enderio:block_dark_fused_quartz@0"
            ]
        },
        {
            "x": 0,
            "y": -2,
            "z": 8,
            "elements": [
                "appliedenergistics2:sky_stone_small_brick_slab@0"
            ]
        },
        {
            "x": 5,
            "y": 3,
            "z": 9,
            "elements": [
                "astralsorcery:blockblackmarble@2"
            ]
        },
        {
            "x": 4,
            "y": -2,
            "z": 3,
            "elements": [
                "appliedenergistics2:smooth_sky_stone_block@0"
            ]
        },
        {
            "x": 1,
            "y": -2,
            "z": 6,
            "elements": [
                "appliedenergistics2:sky_stone_small_brick_slab@0"
            ]
        },
        {
            "x": -5,
            "y": -2,
            "z": 7,
            "elements": [
                "appliedenergistics2:smooth_sky_stone_block@0"
            ]
        },
        {
            "x": 5,
            "y": 4,
            "z": 9,
            "elements": [
                "appliedenergistics2:smooth_sky_stone_block@0"
            ]
        },
        {
            "x": -6,
            "y": 4,
            "z": 2,
            "elements": [
                "appliedenergistics2:sky_stone_brick_stairs@4"
            ]
        },
        {
            "x": 5,
            "y": 0,
            "z": 4,
            "elements": [
                "astralsorcery:blockblackmarble@2"
            ]
        },
        {
            "x": -3,
            "y": 2,
            "z": 2,
            "elements": [
                "astralsorcery:blockblackmarble@2"
            ]
        },
        {
            "x": 5,
            "y": 1,
            "z": 4,
            "elements": [
                "astralsorcery:blockblackmarble@2"
            ]
        },
        {
            "x": 5,
            "y": 1,
            "z": 9,
            "elements": [
                "astralsorcery:blockblackmarble@2"
            ]
        },
        {
            "x": -3,
            "y": 0,
            "z": 2,
            "elements": [
                "astralsorcery:blockblackmarble@2"
            ]
        },
        {
            "x": -4,
            "y": 1,
            "z": 7,
            "elements": [
                "enderio:block_dark_fused_quartz@0"
            ]
        },
        {
            "x": -5,
            "y": -2,
            "z": 3,
            "elements": [
                "appliedenergistics2:smooth_sky_stone_block@0"
            ]
        },
        {
            "x": 4,
            "y": 3,
            "z": 4,
            "elements": [
                "enderio:block_dark_fused_quartz@0"
            ]
        },
        {
            "x": 5,
            "y": -1,
            "z": 2,
            "elements": [
                "astralsorcery:blockblackmarble@2"
            ]
        },
        {
            "x": 4,
            "y": 4,
            "z": 4,
            "elements": [
                "appliedenergistics2:smooth_sky_stone_block@0"
            ]
        },
        {
            "x": -3,
            "y": 1,
            "z": 2,
            "elements": [
                "astralsorcery:blockblackmarble@2"
            ]
        },
        {
            "x": 2,
            "y": -2,
            "z": 9,
            "elements": [
                "appliedenergistics2:sky_stone_brick_stairs@0"
            ]
        },
        {
            "x": 4,
            "y": 4,
            "z": 1,
            "elements": [
                "appliedenergistics2:sky_stone_brick_stairs@6"
            ]
        },
        {
            "x": 5,
            "y": 2,
            "z": 9,
            "elements": [
                "astralsorcery:blockblackmarble@2"
            ]
        },
        {
            "x": 6,
            "y": -2,
            "z": 4,
            "elements": [
                "appliedenergistics2:sky_stone_brick_stairs@1"
            ]
        },
        {
            "x": 5,
            "y": 2,
            "z": 4,
            "elements": [
                "astralsorcery:blockblackmarble@2"
            ]
        },
        {
            "x": 5,
            "y": -1,
            "z": 9,
            "elements": [
                "astralsorcery:blockblackmarble@2"
            ]
        },
        {
            "x": -4,
            "y": 3,
            "z": 7,
            "elements": [
                "enderio:block_dark_fused_quartz@0"
            ]
        },
        {
            "x": -2,
            "y": -1,
            "z": 8,
            "elements": [
                "appliedenergistics2:cable_bus@0"
            ]
        },
        {
            "x": -2,
            "y": 4,
            "z": 8,
            "elements": [
                "appliedenergistics2:sky_stone_brick_stairs@5"
            ]
        },
        {
            "x": -2,
            "y": -2,
            "z": 7,
            "elements": [
                "appliedenergistics2:sky_stone_brick_stairs@1"
            ]
        },
        {
            "x": 5,
            "y": -2,
            "z": 2,
            "elements": [
                "appliedenergistics2:smooth_sky_stone_block@0"
            ]
        },
        {
            "x": -1,
            "y": -2,
            "z": 9,
            "elements": [
                "appliedenergistics2:sky_stone_small_brick_slab@0"
            ]
        },
        {
            "x": -4,
            "y": 0,
            "z": 7,
            "elements": [
                "enderio:block_dark_fused_quartz@0"
            ]
        },
        {
            "x": 0,
            "y": -2,
            "z": 2,
            "elements": [
                "appliedenergistics2:sky_stone_small_brick_slab@0"
            ]
        },
        {
            "x": 2,
            "y": 4,
            "z": 7,
            "elements": [
                "appliedenergistics2:sky_stone_brick_stairs@4"
            ]
        },
        {
            "x": 5,
            "y": 4,
            "z": 3,
            "elements": [
                "appliedenergistics2:smooth_sky_stone_block@0"
            ]
        },
        {
            "x": -4,
            "y": 1,
            "z": 8,
            "elements": [
                "astralsorcery:fluidblockliquidstarlight@0"
            ]
        },
        {
            "x": -5,
            "y": 4,
            "z": 1,
            "elements": [
                "appliedenergistics2:sky_stone_brick_stairs@6"
            ]
        },
        {
            "x": -2,
            "y": -2,
            "z": 8,
            "elements": [
                "appliedenergistics2:sky_stone_brick_stairs@1"
            ]
        },
        {
            "x": -4,
            "y": 4,
            "z": 2,
            "elements": [
                "appliedenergistics2:smooth_sky_stone_block@0"
            ]
        },
        {
            "x": -4,
            "y": 2,
            "z": 8,
            "elements": [
                "astralsorcery:fluidblockliquidstarlight@0"
            ]
        },
        {
            "x": 0,
            "y": -1,
            "z": 2,
            "elements": [
                "appliedenergistics2:cable_bus@0"
            ]
        },
        {
            "x": 5,
            "y": 3,
            "z": 3,
            "elements": [
                "enderio:block_dark_fused_quartz@0"
            ]
        },
        {
            "x": 6,
            "y": 4,
            "z": 10,
            "elements": [
                "appliedenergistics2:sky_stone_brick_stairs@7"
            ]
        },
        {
            "x": -5,
            "y": -1,
            "z": 8,
            "elements": [
                "enderio:block_dark_fused_quartz@0"
            ]
        },
        {
            "x": 4,
            "y": -1,
            "z": 7,
            "elements": [
                "enderio:block_dark_fused_quartz@0"
            ]
        },
        {
            "x": 4,
            "y": -1,
            "z": 3,
            "elements": [
                "astralsorcery:fluidblockliquidstarlight@0"
            ]
        },
        {
            "x": -1,
            "y": -2,
            "z": 2,
            "elements": [
                "appliedenergistics2:sky_stone_small_brick_slab@0"
            ]
        },
        {
            "x": 5,
            "y": 0,
            "z": 7,
            "elements": [
                "astralsorcery:blockblackmarble@2"
            ]
        },
        {
            "x": -5,
            "y": -2,
            "z": 8,
            "elements": [
                "appliedenergistics2:smooth_sky_stone_block@0"
            ]
        },
        {
            "x": 2,
            "y": 4,
            "z": 3,
            "elements": [
                "appliedenergistics2:sky_stone_brick_stairs@4"
            ]
        },
        {
            "x": 6,
            "y": -2,
            "z": 1,
            "elements": [
                "appliedenergistics2:sky_stone_brick_stairs@2"
            ]
        },
        {
            "x": -4,
            "y": 3,
            "z": 8,
            "elements": [
                "astralsorcery:fluidblockliquidstarlight@0"
            ]
        },
        {
            "x": 4,
            "y": -2,
            "z": 7,
            "elements": [
                "appliedenergistics2:smooth_sky_stone_block@0"
            ]
        },
        {
            "x": 5,
            "y": 0,
            "z": 3,
            "elements": [
                "enderio:block_dark_fused_quartz@0"
            ]
        },
        {
            "x": -3,
            "y": 4,
            "z": 2,
            "elements": [
                "appliedenergistics2:smooth_sky_stone_block@0"
            ]
        },
        {
            "x": -2,
            "y": 4,
            "z": 1,
            "elements": [
                "appliedenergistics2:sky_stone_brick_stairs@6"
            ]
        },
        {
            "x": 5,
            "y": 1,
            "z": 7,
            "elements": [
                "astralsorcery:blockblackmarble@2"
            ]
        },
        {
            "x": -4,
            "y": 4,
            "z": 8,
            "elements": [
                "modularmachinery:blockcasing@1"
            ]
        },
        {
            "x": -5,
            "y": 3,
            "z": 8,
            "elements": [
                "enderio:block_dark_fused_quartz@0"
            ]
        },
        {
            "x": -4,
            "y": 0,
            "z": 2,
            "elements": [
                "enderio:block_dark_fused_quartz@0"
            ]
        },
        {
            "x": 3,
            "y": -2,
            "z": 1,
            "elements": [
                "appliedenergistics2:sky_stone_brick_stairs@2"
            ]
        },
        {
            "x": 6,
            "y": 4,
            "z": 5,
            "elements": [
                "appliedenergistics2:sky_stone_brick_stairs@7"
            ]
        },
        {
            "x": -2,
            "y": -2,
            "z": 2,
            "elements": [
                "appliedenergistics2:sky_stone_brick_stairs@1"
            ]
        },
        {
            "x": -4,
            "y": -2,
            "z": 8,
            "elements": [
                "appliedenergistics2:smooth_sky_stone_block@0"
            ]
        },
        {
            "x": 5,
            "y": 3,
            "z": 7,
            "elements": [
                "astralsorcery:blockblackmarble@2"
            ]
        },
        {
            "x": 5,
            "y": 2,
            "z": 7,
            "elements": [
                "astralsorcery:blockblackmarble@2"
            ]
        },
        {
            "x": -2,
            "y": 4,
            "z": 2,
            "elements": [
                "appliedenergistics2:sky_stone_brick_stairs@5"
            ]
        },
        {
            "x": -3,
            "y": 0,
            "z": 8,
            "elements": [
                "enderio:block_dark_fused_quartz@0"
            ]
        },
        {
            "x": -4,
            "y": 1,
            "z": 2,
            "elements": [
                "enderio:block_dark_fused_quartz@0"
            ]
        },
        {
            "x": 2,
            "y": 4,
            "z": 6,
            "elements": [
                "appliedenergistics2:sky_stone_brick_stairs@6"
            ]
        },
        {
            "x": -5,
            "y": 4,
            "z": 8,
            "elements": [
                "appliedenergistics2:smooth_sky_stone_block@0"
            ]
        },
        {
            "x": -3,
            "y": -1,
            "z": 8,
            "elements": [
                "enderio:block_dark_fused_quartz@0"
            ]
        },
        {
            "x": -5,
            "y": -2,
            "z": 4,
            "elements": [
                "appliedenergistics2:smooth_sky_stone_block@0"
            ]
        },
        {
            "x": 1,
            "y": -2,
            "z": 2,
            "elements": [
                "appliedenergistics2:sky_stone_small_brick_slab@0"
            ]
        },
        {
            "x": 5,
            "y": 4,
            "z": 7,
            "elements": [
                "appliedenergistics2:smooth_sky_stone_block@0"
            ]
        },
        {
            "x": -5,
            "y": 1,
            "z": 8,
            "elements": [
                "enderio:block_dark_fused_quartz@0"
            ]
        },
        {
            "x": 4,
            "y": 4,
            "z": 3,
            "elements": [
                "modularmachinery:blockcasing@1"
            ]
        },
        {
            "x": -4,
            "y": 3,
            "z": 2,
            "elements": [
                "enderio:block_dark_fused_quartz@0"
            ]
        },
        {
            "x": 5,
            "y": 2,
            "z": 3,
            "elements": [
                "enderio:block_dark_fused_quartz@0"
            ]
        },
        {
            "x": 4,
            "y": -2,
            "z": 6,
            "elements": [
                "appliedenergistics2:sky_stone_brick_stairs@2"
            ]
        },
        {
            "x": -3,
            "y": -2,
            "z": 8,
            "elements": [
                "appliedenergistics2:smooth_sky_stone_block@0"
            ]
        },
        {
            "x": -4,
            "y": 0,
            "z": 8,
            "elements": [
                "astralsorcery:fluidblockliquidstarlight@0"
            ]
        },
        {
            "x": 5,
            "y": -2,
            "z": 10,
            "elements": [
                "appliedenergistics2:sky_stone_brick_stairs@3"
            ]
        },
        {
            "x": -5,
            "y": 2,
            "z": 8,
            "elements": [
                "enderio:block_dark_fused_quartz@0"
            ]
        },
        {
            "x": 3,
            "y": 4,
            "z": 10,
            "elements": [
                "appliedenergistics2:sky_stone_brick_stairs@7"
            ]
        },
        {
            "x": -4,
            "y": 2,
            "z": 2,
            "elements": [
                "enderio:block_dark_fused_quartz@0"
            ]
        },
        {
            "x": 4,
            "y": 3,
            "z": 3,
            "elements": [
                "astralsorcery:fluidblockliquidstarlight@0"
            ]
        },
        {
            "x": -5,
            "y": 4,
            "z": 2,
            "elements": [
                "appliedenergistics2:smooth_sky_stone_block@0"
            ]
        },
        {
            "x": 5,
            "y": 1,
            "z": 3,
            "elements": [
                "enderio:block_dark_fused_quartz@0"
            ]
        },
        {
            "x": -4,
            "y": -1,
            "z": 8,
            "elements": [
                "astralsorcery:fluidblockliquidstarlight@0"
            ]
        },
        {
            "x": -6,
            "y": 4,
            "z": 8,
            "elements": [
                "appliedenergistics2:sky_stone_brick_stairs@4"
            ]
        },
        {
            "x": -3,
            "y": 4,
            "z": 6,
            "elements": [
                "appliedenergistics2:sky_stone_brick_stairs@6"
            ]
        },
        {
            "x": 4,
            "y": 4,
            "z": 5,
            "elements": [
                "appliedenergistics2:sky_stone_brick_stairs@7"
            ]
        },
        {
            "x": -3,
            "y": -2,
            "z": 1,
            "elements": [
                "appliedenergistics2:sky_stone_brick_stairs@2"
            ]
        },
        {
            "x": -5,
            "y": 3,
            "z": 2,
            "elements": [
                "astralsorcery:blockblackmarble@2"
            ]
        },
        {
            "x": -2,
            "y": 4,
            "z": 7,
            "elements": [
                "appliedenergistics2:sky_stone_brick_stairs@5"
            ]
        },
        {
            "x": 4,
            "y": -2,
            "z": 10,
            "elements": [
                "appliedenergistics2:sky_stone_brick_stairs@3"
            ]
        },
        {
            "x": -1,
            "y": -2,
            "z": 6,
            "elements": [
                "appliedenergistics2:sky_stone_small_brick_slab@0"
            ]
        },
        {
            "x": 2,
            "y": 4,
            "z": 10,
            "elements": [
                "appliedenergistics2:sky_stone_brick_stairs@7"
            ]
        },
        {
            "x": -5,
            "y": 2,
            "z": 2,
            "elements": [
                "astralsorcery:blockblackmarble@2"
            ]
        },
        {
            "x": 2,
            "y": -2,
            "z": 1,
            "elements": [
                "appliedenergistics2:sky_stone_brick_stairs@0"
            ]
        },
        {
            "x": -5,
            "y": 0,
            "z": 2,
            "elements": [
                "astralsorcery:blockblackmarble@2"
            ]
        },
        {
            "x": 0,
            "y": -1,
            "z": 7,
            "elements": [
                "appliedenergistics2:cable_bus@0"
            ]
        },
        {
            "x": -6,
            "y": 4,
            "z": 6,
            "elements": [
                "appliedenergistics2:sky_stone_brick_stairs@6"
            ]
        },
        {
            "x": 3,
            "y": -2,
            "z": 2,
            "elements": [
                "appliedenergistics2:smooth_sky_stone_block@0"
            ]
        },
        {
            "x": -6,
            "y": 4,
            "z": 1,
            "elements": [
                "appliedenergistics2:sky_stone_brick_stairs@4"
            ]
        },
        {
            "x": 2,
            "y": -2,
            "z": 6,
            "elements": [
                "appliedenergistics2:sky_stone_brick_stairs@0"
            ]
        },
        {
            "x": 3,
            "y": -1,
            "z": 2,
            "elements": [
                "astralsorcery:blockblackmarble@2"
            ]
        },
        {
            "x": -5,
            "y": 1,
            "z": 2,
            "elements": [
                "astralsorcery:blockblackmarble@2"
            ]
        },
        {
            "x": 0,
            "y": -2,
            "z": 7,
            "elements": [
                "appliedenergistics2:sky_stone_small_brick_slab@0"
            ]
        },
        {
            "x": 3,
            "y": -1,
            "z": 7,
            "elements": [
                "astralsorcery:blockblackmarble@2"
            ]
        },
        {
            "x": -1,
            "y": -2,
            "z": 1,
            "elements": [
                "appliedenergistics2:sky_stone_small_brick_slab@0"
            ]
        },
        {
            "x": -6,
            "y": -2,
            "z": 2,
            "elements": [
                "appliedenergistics2:sky_stone_brick_stairs@0"
            ]
        },
        {
            "x": 3,
            "y": -2,
            "z": 7,
            "elements": [
                "appliedenergistics2:smooth_sky_stone_block@0"
            ]
        },
        {
            "x": -3,
            "y": 4,
            "z": 1,
            "elements": [
                "appliedenergistics2:sky_stone_brick_stairs@6"
            ]
        },
        {
            "x": 0,
            "y": -2,
            "z": 1,
            "elements": [
                "appliedenergistics2:sky_stone_small_brick_slab@0"
            ]
        },
        {
            "x": -3,
            "y": -2,
            "z": 2,
            "elements": [
                "appliedenergistics2:smooth_sky_stone_block@0"
            ]
        },
        {
            "x": -4,
            "y": 4,
            "z": 1,
            "elements": [
                "appliedenergistics2:sky_stone_brick_stairs@6"
            ]
        },
        {
            "x": 0,
            "y": -1,
            "z": 1,
            "elements": [
                "appliedenergistics2:cable_bus@0"
            ]
        },
        {
            "x": -3,
            "y": -1,
            "z": 2,
            "elements": [
                "astralsorcery:blockblackmarble@2"
            ]
        },
        {
            "x": 1,
            "y": -2,
            "z": 10,
            "elements": [
                "appliedenergistics2:sky_stone_small_brick_slab@0"
            ]
        },
        {
            "x": 4,
            "y": 0,
            "z": 7,
            "elements": [
                "enderio:block_dark_fused_quartz@0"
            ]
        },
        {
            "x": -3,
            "y": 1,
            "z": 7,
            "elements": [
                "astralsorcery:blockblackmarble@2"
            ]
        },
        {
            "x": 1,
            "y": -2,
            "z": 1,
            "elements": [
                "appliedenergistics2:sky_stone_small_brick_slab@0"
            ]
        },
        {
            "x": 5,
            "y": 3,
            "z": 4,
            "elements": [
                "astralsorcery:blockblackmarble@2"
            ]
        },
        {
            "x": -6,
            "y": 4,
            "z": 7,
            "elements": [
                "appliedenergistics2:sky_stone_brick_stairs@4"
            ]
        },
        {
            "x": 5,
            "y": 4,
            "z": 4,
            "elements": [
                "appliedenergistics2:smooth_sky_stone_block@0"
            ]
        },
        {
            "x": 4,
            "y": 1,
            "z": 8,
            "elements": [
                "astralsorcery:fluidblockliquidstarlight@0"
            ]
        },
        {
            "x": -3,
            "y": -1,
            "z": 7,
            "elements": [
                "astralsorcery:blockblackmarble@2"
            ]
        },
        {
            "x": 1,
            "y": -2,
            "z": 8,
            "elements": [
                "appliedenergistics2:sky_stone_small_brick_slab@0"
            ]
        },
        {
            "x": -3,
            "y": 0,
            "z": 7,
            "elements": [
                "astralsorcery:blockblackmarble@2"
            ]
        },
        {
            "x": -5,
            "y": -2,
            "z": 6,
            "elements": [
                "appliedenergistics2:sky_stone_brick_stairs@2"
            ]
        },
        {
            "x": 3,
            "y": 4,
            "z": 1,
            "elements": [
                "appliedenergistics2:sky_stone_brick_stairs@6"
            ]
        },
        {
            "x": -4,
            "y": 2,
            "z": 7,
            "elements": [
                "enderio:block_dark_fused_quartz@0"
            ]
        },
        {
            "x": 4,
            "y": 2,
            "z": 8,
            "elements": [
                "astralsorcery:fluidblockliquidstarlight@0"
            ]
        },
        {
            "x": -3,
            "y": -2,
            "z": 7,
            "elements": [
                "appliedenergistics2:smooth_sky_stone_block@0"
            ]
        },
        {
            "x": 0,
            "y": -2,
            "z": 5,
            "elements": [
                "appliedenergistics2:sky_stone_small_brick_slab@0"
            ]
        },
        {
            "x": 4,
            "y": 4,
            "z": 8,
            "elements": [
                "modularmachinery:blockcasing@1"
            ]
        },
        {
            "x": 1,
            "y": -1,
            "z": 8,
            "elements": [
                "appliedenergistics2:cable_bus@0"
            ]
        },
        {
            "x": -2,
            "y": 4,
            "z": 6,
            "elements": [
                "appliedenergistics2:sky_stone_brick_stairs@5"
            ]
        },
        {
            "x": -2,
            "y": -2,
            "z": 1,
            "elements": [
                "appliedenergistics2:sky_stone_brick_stairs@1"
            ]
        },
        {
            "x": -5,
            "y": 3,
            "z": 7,
            "elements": [
                "astralsorcery:blockblackmarble@2"
            ]
        },
        {
            "x": 4,
            "y": 4,
            "z": 2,
            "elements": [
                "appliedenergistics2:smooth_sky_stone_block@0"
            ]
        },
        {
            "x": -5,
            "y": 4,
            "z": 7,
            "elements": [
                "appliedenergistics2:smooth_sky_stone_block@0"
            ]
        },
        {
            "x": -4,
            "y": -1,
            "z": 7,
            "elements": [
                "enderio:block_dark_fused_quartz@0"
            ]
        },
        {
            "x": 6,
            "y": -2,
            "z": 8,
            "elements": [
                "appliedenergistics2:sky_stone_brick_stairs@1"
            ]
        },
        {
            "x": -2,
            "y": -2,
            "z": 6,
            "elements": [
                "appliedenergistics2:sky_stone_brick_stairs@2"
            ]
        },
        {
            "x": -5,
            "y": 2,
            "z": 7,
            "elements": [
                "astralsorcery:blockblackmarble@2"
            ]
        },
        {
            "x": 6,
            "y": 4,
            "z": 9,
            "elements": [
                "appliedenergistics2:sky_stone_brick_stairs@5"
            ]
        },
        {
            "x": 4,
            "y": 3,
            "z": 8,
            "elements": [
                "astralsorcery:fluidblockliquidstarlight@0"
            ]
        },
        {
            "x": -4,
            "y": -2,
            "z": 7,
            "elements": [
                "appliedenergistics2:smooth_sky_stone_block@0"
            ]
        },
        {
            "x": -5,
            "y": -2,
            "z": 1,
            "elements": [
                "appliedenergistics2:sky_stone_brick_stairs@2"
            ]
        },
        {
            "x": 0,
            "y": -1,
            "z": 5,
            "elements": [
                "appliedenergistics2:cable_bus@0"
            ]
        },
        {
            "x": 5,
            "y": 4,
            "z": 10,
            "elements": [
                "appliedenergistics2:sky_stone_brick_stairs@7"
            ]
        },
        {
            "x": -5,
            "y": 1,
            "z": 7,
            "elements": [
                "astralsorcery:blockblackmarble@2"
            ]
        },
        {
            "x": 2,
            "y": -2,
            "z": 0,
            "elements": [
                "modularmachinery:blockcasing@5"
            ]
        },
        {
            "x": -5,
            "y": 4,
            "z": 6,
            "elements": [
                "appliedenergistics2:sky_stone_brick_stairs@6"
            ]
        },
        {
            "x": 4,
            "y": -1,
            "z": 8,
            "elements": [
                "astralsorcery:fluidblockliquidstarlight@0"
            ]
        },
        {
            "x": -2,
            "y": 4,
            "z": 5,
            "elements": [
                "appliedenergistics2:sky_stone_brick_stairs@7"
            ]
        },
        {
            "x": 4,
            "y": 1,
            "z": 2,
            "elements": [
                "enderio:block_dark_fused_quartz@0"
            ]
        },
        {
            "x": 3,
            "y": -2,
            "z": 5,
            "elements": [
                "appliedenergistics2:sky_stone_brick_stairs@3"
            ]
        },
        {
            "x": 3,
            "y": -2,
            "z": 8,
            "elements": [
                "appliedenergistics2:smooth_sky_stone_block@0"
            ]
        },
        {
            "x": -3,
            "y": -2,
            "z": 6,
            "elements": [
                "appliedenergistics2:sky_stone_brick_stairs@2"
            ]
        },
        {
            "x": -3,
            "y": 3,
            "z": 7,
            "elements": [
                "astralsorcery:blockblackmarble@2"
            ]
        },
        {
            "x": 4,
            "y": 0,
            "z": 2,
            "elements": [
                "enderio:block_dark_fused_quartz@0"
            ]
        },
        {
            "x": 5,
            "y": 0,
            "z": 8,
            "elements": [
                "enderio:block_dark_fused_quartz@0"
            ]
        },
        {
            "x": -5,
            "y": 0,
            "z": 7,
            "elements": [
                "astralsorcery:blockblackmarble@2"
            ]
        },
        {
            "x": 6,
            "y": -2,
            "z": 2,
            "elements": [
                "appliedenergistics2:sky_stone_brick_stairs@1"
            ]
        },
        {
            "x": 4,
            "y": -2,
            "z": 1,
            "elements": [
                "appliedenergistics2:sky_stone_brick_stairs@2"
            ]
        },
        {
            "x": -1,
            "y": -2,
            "z": 7,
            "elements": [
                "appliedenergistics2:sky_stone_small_brick_slab@0"
            ]
        },
        {
            "x": 4,
            "y": 3,
            "z": 2,
            "elements": [
                "enderio:block_dark_fused_quartz@0"
            ]
        },
        {
            "x": -4,
            "y": 4,
            "z": 6,
            "elements": [
                "appliedenergistics2:sky_stone_brick_stairs@6"
            ]
        },
        {
            "x": 0,
            "y": 2,
            "z": 0,
            "elements": [
                "modularmachinery:blockenergyinputhatch"
            ]
        },
        {
            "x": -1,
            "y": -2,
            "z": 0,
            "elements": [
                "appliedenergistics2:controller@0"
            ]
        },
        {
            "x": 3,
            "y": -1,
            "z": 8,
            "elements": [
                "enderio:block_dark_fused_quartz@0"
            ]
        },
        {
            "x": 6,
            "y": 4,
            "z": 2,
            "elements": [
                "appliedenergistics2:sky_stone_brick_stairs@5"
            ]
        },
        {
            "x": 2,
            "y": 4,
            "z": 8,
            "elements": [
                "appliedenergistics2:sky_stone_brick_stairs@4"
            ]
        },
        {
            "x": 6,
            "y": -2,
            "z": 5,
            "elements": [
                "appliedenergistics2:sky_stone_brick_stairs@1"
            ]
        },
        {
            "x": -3,
            "y": 4,
            "z": 7,
            "elements": [
                "appliedenergistics2:smooth_sky_stone_block@0"
            ]
        },
        {
            "x": 2,
            "y": -1,
            "z": 0,
            "elements": [
                "appliedenergistics2:controller@0"
            ]
        },
        {
            "x": 0,
            "y": 1,
            "z": 0,
            "elements": [
                "appliedenergistics2:cable_bus@0"
            ]
        },
        {
            "x": -4,
            "y": -2,
            "z": 6,
            "elements": [
                "appliedenergistics2:sky_stone_brick_stairs@2"
            ]
        },
        {
            "x": -1,
            "y": -1,
            "z": 0,
            "elements": [
                "appliedenergistics2:controller@0"
            ]
        },
        {
            "x": 4,
            "y": -2,
            "z": 8,
            "elements": [
                "appliedenergistics2:smooth_sky_stone_block@0"
            ]
        },
        {
            "x": 3,
            "y": 4,
            "z": 2,
            "elements": [
                "appliedenergistics2:smooth_sky_stone_block@0"
            ]
        },
        {
            "x": 4,
            "y": 2,
            "z": 2,
            "elements": [
                "enderio:block_dark_fused_quartz@0"
            ]
        },
        {
            "x": -3,
            "y": 2,
            "z": 7,
            "elements": [
                "astralsorcery:blockblackmarble@2"
            ]
        },
        {
            "x": 4,
            "y": 0,
            "z": 8,
            "elements": [
                "astralsorcery:fluidblockliquidstarlight@0"
            ]
        },
        {
            "x": -6,
            "y": -2,
            "z": 7,
            "elements": [
                "appliedenergistics2:sky_stone_brick_stairs@0"
            ]
        }
    ]}