{
    "registryname": "moni",
    "localizedname": "#50eaff-ff66ff-ff6633亚空间生物收容装置",
    "failure-action": "still",
    "requires-blueprint": false,
    "color": "000000",
    "parts": [
        {
            "x": 9,
            "y": 4,
            "z": 3,
            "elements": [
                "rpsideas:dark_plate@3"
            ]
        },
        {
            "x": 6,
            "y": 6,
            "z": 4,
            "elements": [
                "immersiveintelligence:metal_decoration@6"
            ]
        },
        {
            "x": -1,
            "y": 2,
            "z": 0,
            "elements": [
                "psicosts:material_glassy@0"
            ]
        },
        {
            "x": -3,
            "y": 0,
            "z": 5,
            "elements": [
                "fluxnetworks:fluxblock@0"
            ]
        },
        {
            "x": 5,
            "y": 1,
            "z": 1,

            "elements": [
                "environmentaltech:structure_frame_5@0"
            ]
        },
        {
            "x": -2,
            "y": 4,
            "z": 0,
            "elements": [
                "rpsideas:dark_plate@3"
            ]
        },
        {
            "x": 5,
            "y": 0,
            "z": 1,
            "elements": [
                "fluxnetworks:fluxblock@0"
            ]
        },
        {
            "x": 8,
            "y": 3,
            "z": 1,
            "elements": [
                "astralsorcery:fluidblockliquidstarlight@1"
            ]
        },
        {
            "x": 3,
            "y": 7,
            "z": 3,
            "elements": [
                "appliedenergistics2:quartz_vibrant_glass@0"
            ]
        },
        {
            "x": 3,
            "y": 8,
            "z": 4,
            "elements": [
                "appliedenergistics2:quartz_vibrant_glass@0"
            ]
        },
        {
            "x": -3,
            "y": 2,
            "z": 5,
            "elements": [
                "psicosts:material_glassy@0"
            ]
        },
        {
            "x": -1,
            "y": 1,
            "z": 0,
            "elements": [
                "rpsideas:dark_plate@3"
            ]
        },
        {
            "x": 6,
            "y": 5,
            "z": 3,
            "elements": [
                "astralsorcery:fluidblockliquidstarlight@0"
            ]
        },
        {
            "x": 8,
            "y": 2,
            "z": 1,
            "elements": [
                "astralsorcery:fluidblockliquidstarlight@1"
            ]
        },
        {
            "x": 5,
            "y": 7,
            "z": 1,
            "elements": [
                "immersiveintelligence:metal_decoration@6"
            ]
        },
        {
            "x": -2,
            "y": 3,
            "z": 0,
            "elements": [
                "psicosts:material_glassy@0"
            ]
        },
        {
            "x": 9,
            "y": 3,
            "z": 3,
            "elements": [
                "psicosts:material_glassy@0"
            ]
        },
        {
            "x": -3,
            "y": 1,
            "z": 5,
            "elements": [
                "rpsideas:dark_plate@3"
            ]
        },
        {
            "x": 6,
            "y": 5,
            "z": 4,
            "elements": [
                "libvulpes:structuremachine@0"
            ]
        },
        {
            "x": -3,
            "y": 5,
            "z": 0,
            "elements": [
                "fluxnetworks:fluxblock@0"
            ]
        },
        {
            "x": 7,
            "y": 5,
            "z": 2,
            "elements": [
                "libvulpes:structuremachine@0"
            ]
        },
        {
            "x": 3,
            "y": 8,
            "z": 3,
            "elements": [
                "appliedenergistics2:quartz_vibrant_glass@0"
            ]
        },
        {
            "x": 3,
            "y": 7,
            "z": 4,
            "elements": [
                "appliedenergistics2:quartz_vibrant_glass@0"
            ]
        },
        {
            "x": 6,
            "y": 6,
            "z": 3,
            "elements": [
                "immersiveintelligence:metal_decoration@6"
            ]
        },
        {
            "x": 1,
            "y": 0,
            "z": 0,

            "elements": [
                "modularmachinery:blockinputbus",
                "modularmachinery:blockmeiteminputbus",
                "modularmachinery:blockmepatternprovider"
            ]
        },
        {
            "x": 7,
            "y": 6,
            "z": 2,
            "elements": [
                "immersiveintelligence:metal_decoration@6"
            ]
        },
        {
            "x": -2,
            "y": 2,
            "z": 0,
            "elements": [
                "psicosts:material_glassy@0"
            ]
        },
        {
            "x": 8,
            "y": 1,
            "z": 1,
            "elements": [
                "astralsorcery:fluidblockliquidstarlight@1"
            ]
        },
        {
            "x": 6,
            "y": 4,
            "z": 3,
            "elements": [
                "astralsorcery:fluidblockliquidstarlight@1"
            ]
        },
        {
            "x": 3,
            "y": 9,
            "z": 3,
            "elements": [
                "fluxnetworks:fluxblock@0"
            ]
        },
        {
            "x": -2,
            "y": 0,
            "z": 5,
            "elements": [
                "fluxnetworks:fluxblock@0"
            ]
        },
        {
            "x": -1,
            "y": 4,
            "z": 0,
            "elements": [
                "rpsideas:dark_plate@3"
            ]
        },
        {
            "x": 2,
            "y": 5,
            "z": 1,
            "elements": [
                "appliedenergistics2:quartz_vibrant_glass@0"
            ]
        },
        {
            "x": 7,
            "y": 7,
            "z": 2,
            "elements": [
                "immersiveintelligence:metal_decoration@6"
            ]
        },
        {
            "x": 9,
            "y": 5,
            "z": 3,
            "elements": [
                "fluxnetworks:fluxblock@0"
            ]
        },
        {
            "x": -2,
            "y": 1,
            "z": 0,
            "elements": [
                "rpsideas:dark_plate@3"
            ]
        },
        {
            "x": 2,
            "y": 4,
            "z": 1,

            "elements": [
                "projectred-illumination:lamp@0"
            ]
        },
        {
            "x": 8,
            "y": 0,
            "z": 1,
            "elements": [
                "fluxnetworks:fluxblock@0"
            ]
        },
        {
            "x": -1,
            "y": 3,
            "z": 0,
            "elements": [
                "psicosts:material_glassy@0"
            ]
        },
        {
            "x": -2,
            "y": 1,
            "z": 5,
            "elements": [
                "sonarcore:reinforcedstonebrickfence@0"
            ]
        },
        {
            "x": 6,
            "y": 3,
            "z": 3,
            "elements": [
                "astralsorcery:fluidblockliquidstarlight@1"
            ]
        },
        {
            "x": 3,
            "y": 9,
            "z": 4,
            "elements": [
                "fluxnetworks:fluxblock@0"
            ]
        },
        {
            "x": 9,
            "y": 6,
            "z": 3,
            "elements": [
                "appliedenergistics2:quartz_vibrant_glass@0"
            ]
        },
        {
            "x": 9,
            "y": 3,
            "z": 2,
            "elements": [
                "psicosts:material_glassy@0"
            ]
        },
        {
            "x": 6,
            "y": 1,
            "z": 4,

            "elements": [
                "environmentaltech:structure_frame_5@0"
            ]
        },
        {
            "x": 2,
            "y": 0,
            "z": 0,
            "elements": [
                "fluxnetworks:fluxblock@0"
            ]
        },
        {
            "x": 6,
            "y": 3,
            "z": 1,
            "elements": [
                "astralsorcery:fluidblockliquidstarlight@1"
            ]
        },
        {
            "x": 3,
            "y": 1,
            "z": 3,

            "elements": [
                "environmentaltech:structure_frame_5@0"
            ]
        },
        {
            "x": 7,
            "y": 8,
            "z": 2,
            "elements": [
                "immersiveintelligence:metal_decoration@6"
            ]
        },
        {
            "x": 1,
            "y": 2,
            "z": 0,
            "elements": [
                "psicosts:material_glassy@0"
            ]
        },
        {
            "x": 3,
            "y": 3,
            "z": 4,

            "elements": [
                "environmentaltech:structure_frame_5@0"
            ]
        },
        {
            "x": 6,
            "y": 9,
            "z": 3,
            "elements": [
                "fluxnetworks:fluxblock@0"
            ]
        },
        {
            "x": 7,
            "y": 9,
            "z": 2,
            "elements": [
                "fluxnetworks:fluxblock@0"
            ]
        },
        {
            "x": 3,
            "y": 4,
            "z": 4,

            "elements": [
                "environmentaltech:structure_frame_5@0"
            ]
        },
        {
            "x": 1,
            "y": 0,
            "z": 6,
            "elements": [
                "fluxnetworks:fluxblock@0"
            ]
        },
        {
            "x": 9,
            "y": 0,
            "z": 3,
            "elements": [
                "fluxnetworks:fluxblock@0"
            ]
        },
        {
            "x": 5,
            "y": 5,
            "z": 1,
            "elements": [
                "libvulpes:structuremachine@0"
            ]
        },
        {
            "x": 6,
            "y": 2,
            "z": 1,
            "elements": [
                "astralsorcery:fluidblockliquidstarlight@1"
            ]
        },
        {
            "x": 1,
            "y": 1,
            "z": 0,
            "elements": [
                "rpsideas:dark_plate@3"
            ]
        },
        {
            "x": 6,
            "y": 10,
            "z": 3,

            "elements": [
                "environmentaltech:lightning_rod_insulated@0"
            ]
        },
        {
            "x": 0,
            "y": 5,
            "z": 3,
            "elements": [
                "appliedenergistics2:quartz_vibrant_glass@0"
            ]
        },
        {
            "x": -3,
            "y": 5,
            "z": 5,
            "elements": [
                "fluxnetworks:fluxblock@0"
            ]
        },
        {
            "x": -1,
            "y": 0,
            "z": 0,

            "elements": [
                "modularmachinery:blockoutputbus",
                "modularmachinery:blockmeitemoutputbus",
                "modularmachinery:blockmepatternprovider"
            ]
        },
        {
            "x": 6,
            "y": 11,
            "z": 3,

            "elements": [
                "environmentaltech:lightning_rod@0"
            ]
        },
        {
            "x": 1,
            "y": 1,
            "z": 6,
            "elements": [
                "rpsideas:dark_plate@3"
            ]
        },
        {
            "x": 4,
            "y": 8,
            "z": 2,
            "elements": [
                "immersiveintelligence:metal_decoration@6"
            ]
        },
        {
            "x": 9,
            "y": 2,
            "z": 3,
            "elements": [
                "psicosts:material_glassy@0"
            ]
        },
        {
            "x": 6,
            "y": 1,
            "z": 1,
            "elements": [
                "astralsorcery:fluidblockliquidstarlight@1"
            ]
        },
        {
            "x": 6,
            "y": 0,
            "z": 1,
            "elements": [
                "fluxnetworks:fluxblock@0"
            ]
        },
        {
            "x": 0,
            "y": 0,
            "z": 5,
            "elements": [
                "fluxnetworks:fluxblock@0"
            ]
        },
        {
            "x": 0,
            "y": 4,
            "z": 3,

            "elements": [
                "projectred-illumination:lamp@0"
            ]
        },
        {
            "x": 1,
            "y": 4,
            "z": 0,
            "elements": [
                "rpsideas:dark_plate@3"
            ]
        },
        {
            "x": 3,
            "y": 6,
            "z": 4,
            "elements": [
                "appliedenergistics2:quartz_vibrant_glass@0"
            ]
        },
        {
            "x": 6,
            "y": 7,
            "z": 3,
            "elements": [
                "immersiveintelligence:metal_decoration@6"
            ]
        },
        {
            "x": -3,
            "y": 4,
            "z": 5,
            "elements": [
                "rpsideas:dark_plate@3"
            ]
        },
        {
            "x": 3,
            "y": 0,
            "z": 3,
            "elements": [
                "fluxnetworks:fluxblock@0"
            ]
        },
        {
            "x": 4,
            "y": 9,
            "z": 2,
            "elements": [
                "fluxnetworks:fluxblock@0"
            ]
        },
        {
            "x": 6,
            "y": 8,
            "z": 3,
            "elements": [
                "immersiveintelligence:metal_decoration@6"
            ]
        },
        {
            "x": 1,
            "y": 3,
            "z": 0,
            "elements": [
                "psicosts:material_glassy@0"
            ]
        },
        {
            "x": 9,
            "y": 1,
            "z": 3,
            "elements": [
                "rpsideas:dark_plate@3"
            ]
        },
        {
            "x": 3,
            "y": 5,
            "z": 4,
            "elements": [
                "fluxnetworks:fluxblock@0"
            ]
        },
        {
            "x": 5,
            "y": 6,
            "z": 1,
            "elements": [
                "immersiveintelligence:metal_decoration@6"
            ]
        },
        {
            "x": -2,
            "y": 5,
            "z": 0,
            "elements": [
                "fluxnetworks:fluxblock@0"
            ]
        },
        {
            "x": 7,
            "y": 10,
            "z": 2,

            "elements": [
                "environmentaltech:lightning_rod_insulated@0"
            ]
        },
        {
            "x": -3,
            "y": 3,
            "z": 5,
            "elements": [
                "psicosts:material_glassy@0"
            ]
        },
        {
            "x": 6,
            "y": 0,
            "z": 4,
            "elements": [
                "fluxnetworks:fluxblock@0"
            ]
        },
        {
            "x": 0,
            "y": 1,
            "z": 5,
            "elements": [
                "sonarcore:reinforcedstonebrickfence@0"
            ]
        },
        {
            "x": 7,
            "y": 0,
            "z": 6,
            "elements": [
                "fluxnetworks:fluxblock@0"
            ]
        },
        {
            "x": 3,
            "y": 7,
            "z": 6,
            "elements": [
                "fluxnetworks:fluxblock@0"
            ]
        },
        {
            "x": 4,
            "y": 0,
            "z": 0,
            "elements": [
                "fluxnetworks:fluxblock@0"
            ]
        },
        {
            "x": 8,
            "y": 8,
            "z": 1,
            "elements": [
                "immersiveintelligence:metal_decoration@6"
            ]
        },
        {
            "x": 1,
            "y": 4,
            "z": 6,
            "elements": [
                "rpsideas:dark_plate@3"
            ]
        },
        {
            "x": 6,
            "y": 2,
            "z": 6,
            "elements": [
                "psicosts:material_glassy@0"
            ]
        },
        {
            "x": 9,
            "y": 9,
            "z": 2,
            "elements": [
                "fluxnetworks:fluxblock@0"
            ]
        },
        {
            "x": 0,
            "y": 4,
            "z": 5,

            "elements": [
                "projectred-illumination:lamp@0"
            ]
        },
        {
            "x": -3,
            "y": 3,
            "z": 4,
            "elements": [
                "psicosts:material_glassy@0"
            ]
        },
        {
            "x": 2,
            "y": 4,
            "z": 0,
            "elements": [
                "rpsideas:dark_plate@3"
            ]
        },
        {
            "x": 4,
            "y": 5,
            "z": 6,
            "elements": [
                "fluxnetworks:fluxblock@0"
            ]
        },
        {
            "x": 0,
            "y": 1,
            "z": 4,
            "elements": [
                "minecraft:carpet@3"
            ]
        },
        {
            "x": -3,
            "y": 4,
            "z": 4,
            "elements": [
                "rpsideas:dark_plate@3"
            ]
        },
        {
            "x": 7,
            "y": 1,
            "z": 6,
            "elements": [
                "rpsideas:dark_plate@3"
            ]
        },
        {
            "x": -1,
            "y": 5,
            "z": 5,
            "elements": [
                "appliedenergistics2:quartz_vibrant_glass@0"
            ]
        },
        {
            "x": 4,
            "y": 4,
            "z": 6,
            "elements": [
                "rpsideas:dark_plate@3"
            ]
        },
        {
            "x": 2,
            "y": 3,
            "z": 0,
            "elements": [
                "psicosts:material_glassy@0"
            ]
        },
        {
            "x": 8,
            "y": 9,
            "z": 1,
            "elements": [
                "fluxnetworks:fluxblock@0"
            ]
        },
        {
            "x": 9,
            "y": 8,
            "z": 2,
            "elements": [
                "appliedenergistics2:quartz_vibrant_glass@0"
            ]
        },
        {
            "x": 3,
            "y": 6,
            "z": 6,
            "elements": [
                "fluxnetworks:fluxblock@0"
            ]
        },
        {
            "x": 3,
            "y": 0,
            "z": 4,
            "elements": [
                "fluxnetworks:fluxblock@0"
            ]
        },
        {
            "x": 1,
            "y": 2,
            "z": 6,
            "elements": [
                "psicosts:material_glassy@0"
            ]
        },
        {
            "x": 5,
            "y": 0,
            "z": 0,
            "elements": [
                "fluxnetworks:fluxblock@0"
            ]
        },
        {
            "x": 3,
            "y": 9,
            "z": 6,
            "elements": [
                "fluxnetworks:fluxblock@0"
            ]
        },
        {
            "x": 2,
            "y": 2,
            "z": 0,
            "elements": [
                "psicosts:material_glassy@0"
            ]
        },
        {
            "x": -3,
            "y": 0,
            "z": 4,
            "elements": [
                "fluxnetworks:fluxblock@0"
            ]
        },
        {
            "x": -3,
            "y": 5,
            "z": 4,
            "elements": [
                "fluxnetworks:fluxblock@0"
            ]
        },
        {
            "x": 1,
            "y": 5,
            "z": 6,
            "elements": [
                "fluxnetworks:fluxblock@0"
            ]
        },
        {
            "x": -1,
            "y": 4,
            "z": 5,

            "elements": [
                "projectred-illumination:lamp@0"
            ]
        },
        {
            "x": 3,
            "y": 1,
            "z": 4,

            "elements": [
                "environmentaltech:structure_frame_5@0"
            ]
        },
        {
            "x": 2,
            "y": 0,
            "z": 5,
            "elements": [
                "fluxnetworks:fluxblock@0"
            ]
        },
        {
            "x": 4,
            "y": 0,
            "z": 6,
            "elements": [
                "fluxnetworks:fluxblock@0"
            ]
        },
        {
            "x": 3,
            "y": 2,
            "z": 3,

            "elements": [
                "environmentaltech:structure_frame_5@0"
            ]
        },
        {
            "x": 4,
            "y": 1,
            "z": 6,
            "elements": [
                "rpsideas:dark_plate@3"
            ]
        },
        {
            "x": 3,
            "y": 2,
            "z": 4,

            "elements": [
                "environmentaltech:structure_frame_5@0"
            ]
        },
        {
            "x": 2,
            "y": 1,
            "z": 0,
            "elements": [
                "rpsideas:dark_plate@3"
            ]
        },
        {
            "x": 0,
            "y": 5,
            "z": 5,
            "elements": [
                "appliedenergistics2:quartz_vibrant_glass@0"
            ]
        },
        {
            "x": 1,
            "y": 3,
            "z": 6,
            "elements": [
                "psicosts:material_glassy@0"
            ]
        },
        {
            "x": 3,
            "y": 8,
            "z": 6,
            "elements": [
                "fluxnetworks:fluxblock@0"
            ]
        },
        {
            "x": 0,
            "y": 0,
            "z": 4,
            "elements": [
                "fluxnetworks:fluxblock@0"
            ]
        },
        {
            "x": 2,
            "y": 1,
            "z": 5,
            "elements": [
                "sonarcore:reinforcedstonebrickfence@0"
            ]
        },
        {
            "x": -2,
            "y": 0,
            "z": 0,
            "elements": [
                "fluxnetworks:fluxblock@0"
            ]
        },
        {
            "x": 4,
            "y": 2,
            "z": 6,
            "elements": [
                "psicosts:material_glassy@0"
            ]
        },
        {
            "x": 6,
            "y": 2,
            "z": 3,
            "elements": [
                "astralsorcery:fluidblockliquidstarlight@1"
            ]
        },
        {
            "x": 5,
            "y": 2,
            "z": 0,
            "elements": [
                "psicosts:material_glassy@0"
            ]
        },
        {
            "x": 3,
            "y": 4,
            "z": 3,

            "elements": [
                "environmentaltech:structure_frame_5@0"
            ]
        },
        {
            "x": -1,
            "y": 0,
            "z": 5,
            "elements": [
                "fluxnetworks:fluxblock@0"
            ]
        },
        {
            "x": 9,
            "y": 4,
            "z": 2,
            "elements": [
                "rpsideas:dark_plate@3"
            ]
        },
        {
            "x": 9,
            "y": 0,
            "z": 4,
            "elements": [
                "fluxnetworks:fluxblock@0"
            ]
        },
        {
            "x": 9,
            "y": 5,
            "z": 2,
            "elements": [
                "fluxnetworks:fluxblock@0"
            ]
        },
        {
            "x": 6,
            "y": 0,
            "z": 3,
            "elements": [
                "fluxnetworks:fluxblock@0"
            ]
        },
        {
            "x": 4,
            "y": 3,
            "z": 6,
            "elements": [
                "psicosts:material_glassy@0"
            ]
        },
        {
            "x": 5,
            "y": 1,
            "z": 0,
            "elements": [
                "rpsideas:dark_plate@3"
            ]
        },
        {
            "x": 3,
            "y": 3,
            "z": 3,

            "elements": [
                "environmentaltech:structure_frame_5@0"
            ]
        },
        {
            "x": 0,
            "y": 5,
            "z": 4,
            "elements": [
                "appliedenergistics2:quartz_vibrant_glass@0"
            ]
        },
        {
            "x": -1,
            "y": 5,
            "z": 0,
            "elements": [
                "fluxnetworks:fluxblock@0"
            ]
        },
        {
            "x": -1,
            "y": 1,
            "z": 5,
            "elements": [
                "sonarcore:reinforcedstonebrickfence@0"
            ]
        },
        {
            "x": 6,
            "y": 1,
            "z": 3,
            "elements": [
                "astralsorcery:fluidblockliquidstarlight@1"
            ]
        },
        {
            "x": 6,
            "y": 0,
            "z": 6,
            "elements": [
                "fluxnetworks:fluxblock@0"
            ]
        },
        {
            "x": 9,
            "y": 6,
            "z": 2,
            "elements": [
                "appliedenergistics2:quartz_vibrant_glass@0"
            ]
        },
        {
            "x": 2,
            "y": 5,
            "z": 0,
            "elements": [
                "fluxnetworks:fluxblock@0"
            ]
        },
        {
            "x": 3,
            "y": 2,
            "z": 6,
            "elements": [
                "fluxnetworks:fluxblock@0"
            ]
        },
        {
            "x": 3,
            "y": 6,
            "z": 3,
            "elements": [
                "appliedenergistics2:quartz_vibrant_glass@0"
            ]
        },
        {
            "x": 8,
            "y": 8,
            "z": 2,
            "elements": [
                "immersiveintelligence:metal_decoration@6"
            ]
        },
        {
            "x": 8,
            "y": 6,
            "z": 1,
            "elements": [
                "immersiveintelligence:metal_decoration@6"
            ]
        },
        {
            "x": 9,
            "y": 1,
            "z": 4,
            "elements": [
                "rpsideas:dark_plate@3"
            ]
        },
        {
            "x": 5,
            "y": 8,
            "z": 1,
            "elements": [
                "immersiveintelligence:metal_decoration@6"
            ]
        },
        {
            "x": 8,
            "y": 9,
            "z": 2,
            "elements": [
                "fluxnetworks:fluxblock@0"
            ]
        },
        {
            "x": 8,
            "y": 5,
            "z": 1,
            "elements": [
                "astralsorcery:fluidblockliquidstarlight@0"
            ]
        },
        {
            "x": 9,
            "y": 2,
            "z": 4,
            "elements": [
                "psicosts:material_glassy@0"
            ]
        },
        {
            "x": 3,
            "y": 5,
            "z": 6,
            "elements": [
                "fluxnetworks:fluxblock@0"
            ]
        },
        {
            "x": 8,
            "y": 7,
            "z": 1,
            "elements": [
                "immersiveintelligence:metal_decoration@6"
            ]
        },
        {
            "x": 5,
            "y": 4,
            "z": 0,
            "elements": [
                "rpsideas:dark_plate@3"
            ]
        },
        {
            "x": 6,
            "y": 1,
            "z": 6,
            "elements": [
                "rpsideas:dark_plate@3"
            ]
        },
        {
            "x": 0,
            "y": 4,
            "z": 4,

            "elements": [
                "projectred-illumination:lamp@0"
            ]
        },
        {
            "x": 3,
            "y": 5,
            "z": 3,
            "elements": [
                "fluxnetworks:fluxblock@0"
            ]
        },
        {
            "x": 5,
            "y": 9,
            "z": 1,
            "elements": [
                "fluxnetworks:fluxblock@0"
            ]
        },
        {
            "x": 9,
            "y": 7,
            "z": 2,
            "elements": [
                "appliedenergistics2:quartz_vibrant_glass@0"
            ]
        },
        {
            "x": 3,
            "y": 3,
            "z": 6,
            "elements": [
                "fluxnetworks:fluxblock@0"
            ]
        },
        {
            "x": 3,
            "y": 4,
            "z": 6,
            "elements": [
                "fluxnetworks:fluxblock@0"
            ]
        },
        {
            "x": 7,
            "y": 7,
            "z": 6,
            "elements": [
                "appliedenergistics2:quartz_vibrant_glass@0"
            ]
        },
        {
            "x": 5,
            "y": 3,
            "z": 0,
            "elements": [
                "psicosts:material_glassy@0"
            ]
        },
        {
            "x": 8,
            "y": 4,
            "z": 1,
            "elements": [
                "astralsorcery:fluidblockliquidstarlight@1"
            ]
        },
        {
            "x": 8,
            "y": 6,
            "z": 2,
            "elements": [
                "immersiveintelligence:metal_decoration@6"
            ]
        },
        {
            "x": 5,
            "y": 1,
            "z": 5,

            "elements": [
                "environmentaltech:structure_frame_5@0"
            ]
        },
        {
            "x": 1,
            "y": 1,
            "z": 3,
            "elements": [
                "minecraft:carpet@3"
            ]
        },
        {
            "x": 3,
            "y": 6,
            "z": 5,
            "elements": [
                "appliedenergistics2:quartz_vibrant_glass@0"
            ]
        },
        {
            "x": 5,
            "y": 8,
            "z": 2,
            "elements": [
                "immersiveintelligence:metal_decoration@6"
            ]
        },
        {
            "x": -2,
            "y": 5,
            "z": 4,
            "elements": [
                "appliedenergistics2:quartz_vibrant_glass@0"
            ]
        },
        {
            "x": 4,
            "y": 7,
            "z": 0,
            "elements": [
                "appliedenergistics2:quartz_vibrant_glass@0"
            ]
        },
        {
            "x": 1,
            "y": 4,
            "z": 3,

            "elements": [
                "projectred-illumination:lamp@0"
            ]
        },
        {
            "x": 8,
            "y": 0,
            "z": 0,
            "elements": [
                "fluxnetworks:fluxblock@0"
            ]
        },
        {
            "x": 2,
            "y": 1,
            "z": 2,
            "elements": [
                "sonarcore:reinforcedstonebrickfence@0"
            ]
        },
        {
            "x": 7,
            "y": 2,
            "z": 0,
            "elements": [
                "psicosts:material_glassy@0"
            ]
        },
        {
            "x": 5,
            "y": 0,
            "z": 5,
            "elements": [
                "fluxnetworks:fluxblock@0"
            ]
        },
        {
            "x": 4,
            "y": 2,
            "z": 3,
            "elements": [
                "astralsorcery:fluidblockliquidstarlight@1"
            ]
        },
        {
            "x": 7,
            "y": 6,
            "z": 6,
            "elements": [
                "appliedenergistics2:quartz_vibrant_glass@0"
            ]
        },
        {
            "x": 4,
            "y": 0,
            "z": 3,
            "elements": [
                "fluxnetworks:fluxblock@0"
            ]
        },
        {
            "x": 6,
            "y": 12,
            "z": 1,

            "elements": [
                "environmentaltech:lightning_rod@0"
            ]
        },
        {
            "x": 5,
            "y": 9,
            "z": 2,
            "elements": [
                "fluxnetworks:fluxblock@0"
            ]
        },
        {
            "x": 7,
            "y": 1,
            "z": 0,
            "elements": [
                "rpsideas:dark_plate@3"
            ]
        },
        {
            "x": 8,
            "y": 7,
            "z": 2,
            "elements": [
                "immersiveintelligence:metal_decoration@6"
            ]
        },
        {
            "x": 3,
            "y": 5,
            "z": 5,
            "elements": [
                "fluxnetworks:fluxblock@0"
            ]
        },
        {
            "x": 4,
            "y": 8,
            "z": 0,
            "elements": [
                "appliedenergistics2:quartz_vibrant_glass@0"
            ]
        },
        {
            "x": -1,
            "y": 0,
            "z": 4,
            "elements": [
                "fluxnetworks:fluxblock@0"
            ]
        },
        {
            "x": -2,
            "y": 5,
            "z": 3,
            "elements": [
                "appliedenergistics2:quartz_vibrant_glass@0"
            ]
        },
        {
            "x": 4,
            "y": 1,
            "z": 3,
            "elements": [
                "astralsorcery:fluidblockliquidstarlight@1"
            ]
        },
        {
            "x": 2,
            "y": 0,
            "z": 2,
            "elements": [
                "fluxnetworks:fluxblock@0"
            ]
        },
        {
            "x": 6,
            "y": 1,
            "z": 5,
            "elements": [
                "astralsorcery:fluidblockliquidstarlight@1"
            ]
        },
        {
            "x": 4,
            "y": 5,
            "z": 0,
            "elements": [
                "fluxnetworks:fluxblock@0"
            ]
        },
        {
            "x": 7,
            "y": 8,
            "z": 1,
            "elements": [
                "immersiveintelligence:metal_decoration@6"
            ]
        },
        {
            "x": 3,
            "y": 4,
            "z": 5,

            "elements": [
                "environmentaltech:structure_frame_5@0"
            ]
        },
        {
            "x": -1,
            "y": 1,
            "z": 4,
            "elements": [
                "minecraft:carpet@3"
            ]
        },
        {
            "x": 6,
            "y": 2,
            "z": 5,
            "elements": [
                "astralsorcery:fluidblockliquidstarlight@1"
            ]
        },
        {
            "x": 7,
            "y": 8,
            "z": 6,
            "elements": [
                "appliedenergistics2:quartz_vibrant_glass@0"
            ]
        },
        {
            "x": -2,
            "y": 4,
            "z": 3,

            "elements": [
                "projectred-illumination:lamp@0"
            ]
        },
        {
            "x": -2,
            "y": 4,
            "z": 4,

            "elements": [
                "projectred-illumination:lamp@0"
            ]
        },
        {
            "x": 6,
            "y": 0,
            "z": 5,
            "elements": [
                "fluxnetworks:fluxblock@0"
            ]
        },
        {
            "x": 7,
            "y": 4,
            "z": 0,
            "elements": [
                "rpsideas:dark_plate@3"
            ]
        },
        {
            "x": 1,
            "y": 5,
            "z": 3,
            "elements": [
                "appliedenergistics2:quartz_vibrant_glass@0"
            ]
        },
        {
            "x": 4,
            "y": 6,
            "z": 0,
            "elements": [
                "appliedenergistics2:quartz_vibrant_glass@0"
            ]
        },
        {
            "x": 1,
            "y": 0,
            "z": 3,
            "elements": [
                "fluxnetworks:fluxblock@0"
            ]
        },
        {
            "x": 7,
            "y": 9,
            "z": 6,
            "elements": [
                "fluxnetworks:fluxblock@0"
            ]
        },
        {
            "x": 5,
            "y": 10,
            "z": 2,

            "elements": [
                "environmentaltech:lightning_rod_insulated@0"
            ]
        },
        {
            "x": 7,
            "y": 9,
            "z": 1,
            "elements": [
                "fluxnetworks:fluxblock@0"
            ]
        },
        {
            "x": 3,
            "y": 3,
            "z": 5,

            "elements": [
                "environmentaltech:structure_frame_5@0"
            ]
        },
        {
            "x": 8,
            "y": 5,
            "z": 2,
            "elements": [
                "libvulpes:structuremachine@0"
            ]
        },
        {
            "x": 7,
            "y": 3,
            "z": 0,
            "elements": [
                "psicosts:material_glassy@0"
            ]
        },
        {
            "x": 3,
            "y": 1,
            "z": 5,

            "elements": [
                "environmentaltech:structure_frame_5@0"
            ]
        },
        {
            "x": 9,
            "y": 0,
            "z": 6,
            "elements": [
                "fluxnetworks:fluxblock@0"
            ]
        },
        {
            "x": 8,
            "y": 1,
            "z": 2,

            "elements": [
                "environmentaltech:structure_frame_5@0"
            ]
        },
        {
            "x": -2,
            "y": 1,
            "z": 4,
            "elements": [
                "sonarcore:reinforcedstonebrickfence@0"
            ]
        },
        {
            "x": 2,
            "y": 4,
            "z": 5,

            "elements": [
                "projectred-illumination:lamp@0"
            ]
        },
        {
            "x": 7,
            "y": 3,
            "z": 6,
            "elements": [
                "psicosts:material_glassy@0"
            ]
        },
        {
            "x": 6,
            "y": 5,
            "z": 6,
            "elements": [
                "fluxnetworks:fluxblock@0"
            ]
        },
        {
            "x": 4,
            "y": 4,
            "z": 0,
            "elements": [
                "rpsideas:dark_plate@3"
            ]
        },
        {
            "x": 3,
            "y": 2,
            "z": 5,

            "elements": [
                "environmentaltech:structure_frame_5@0"
            ]
        },
        {
            "x": 3,
            "y": 0,
            "z": 5,
            "elements": [
                "fluxnetworks:fluxblock@0"
            ]
        },
        {
            "x": 5,
            "y": 5,
            "z": 5,
            "elements": [
                "libvulpes:structuremachine@0"
            ]
        },
        {
            "x": 2,
            "y": 4,
            "z": 2,

            "elements": [
                "projectred-illumination:lamp@0"
            ]
        },
        {
            "x": 8,
            "y": 0,
            "z": 2,
            "elements": [
                "fluxnetworks:fluxblock@0"
            ]
        },
        {
            "x": 4,
            "y": 8,
            "z": 6,
            "elements": [
                "appliedenergistics2:quartz_vibrant_glass@0"
            ]
        },
        {
            "x": 9,
            "y": 1,
            "z": 6,
            "elements": [
                "fluxnetworks:fluxblock@0"
            ]
        },
        {
            "x": 4,
            "y": 9,
            "z": 6,
            "elements": [
                "fluxnetworks:fluxblock@0"
            ]
        },
        {
            "x": 4,
            "y": 3,
            "z": 0,
            "elements": [
                "psicosts:material_glassy@0"
            ]
        },
        {
            "x": 5,
            "y": 5,
            "z": 2,
            "elements": [
                "libvulpes:structuremachine@0"
            ]
        },
        {
            "x": 6,
            "y": 4,
            "z": 6,
            "elements": [
                "rpsideas:dark_plate@3"
            ]
        },
        {
            "x": 7,
            "y": 0,
            "z": 0,
            "elements": [
                "fluxnetworks:fluxblock@0"
            ]
        },
        {
            "x": 4,
            "y": 7,
            "z": 6,
            "elements": [
                "appliedenergistics2:quartz_vibrant_glass@0"
            ]
        },
        {
            "x": 7,
            "y": 5,
            "z": 6,
            "elements": [
                "fluxnetworks:fluxblock@0"
            ]
        },
        {
            "x": -1,
            "y": 5,
            "z": 2,
            "elements": [
                "appliedenergistics2:quartz_vibrant_glass@0"
            ]
        },
        {
            "x": 8,
            "y": 2,
            "z": 5,
            "elements": [
                "astralsorcery:fluidblockliquidstarlight@1"
            ]
        },
        {
            "x": 5,
            "y": 1,
            "z": 2,

            "elements": [
                "environmentaltech:structure_frame_5@0"
            ]
        },
        {
            "x": 7,
            "y": 2,
            "z": 6,
            "elements": [
                "psicosts:material_glassy@0"
            ]
        },
        {
            "x": 8,
            "y": 1,
            "z": 5,
            "elements": [
                "astralsorcery:fluidblockliquidstarlight@1"
            ]
        },
        {
            "x": 6,
            "y": 3,
            "z": 6,
            "elements": [
                "psicosts:material_glassy@0"
            ]
        },
        {
            "x": 4,
            "y": 2,
            "z": 0,
            "elements": [
                "psicosts:material_glassy@0"
            ]
        },
        {
            "x": -3,
            "y": 1,
            "z": 4,
            "elements": [
                "rpsideas:dark_plate@3"
            ]
        },
        {
            "x": 9,
            "y": 8,
            "z": 1,
            "elements": [
                "appliedenergistics2:quartz_vibrant_glass@0"
            ]
        },
        {
            "x": 5,
            "y": 6,
            "z": 2,
            "elements": [
                "immersiveintelligence:metal_decoration@6"
            ]
        },
        {
            "x": -1,
            "y": 4,
            "z": 2,

            "elements": [
                "projectred-illumination:lamp@0"
            ]
        },
        {
            "x": 8,
            "y": 0,
            "z": 5,
            "elements": [
                "fluxnetworks:fluxblock@0"
            ]
        },
        {
            "x": 5,
            "y": 7,
            "z": 2,
            "elements": [
                "immersiveintelligence:metal_decoration@6"
            ]
        },
        {
            "x": 4,
            "y": 6,
            "z": 6,
            "elements": [
                "appliedenergistics2:quartz_vibrant_glass@0"
            ]
        },
        {
            "x": 2,
            "y": 5,
            "z": 5,
            "elements": [
                "appliedenergistics2:quartz_vibrant_glass@0"
            ]
        },
        {
            "x": 4,
            "y": 1,
            "z": 0,
            "elements": [
                "rpsideas:dark_plate@3"
            ]
        },
        {
            "x": -2,
            "y": 0,
            "z": 4,
            "elements": [
                "fluxnetworks:fluxblock@0"
            ]
        },
        {
            "x": 9,
            "y": 9,
            "z": 1,
            "elements": [
                "fluxnetworks:fluxblock@0"
            ]
        },
        {
            "x": 5,
            "y": 0,
            "z": 2,
            "elements": [
                "fluxnetworks:fluxblock@0"
            ]
        },
        {
            "x": 2,
            "y": 5,
            "z": 2,
            "elements": [
                "appliedenergistics2:quartz_vibrant_glass@0"
            ]
        },
        {
            "x": 5,
            "y": 6,
            "z": 5,
            "elements": [
                "immersiveintelligence:metal_decoration@6"
            ]
        },
        {
            "x": 7,
            "y": 4,
            "z": 6,
            "elements": [
                "rpsideas:dark_plate@3"
            ]
        },
        {
            "x": -3,
            "y": 2,
            "z": 4,
            "elements": [
                "psicosts:material_glassy@0"
            ]
        },
        {
            "x": 8,
            "y": 4,
            "z": 5,
            "elements": [
                "astralsorcery:fluidblockliquidstarlight@1"
            ]
        },
        {
            "x": 9,
            "y": 1,
            "z": 1,
            "elements": [
                "rpsideas:dark_plate@3"
            ]
        },
        {
            "x": -3,
            "y": 1,
            "z": 3,
            "elements": [
                "rpsideas:dark_plate@3"
            ]
        },
        {
            "x": 9,
            "y": 6,
            "z": 1,
            "elements": [
                "appliedenergistics2:quartz_vibrant_glass@0"
            ]
        },
        {
            "x": -3,
            "y": 4,
            "z": 3,
            "elements": [
                "rpsideas:dark_plate@3"
            ]
        },
        {
            "x": 9,
            "y": 3,
            "z": 6,
            "elements": [
                "fluxnetworks:fluxblock@0"
            ]
        },
        {
            "x": 5,
            "y": 7,
            "z": 5,
            "elements": [
                "immersiveintelligence:metal_decoration@6"
            ]
        },
        {
            "x": 9,
            "y": 7,
            "z": 1,
            "elements": [
                "appliedenergistics2:quartz_vibrant_glass@0"
            ]
        },
        {
            "x": -3,
            "y": 2,
            "z": 3,
            "elements": [
                "psicosts:material_glassy@0"
            ]
        },
        {
            "x": 5,
            "y": 8,
            "z": 5,
            "elements": [
                "immersiveintelligence:metal_decoration@6"
            ]
        },
        {
            "x": 0,
            "y": 0,
            "z": 3,
            "elements": [
                "fluxnetworks:fluxblock@0"
            ]
        },
        {
            "x": 6,
            "y": 8,
            "z": 6,
            "elements": [
                "appliedenergistics2:quartz_vibrant_glass@0"
            ]
        },
        {
            "x": 8,
            "y": 3,
            "z": 5,
            "elements": [
                "astralsorcery:fluidblockliquidstarlight@1"
            ]
        },
        {
            "x": 2,
            "y": 5,
            "z": 4,
            "elements": [
                "appliedenergistics2:quartz_vibrant_glass@0"
            ]
        },
        {
            "x": 9,
            "y": 0,
            "z": 1,
            "elements": [
                "fluxnetworks:fluxblock@0"
            ]
        },
        {
            "x": 9,
            "y": 2,
            "z": 6,
            "elements": [
                "fluxnetworks:fluxblock@0"
            ]
        },
        {
            "x": 6,
            "y": 9,
            "z": 6,
            "elements": [
                "fluxnetworks:fluxblock@0"
            ]
        },
        {
            "x": 6,
            "y": 6,
            "z": 1,
            "elements": [
                "immersiveintelligence:metal_decoration@6"
            ]
        },
        {
            "x": 1,
            "y": 5,
            "z": 0,
            "elements": [
                "fluxnetworks:fluxblock@0"
            ]
        },
        {
            "x": 0,
            "y": 1,
            "z": 3,
            "elements": [
                "astralsorcery:blockblackmarble@2"
            ]
        },
        {
            "x": 9,
            "y": 5,
            "z": 6,
            "elements": [
                "fluxnetworks:fluxblock@0"
            ]
        },
        {
            "x": 3,
            "y": 8,
            "z": 1,
            "elements": [
                "appliedenergistics2:quartz_vibrant_glass@0"
            ]
        },
        {
            "x": 5,
            "y": 9,
            "z": 5,
            "elements": [
                "fluxnetworks:fluxblock@0"
            ]
        },
        {
            "x": 6,
            "y": 7,
            "z": 6,
            "elements": [
                "appliedenergistics2:quartz_vibrant_glass@0"
            ]
        },
        {
            "x": 6,
            "y": 5,
            "z": 1,
            "elements": [
                "astralsorcery:fluidblockliquidstarlight@0"
            ]
        },
        {
            "x": 9,
            "y": 3,
            "z": 1,
            "elements": [
                "psicosts:material_glassy@0"
            ]
        },
        {
            "x": 6,
            "y": 6,
            "z": 6,
            "elements": [
                "appliedenergistics2:quartz_vibrant_glass@0"
            ]
        },
        {
            "x": 0,
            "y": 2,
            "z": 3,
            "elements": [
                "minecraft:dragon_egg@0"
            ]
        },
        {
            "x": 9,
            "y": 2,
            "z": 1,
            "elements": [
                "psicosts:material_glassy@0"
            ]
        },
        {
            "x": 2,
            "y": 4,
            "z": 4,

            "elements": [
                "projectred-illumination:lamp@0"
            ]
        },
        {
            "x": 6,
            "y": 7,
            "z": 1,
            "elements": [
                "immersiveintelligence:metal_decoration@6"
            ]
        },
        {
            "x": 3,
            "y": 9,
            "z": 1,
            "elements": [
                "fluxnetworks:fluxblock@0"
            ]
        },
        {
            "x": -3,
            "y": 0,
            "z": 3,
            "elements": [
                "fluxnetworks:fluxblock@0"
            ]
        },
        {
            "x": -3,
            "y": 5,
            "z": 3,
            "elements": [
                "fluxnetworks:fluxblock@0"
            ]
        },
        {
            "x": 6,
            "y": 4,
            "z": 1,
            "elements": [
                "astralsorcery:fluidblockliquidstarlight@1"
            ]
        },
        {
            "x": 9,
            "y": 4,
            "z": 6,
            "elements": [
                "fluxnetworks:fluxblock@0"
            ]
        },
        {
            "x": 7,
            "y": 5,
            "z": 0,
            "elements": [
                "fluxnetworks:fluxblock@0"
            ]
        },
        {
            "x": 9,
            "y": 7,
            "z": 6,
            "elements": [
                "fluxnetworks:fluxblock@0"
            ]
        },
        {
            "x": 6,
            "y": 8,
            "z": 1,
            "elements": [
                "immersiveintelligence:metal_decoration@6"
            ]
        },
        {
            "x": -1,
            "y": 1,
            "z": 3,
            "elements": [
                "minecraft:carpet@3"
            ]
        },
        {
            "x": 8,
            "y": 8,
            "z": 6,
            "elements": [
                "appliedenergistics2:quartz_vibrant_glass@0"
            ]
        },
        {
            "x": 9,
            "y": 5,
            "z": 1,
            "elements": [
                "fluxnetworks:fluxblock@0"
            ]
        },
        {
            "x": 2,
            "y": 1,
            "z": 4,
            "elements": [
                "sonarcore:reinforcedstonebrickfence@0"
            ]
        },
        {
            "x": -1,
            "y": 4,
            "z": 4,

            "elements": [
                "projectred-illumination:lamp@0"
            ]
        },
        {
            "x": 6,
            "y": 9,
            "z": 1,
            "elements": [
                "fluxnetworks:fluxblock@0"
            ]
        },
        {
            "x": 7,
            "y": 6,
            "z": 0,
            "elements": [
                "appliedenergistics2:quartz_vibrant_glass@0"
            ]
        },
        {
            "x": 9,
            "y": 6,
            "z": 6,
            "elements": [
                "fluxnetworks:fluxblock@0"
            ]
        },
        {
            "x": 9,
            "y": 4,
            "z": 1,
            "elements": [
                "rpsideas:dark_plate@3"
            ]
        },
        {
            "x": 1,
            "y": 0,
            "z": 4,
            "elements": [
                "fluxnetworks:fluxblock@0"
            ]
        },
        {
            "x": -2,
            "y": 0,
            "z": 3,
            "elements": [
                "fluxnetworks:fluxblock@0"
            ]
        },
        {
            "x": 8,
            "y": 9,
            "z": 6,
            "elements": [
                "fluxnetworks:fluxblock@0"
            ]
        },
        {
            "x": -3,
            "y": 3,
            "z": 3,
            "elements": [
                "psicosts:material_glassy@0"
            ]
        },
        {
            "x": -1,
            "y": 5,
            "z": 4,
            "elements": [
                "appliedenergistics2:quartz_vibrant_glass@0"
            ]
        },
        {
            "x": 8,
            "y": 7,
            "z": 6,
            "elements": [
                "appliedenergistics2:quartz_vibrant_glass@0"
            ]
        },
        {
            "x": -2,
            "y": 1,
            "z": 3,
            "elements": [
                "sonarcore:reinforcedstonebrickfence@0"
            ]
        },
        {
            "x": 6,
            "y": 10,
            "z": 1,

            "elements": [
                "environmentaltech:lightning_rod_insulated@0"
            ]
        },
        {
            "x": 7,
            "y": 7,
            "z": 0,
            "elements": [
                "appliedenergistics2:quartz_vibrant_glass@0"
            ]
        },
        {
            "x": 9,
            "y": 8,
            "z": 6,
            "elements": [
                "fluxnetworks:fluxblock@0"
            ]
        },
        {
            "x": 1,
            "y": 1,
            "z": 4,
            "elements": [
                "minecraft:carpet@3"
            ]
        },
        {
            "x": 4,
            "y": 9,
            "z": 0,
            "elements": [
                "fluxnetworks:fluxblock@0"
            ]
        },
        {
            "x": 7,
            "y": 9,
            "z": 0,
            "elements": [
                "fluxnetworks:fluxblock@0"
            ]
        },
        {
            "x": -1,
            "y": 0,
            "z": 3,
            "elements": [
                "fluxnetworks:fluxblock@0"
            ]
        },
        {
            "x": 8,
            "y": 6,
            "z": 6,
            "elements": [
                "appliedenergistics2:quartz_vibrant_glass@0"
            ]
        },
        {
            "x": 6,
            "y": 11,
            "z": 1,

            "elements": [
                "environmentaltech:lightning_rod@0"
            ]
        },
        {
            "x": 2,
            "y": 0,
            "z": 4,
            "elements": [
                "fluxnetworks:fluxblock@0"
            ]
        },
        {
            "x": 7,
            "y": 8,
            "z": 0,
            "elements": [
                "appliedenergistics2:quartz_vibrant_glass@0"
            ]
        },
        {
            "x": 9,
            "y": 9,
            "z": 6,
            "elements": [
                "fluxnetworks:fluxblock@0"
            ]
        },
        {
            "x": 4,
            "y": 8,
            "z": 1,
            "elements": [
                "immersiveintelligence:metal_decoration@6"
            ]
        },
        {
            "x": 2,
            "y": 2,
            "z": 6,
            "elements": [
                "psicosts:material_glassy@0"
            ]
        },
        {
            "x": 3,
            "y": 3,
            "z": 2,

            "elements": [
                "environmentaltech:structure_frame_5@0"
            ]
        },
        {
            "x": 8,
            "y": 5,
            "z": 6,
            "elements": [
                "fluxnetworks:fluxblock@0"
            ]
        },
        {
            "x": 4,
            "y": 1,
            "z": 4,

            "elements": [
                "environmentaltech:structure_frame_5@0"
            ]
        },
        {
            "x": 8,
            "y": 9,
            "z": 5,
            "elements": [
                "fluxnetworks:fluxblock@0"
            ]
        },
        {
            "x": 0,
            "y": 5,
            "z": 2,
            "elements": [
                "appliedenergistics2:quartz_vibrant_glass@0"
            ]
        },
        {
            "x": 5,
            "y": 3,
            "z": 6,
            "elements": [
                "psicosts:material_glassy@0"
            ]
        },
        {
            "x": 7,
            "y": 5,
            "z": 1,
            "elements": [
                "libvulpes:structuremachine@0"
            ]
        },
        {
            "x": 9,
            "y": 7,
            "z": 5,
            "elements": [
                "appliedenergistics2:quartz_vibrant_glass@0"
            ]
        },
        {
            "x": 7,
            "y": 0,
            "z": 4,
            "elements": [
                "fluxnetworks:fluxblock@0"
            ]
        },
        {
            "x": 1,
            "y": 4,
            "z": 4,

            "elements": [
                "projectred-illumination:lamp@0"
            ]
        },
        {
            "x": 0,
            "y": 4,
            "z": 2,

            "elements": [
                "projectred-illumination:lamp@0"
            ]
        },
        {
            "x": 3,
            "y": 2,
            "z": 2,

            "elements": [
                "environmentaltech:structure_frame_5@0"
            ]
        },
        {
            "x": 2,
            "y": 3,
            "z": 6,
            "elements": [
                "psicosts:material_glassy@0"
            ]
        },
        {
            "x": 9,
            "y": 8,
            "z": 5,
            "elements": [
                "appliedenergistics2:quartz_vibrant_glass@0"
            ]
        },
        {
            "x": 4,
            "y": 9,
            "z": 1,
            "elements": [
                "fluxnetworks:fluxblock@0"
            ]
        },
        {
            "x": 8,
            "y": 4,
            "z": 6,
            "elements": [
                "rpsideas:dark_plate@3"
            ]
        },
        {
            "x": 7,
            "y": 1,
            "z": 4,

            "elements": [
                "environmentaltech:structure_frame_5@0"
            ]
        },
        {
            "x": 6,
            "y": 11,
            "z": 5,

            "elements": [
                "environmentaltech:lightning_rod@0"
            ]
        },
        {
            "x": 8,
            "y": 0,
            "z": 6,
            "elements": [
                "fluxnetworks:fluxblock@0"
            ]
        },
        {
            "x": 9,
            "y": 9,
            "z": 5,
            "elements": [
                "fluxnetworks:fluxblock@0"
            ]
        },
        {
            "x": 5,
            "y": 2,
            "z": 6,
            "elements": [
                "psicosts:material_glassy@0"
            ]
        },
        {
            "x": 6,
            "y": 12,
            "z": 5,

            "elements": [
                "environmentaltech:lightning_rod@0"
            ]
        },
        {
            "x": 8,
            "y": 3,
            "z": 6,
            "elements": [
                "psicosts:material_glassy@0"
            ]
        },
        {
            "x": 8,
            "y": 7,
            "z": 5,
            "elements": [
                "immersiveintelligence:metal_decoration@6"
            ]
        },
        {
            "x": 3,
            "y": 1,
            "z": 2,

            "elements": [
                "environmentaltech:structure_frame_5@0"
            ]
        },
        {
            "x": 5,
            "y": 5,
            "z": 6,
            "elements": [
                "fluxnetworks:fluxblock@0"
            ]
        },
        {
            "x": 9,
            "y": 9,
            "z": 0,
            "elements": [
                "fluxnetworks:fluxblock@0"
            ]
        },
        {
            "x": 8,
            "y": 1,
            "z": 6,
            "elements": [
                "rpsideas:dark_plate@3"
            ]
        },
        {
            "x": 8,
            "y": 8,
            "z": 5,
            "elements": [
                "immersiveintelligence:metal_decoration@6"
            ]
        },
        {
            "x": 1,
            "y": 4,
            "z": 2,

            "elements": [
                "projectred-illumination:lamp@0"
            ]
        },
        {
            "x": 8,
            "y": 2,
            "z": 6,
            "elements": [
                "psicosts:material_glassy@0"
            ]
        },
        {
            "x": 5,
            "y": 4,
            "z": 6,
            "elements": [
                "rpsideas:dark_plate@3"
            ]
        },
        {
            "x": 1,
            "y": 5,
            "z": 4,
            "elements": [
                "appliedenergistics2:quartz_vibrant_glass@0"
            ]
        },
        {
            "x": 4,
            "y": 0,
            "z": 4,
            "elements": [
                "fluxnetworks:fluxblock@0"
            ]
        },
        {
            "x": 3,
            "y": 0,
            "z": 2,
            "elements": [
                "fluxnetworks:fluxblock@0"
            ]
        },
        {
            "x": 5,
            "y": 7,
            "z": 6,
            "elements": [
                "appliedenergistics2:quartz_vibrant_glass@0"
            ]
        },
        {
            "x": 7,
            "y": 1,
            "z": 1,

            "elements": [
                "environmentaltech:structure_frame_5@0"
            ]
        },
        {
            "x": -1,
            "y": 4,
            "z": 6,
            "elements": [
                "rpsideas:dark_plate@3"
            ]
        },
        {
            "x": 7,
            "y": 7,
            "z": 5,
            "elements": [
                "immersiveintelligence:metal_decoration@6"
            ]
        },
        {
            "x": 7,
            "y": 0,
            "z": 1,
            "elements": [
                "fluxnetworks:fluxblock@0"
            ]
        },
        {
            "x": -1,
            "y": 4,
            "z": 3,

            "elements": [
                "projectred-illumination:lamp@0"
            ]
        },
        {
            "x": -3,
            "y": 3,
            "z": 2,
            "elements": [
                "psicosts:material_glassy@0"
            ]
        },
        {
            "x": 8,
            "y": 5,
            "z": 5,
            "elements": [
                "astralsorcery:fluidblockliquidstarlight@0"
            ]
        },
        {
            "x": 4,
            "y": 6,
            "z": 4,
            "elements": [
                "immersiveintelligence:metal_decoration@6"
            ]
        },
        {
            "x": 0,
            "y": 1,
            "z": 2,
            "elements": [
                "minecraft:carpet@3"
            ]
        },
        {
            "x": 5,
            "y": 6,
            "z": 6,
            "elements": [
                "appliedenergistics2:quartz_vibrant_glass@0"
            ]
        },
        {
            "x": 8,
            "y": 9,
            "z": 0,
            "elements": [
                "fluxnetworks:fluxblock@0"
            ]
        },
        {
            "x": 7,
            "y": 8,
            "z": 5,
            "elements": [
                "immersiveintelligence:metal_decoration@6"
            ]
        },
        {
            "x": 2,
            "y": 0,
            "z": 3,
            "elements": [
                "fluxnetworks:fluxblock@0"
            ]
        },
        {
            "x": 4,
            "y": 6,
            "z": 1,
            "elements": [
                "immersiveintelligence:metal_decoration@6"
            ]
        },
        {
            "x": 5,
            "y": 0,
            "z": 4,
            "elements": [
                "fluxnetworks:fluxblock@0"
            ]
        },
        {
            "x": 0,
            "y": 0,
            "z": 2,
            "elements": [
                "fluxnetworks:fluxblock@0"
            ]
        },
        {
            "x": 4,
            "y": 5,
            "z": 4,
            "elements": [
                "libvulpes:structuremachine@0"
            ]
        },
        {
            "x": -3,
            "y": 2,
            "z": 2,
            "elements": [
                "psicosts:material_glassy@0"
            ]
        },
        {
            "x": 8,
            "y": 6,
            "z": 5,
            "elements": [
                "immersiveintelligence:metal_decoration@6"
            ]
        },
        {
            "x": 2,
            "y": 1,
            "z": 3,
            "elements": [
                "sonarcore:reinforcedstonebrickfence@0"
            ]
        },
        {
            "x": -3,
            "y": 0,
            "z": 2,
            "elements": [
                "fluxnetworks:fluxblock@0"
            ]
        },
        {
            "x": 5,
            "y": 1,
            "z": 4,

            "elements": [
                "environmentaltech:structure_frame_5@0"
            ]
        },
        {
            "x": 7,
            "y": 9,
            "z": 5,
            "elements": [
                "fluxnetworks:fluxblock@0"
            ]
        },
        {
            "x": -1,
            "y": 5,
            "z": 6,
            "elements": [
                "fluxnetworks:fluxblock@0"
            ]
        },
        {
            "x": -3,
            "y": 1,
            "z": 2,
            "elements": [
                "rpsideas:dark_plate@3"
            ]
        },
        {
            "x": -1,
            "y": 2,
            "z": 6,
            "elements": [
                "psicosts:material_glassy@0"
            ]
        },
        {
            "x": 2,
            "y": 0,
            "z": 6,
            "elements": [
                "fluxnetworks:fluxblock@0"
            ]
        },
        {
            "x": 4,
            "y": 5,
            "z": 1,
            "elements": [
                "astralsorcery:fluidblockliquidstarlight@0"
            ]
        },
        {
            "x": 4,
            "y": 12,
            "z": 3,

            "elements": [
                "environmentaltech:lightning_rod@0"
            ]
        },
        {
            "x": 4,
            "y": 4,
            "z": 1,
            "elements": [
                "astralsorcery:fluidblockliquidstarlight@1"
            ]
        },
        {
            "x": -1,
            "y": 3,
            "z": 6,
            "elements": [
                "psicosts:material_glassy@0"
            ]
        },
        {
            "x": 4,
            "y": 7,
            "z": 1,
            "elements": [
                "immersiveintelligence:metal_decoration@6"
            ]
        },
        {
            "x": 5,
            "y": 8,
            "z": 6,
            "elements": [
                "appliedenergistics2:quartz_vibrant_glass@0"
            ]
        },
        {
            "x": -1,
            "y": 5,
            "z": 3,
            "elements": [
                "appliedenergistics2:quartz_vibrant_glass@0"
            ]
        },
        {
            "x": 5,
            "y": 9,
            "z": 6,
            "elements": [
                "fluxnetworks:fluxblock@0"
            ]
        },
        {
            "x": 2,
            "y": 1,
            "z": 6,
            "elements": [
                "rpsideas:dark_plate@3"
            ]
        },
        {
            "x": 4,
            "y": 3,
            "z": 1,
            "elements": [
                "astralsorcery:fluidblockliquidstarlight@1"
            ]
        },
        {
            "x": -2,
            "y": 0,
            "z": 2,
            "elements": [
                "fluxnetworks:fluxblock@0"
            ]
        },
        {
            "x": 9,
            "y": 2,
            "z": 5,
            "elements": [
                "psicosts:material_glassy@0"
            ]
        },
        {
            "x": 9,
            "y": 1,
            "z": 5,
            "elements": [
                "rpsideas:dark_plate@3"
            ]
        },
        {
            "x": 8,
            "y": 2,
            "z": 3,
            "elements": [
                "astralsorcery:fluidblockliquidstarlight@1"
            ]
        },
        {
            "x": 9,
            "y": 5,
            "z": 0,
            "elements": [
                "fluxnetworks:fluxblock@0"
            ]
        },
        {
            "x": 7,
            "y": 9,
            "z": 4,
            "elements": [
                "fluxnetworks:fluxblock@0"
            ]
        },
        {
            "x": 4,
            "y": 9,
            "z": 3,
            "elements": [
                "fluxnetworks:fluxblock@0"
            ]
        },
        {
            "x": 8,
            "y": 7,
            "z": 0,
            "elements": [
                "appliedenergistics2:quartz_vibrant_glass@0"
            ]
        },
        {
            "x": 7,
            "y": 8,
            "z": 4,
            "elements": [
                "immersiveintelligence:metal_decoration@6"
            ]
        },
        {
            "x": -2,
            "y": 1,
            "z": 2,
            "elements": [
                "sonarcore:reinforcedstonebrickfence@0"
            ]
        },
        {
            "x": 1,
            "y": 0,
            "z": 1,
            "elements": [
                "fluxnetworks:fluxblock@0"
            ]
        },
        {
            "x": 7,
            "y": 10,
            "z": 4,

            "elements": [
                "environmentaltech:lightning_rod_insulated@0"
            ]
        },
        {
            "x": 9,
            "y": 0,
            "z": 5,
            "elements": [
                "fluxnetworks:fluxblock@0"
            ]
        },
        {
            "x": 1,
            "y": 1,
            "z": 1,
            "elements": [
                "sonarcore:reinforcedstonebrickfence@0"
            ]
        },
        {
            "x": 2,
            "y": 5,
            "z": 3,
            "elements": [
                "appliedenergistics2:quartz_vibrant_glass@0"
            ]
        },
        {
            "x": 8,
            "y": 1,
            "z": 3,
            "elements": [
                "astralsorcery:fluidblockliquidstarlight@1"
            ]
        },
        {
            "x": 4,
            "y": 10,
            "z": 3,

            "elements": [
                "environmentaltech:lightning_rod_insulated@0"
            ]
        },
        {
            "x": 4,
            "y": 2,
            "z": 1,
            "elements": [
                "astralsorcery:fluidblockliquidstarlight@1"
            ]
        },
        {
            "x": 9,
            "y": 6,
            "z": 0,
            "elements": [
                "fluxnetworks:fluxblock@0"
            ]
        },
        {
            "x": 7,
            "y": 7,
            "z": 4,
            "elements": [
                "immersiveintelligence:metal_decoration@6"
            ]
        },
        {
            "x": 4,
            "y": 9,
            "z": 4,
            "elements": [
                "fluxnetworks:fluxblock@0"
            ]
        },
        {
            "x": 4,
            "y": 11,
            "z": 3,

            "elements": [
                "environmentaltech:lightning_rod@0"
            ]
        },
        {
            "x": 8,
            "y": 8,
            "z": 0,
            "elements": [
                "appliedenergistics2:quartz_vibrant_glass@0"
            ]
        },
        {
            "x": 6,
            "y": 6,
            "z": 5,
            "elements": [
                "immersiveintelligence:metal_decoration@6"
            ]
        },
        {
            "x": -2,
            "y": 5,
            "z": 1,
            "elements": [
                "appliedenergistics2:quartz_vibrant_glass@0"
            ]
        },
        {
            "x": 5,
            "y": 6,
            "z": 3,
            "elements": [
                "immersiveintelligence:metal_decoration@6"
            ]
        },
        {
            "x": -3,
            "y": 5,
            "z": 2,
            "elements": [
                "fluxnetworks:fluxblock@0"
            ]
        },
        {
            "x": 8,
            "y": 5,
            "z": 0,
            "elements": [
                "fluxnetworks:fluxblock@0"
            ]
        },
        {
            "x": -1,
            "y": 1,
            "z": 2,
            "elements": [
                "minecraft:carpet@3"
            ]
        },
        {
            "x": 4,
            "y": 8,
            "z": 4,
            "elements": [
                "immersiveintelligence:metal_decoration@6"
            ]
        },
        {
            "x": 4,
            "y": 0,
            "z": 1,
            "elements": [
                "fluxnetworks:fluxblock@0"
            ]
        },
        {
            "x": 2,
            "y": 4,
            "z": 3,

            "elements": [
                "projectred-illumination:lamp@0"
            ]
        },
        {
            "x": 8,
            "y": 0,
            "z": 3,
            "elements": [
                "fluxnetworks:fluxblock@0"
            ]
        },
        {
            "x": 6,
            "y": 9,
            "z": 0,
            "elements": [
                "fluxnetworks:fluxblock@0"
            ]
        },
        {
            "x": 9,
            "y": 7,
            "z": 0,
            "elements": [
                "fluxnetworks:fluxblock@0"
            ]
        },
        {
            "x": 4,
            "y": 7,
            "z": 3,
            "elements": [
                "immersiveintelligence:metal_decoration@6"
            ]
        },
        {
            "x": 5,
            "y": 0,
            "z": 3,
            "elements": [
                "fluxnetworks:fluxblock@0"
            ]
        },
        {
            "x": 5,
            "y": 5,
            "z": 3,
            "elements": [
                "libvulpes:structuremachine@0"
            ]
        },
        {
            "x": -3,
            "y": 4,
            "z": 2,
            "elements": [
                "rpsideas:dark_plate@3"
            ]
        },
        {
            "x": -2,
            "y": 4,
            "z": 1,

            "elements": [
                "projectred-illumination:lamp@0"
            ]
        },
        {
            "x": 4,
            "y": 1,
            "z": 1,
            "elements": [
                "astralsorcery:fluidblockliquidstarlight@1"
            ]
        },
        {
            "x": 8,
            "y": 6,
            "z": 0,
            "elements": [
                "appliedenergistics2:quartz_vibrant_glass@0"
            ]
        },
        {
            "x": -1,
            "y": 0,
            "z": 2,
            "elements": [
                "fluxnetworks:fluxblock@0"
            ]
        },
        {
            "x": 4,
            "y": 8,
            "z": 3,
            "elements": [
                "immersiveintelligence:metal_decoration@6"
            ]
        },
        {
            "x": 4,
            "y": 7,
            "z": 4,
            "elements": [
                "immersiveintelligence:metal_decoration@6"
            ]
        },
        {
            "x": 9,
            "y": 8,
            "z": 0,
            "elements": [
                "fluxnetworks:fluxblock@0"
            ]
        },
        {
            "x": 8,
            "y": 3,
            "z": 0,
            "elements": [
                "psicosts:material_glassy@0"
            ]
        },
        {
            "x": 4,
            "y": 6,
            "z": 3,
            "elements": [
                "immersiveintelligence:metal_decoration@6"
            ]
        },
        {
            "x": 5,
            "y": 0,
            "z": 6,
            "elements": [
                "fluxnetworks:fluxblock@0"
            ]
        },
        {
            "x": 1,
            "y": 5,
            "z": 1,
            "elements": [
                "appliedenergistics2:quartz_vibrant_glass@0"
            ]
        },
        {
            "x": 7,
            "y": 6,
            "z": 1,
            "elements": [
                "immersiveintelligence:metal_decoration@6"
            ]
        },
        {
            "x": 6,
            "y": 9,
            "z": 5,
            "elements": [
                "fluxnetworks:fluxblock@0"
            ]
        },
        {
            "x": 6,
            "y": 4,
            "z": 5,
            "elements": [
                "astralsorcery:fluidblockliquidstarlight@1"
            ]
        },
        {
            "x": -2,
            "y": 5,
            "z": 2,
            "elements": [
                "appliedenergistics2:quartz_vibrant_glass@0"
            ]
        },
        {
            "x": 2,
            "y": 5,
            "z": 6,
            "elements": [
                "fluxnetworks:fluxblock@0"
            ]
        },
        {
            "x": 3,
            "y": 7,
            "z": 5,
            "elements": [
                "appliedenergistics2:quartz_vibrant_glass@0"
            ]
        },
        {
            "x": 6,
            "y": 10,
            "z": 5,

            "elements": [
                "environmentaltech:lightning_rod_insulated@0"
            ]
        },
        {
            "x": -2,
            "y": 4,
            "z": 2,

            "elements": [
                "projectred-illumination:lamp@0"
            ]
        },
        {
            "x": 1,
            "y": 4,
            "z": 1,

            "elements": [
                "projectred-illumination:lamp@0"
            ]
        },
        {
            "x": 8,
            "y": 4,
            "z": 0,
            "elements": [
                "rpsideas:dark_plate@3"
            ]
        },
        {
            "x": 5,
            "y": 1,
            "z": 6,
            "elements": [
                "rpsideas:dark_plate@3"
            ]
        },
        {
            "x": 6,
            "y": 3,
            "z": 5,
            "elements": [
                "astralsorcery:fluidblockliquidstarlight@1"
            ]
        },
        {
            "x": 4,
            "y": 5,
            "z": 3,
            "elements": [
                "astralsorcery:fluidblockliquidstarlight@0"
            ]
        },
        {
            "x": 7,
            "y": 7,
            "z": 1,
            "elements": [
                "immersiveintelligence:metal_decoration@6"
            ]
        },
        {
            "x": 2,
            "y": 4,
            "z": 6,
            "elements": [
                "rpsideas:dark_plate@3"
            ]
        },
        {
            "x": 3,
            "y": 8,
            "z": 5,
            "elements": [
                "appliedenergistics2:quartz_vibrant_glass@0"
            ]
        },
        {
            "x": 9,
            "y": 4,
            "z": 5,
            "elements": [
                "rpsideas:dark_plate@3"
            ]
        },
        {
            "x": 7,
            "y": 6,
            "z": 4,
            "elements": [
                "immersiveintelligence:metal_decoration@6"
            ]
        },
        {
            "x": 4,
            "y": 4,
            "z": 3,
            "elements": [
                "astralsorcery:fluidblockliquidstarlight@1"
            ]
        },
        {
            "x": 6,
            "y": 7,
            "z": 5,
            "elements": [
                "immersiveintelligence:metal_decoration@6"
            ]
        },
        {
            "x": 3,
            "y": 9,
            "z": 5,
            "elements": [
                "fluxnetworks:fluxblock@0"
            ]
        },
        {
            "x": 1,
            "y": 1,
            "z": 2,
            "elements": [
                "minecraft:carpet@3"
            ]
        },
        {
            "x": 8,
            "y": 2,
            "z": 0,
            "elements": [
                "psicosts:material_glassy@0"
            ]
        },
        {
            "x": 9,
            "y": 5,
            "z": 5,
            "elements": [
                "fluxnetworks:fluxblock@0"
            ]
        },
        {
            "x": 6,
            "y": 5,
            "z": 5,
            "elements": [
                "astralsorcery:fluidblockliquidstarlight@0"
            ]
        },
        {
            "x": 9,
            "y": 3,
            "z": 5,
            "elements": [
                "psicosts:material_glassy@0"
            ]
        },
        {
            "x": 6,
            "y": 8,
            "z": 5,
            "elements": [
                "immersiveintelligence:metal_decoration@6"
            ]
        },
        {
            "x": 9,
            "y": 6,
            "z": 5,
            "elements": [
                "appliedenergistics2:quartz_vibrant_glass@0"
            ]
        },
        {
            "x": 8,
            "y": 1,
            "z": 0,
            "elements": [
                "rpsideas:dark_plate@3"
            ]
        },
        {
            "x": 4,
            "y": 3,
            "z": 3,
            "elements": [
                "astralsorcery:fluidblockliquidstarlight@1"
            ]
        },
        {
            "x": 7,
            "y": 5,
            "z": 4,
            "elements": [
                "libvulpes:structuremachine@0"
            ]
        },
        {
            "x": 5,
            "y": 1,
            "z": 3,

            "elements": [
                "environmentaltech:structure_frame_5@0"
            ]
        },
        {
            "x": 1,
            "y": 0,
            "z": 2,
            "elements": [
                "fluxnetworks:fluxblock@0"
            ]
        },
        {
            "x": -1,
            "y": 5,
            "z": 1,
            "elements": [
                "appliedenergistics2:quartz_vibrant_glass@0"
            ]
        },
        {
            "x": -3,
            "y": 4,
            "z": 6,
            "elements": [
                "fluxnetworks:fluxblock@0"
            ]
        },
        {
            "x": 5,
            "y": 5,
            "z": 0,
            "elements": [
                "fluxnetworks:fluxblock@0"
            ]
        },
        {
            "x": -3,
            "y": 0,
            "z": 1,
            "elements": [
                "fluxnetworks:fluxblock@0"
            ]
        },
        {
            "x": 4,
            "y": 4,
            "z": 5,
            "elements": [
                "astralsorcery:fluidblockliquidstarlight@1"
            ]
        },
        {
            "x": 8,
            "y": 9,
            "z": 3,
            "elements": [
                "fluxnetworks:fluxblock@0"
            ]
        },
        {
            "x": 0,
            "y": 5,
            "z": 6,
            "elements": [
                "fluxnetworks:fluxblock@0"
            ]
        },
        {
            "x": 7,
            "y": 0,
            "z": 3,
            "elements": [
                "fluxnetworks:fluxblock@0"
            ]
        },
        {
            "x": 9,
            "y": 4,
            "z": 4,
            "elements": [
                "rpsideas:dark_plate@3"
            ]
        },
        {
            "x": 3,
            "y": 9,
            "z": 0,
            "elements": [
                "fluxnetworks:fluxblock@0"
            ]
        },
        {
            "x": 3,
            "y": 0,
            "z": 6,
            "elements": [
                "fluxnetworks:fluxblock@0"
            ]
        },
        {
            "x": 6,
            "y": 4,
            "z": 0,
            "elements": [
                "rpsideas:dark_plate@3"
            ]
        },
        {
            "x": 5,
            "y": 6,
            "z": 0,
            "elements": [
                "appliedenergistics2:quartz_vibrant_glass@0"
            ]
        },
        {
            "x": 3,
            "y": 1,
            "z": 6,
            "elements": [
                "fluxnetworks:fluxblock@0"
            ]
        },
        {
            "x": 8,
            "y": 10,
            "z": 3,

            "elements": [
                "environmentaltech:lightning_rod_insulated@0"
            ]
        },
        {
            "x": 8,
            "y": 12,
            "z": 3,

            "elements": [
                "environmentaltech:lightning_rod@0"
            ]
        },
        {
            "x": -3,
            "y": 5,
            "z": 6,
            "elements": [
                "fluxnetworks:fluxblock@0"
            ]
        },
        {
            "x": -1,
            "y": 4,
            "z": 1,

            "elements": [
                "projectred-illumination:lamp@0"
            ]
        },
        {
            "x": 9,
            "y": 3,
            "z": 4,
            "elements": [
                "psicosts:material_glassy@0"
            ]
        },
        {
            "x": 4,
            "y": 3,
            "z": 5,
            "elements": [
                "astralsorcery:fluidblockliquidstarlight@1"
            ]
        },
        {
            "x": 6,
            "y": 10,
            "z": 2,

            "elements": [
                "environmentaltech:lightning_rod_insulated@0"
            ]
        },
        {
            "x": 6,
            "y": 3,
            "z": 0,
            "elements": [
                "psicosts:material_glassy@0"
            ]
        },
        {
            "x": -3,
            "y": 1,
            "z": 1,
            "elements": [
                "rpsideas:dark_plate@3"
            ]
        },
        {
            "x": 9,
            "y": 6,
            "z": 4,
            "elements": [
                "appliedenergistics2:quartz_vibrant_glass@0"
            ]
        },
        {
            "x": 4,
            "y": 6,
            "z": 5,
            "elements": [
                "immersiveintelligence:metal_decoration@6"
            ]
        },
        {
            "x": 6,
            "y": 9,
            "z": 4,
            "elements": [
                "fluxnetworks:fluxblock@0"
            ]
        },
        {
            "x": 6,
            "y": 2,
            "z": 0,
            "elements": [
                "psicosts:material_glassy@0"
            ]
        },
        {
            "x": 6,
            "y": 8,
            "z": 2,
            "elements": [
                "immersiveintelligence:metal_decoration@6"
            ]
        },
        {
            "x": 0,
            "y": 0,
            "z": 6,
            "elements": [
                "fluxnetworks:fluxblock@0"
            ]
        },
        {
            "x": 9,
            "y": 0,
            "z": 0,
            "elements": [
                "fluxnetworks:fluxblock@0"
            ]
        },
        {
            "x": 6,
            "y": 9,
            "z": 2,
            "elements": [
                "fluxnetworks:fluxblock@0"
            ]
        },
        {
            "x": 5,
            "y": 7,
            "z": 0,
            "elements": [
                "appliedenergistics2:quartz_vibrant_glass@0"
            ]
        },
        {
            "x": 8,
            "y": 7,
            "z": 3,
            "elements": [
                "immersiveintelligence:metal_decoration@6"
            ]
        },
        {
            "x": -3,
            "y": 2,
            "z": 6,
            "elements": [
                "fluxnetworks:fluxblock@0"
            ]
        },
        {
            "x": 0,
            "y": 0,
            "z": 1,
            "elements": [
                "fluxnetworks:fluxblock@0"
            ]
        },
        {
            "x": -3,
            "y": 2,
            "z": 1,
            "elements": [
                "psicosts:material_glassy@0"
            ]
        },
        {
            "x": 4,
            "y": 5,
            "z": 5,
            "elements": [
                "astralsorcery:fluidblockliquidstarlight@0"
            ]
        },
        {
            "x": 6,
            "y": 10,
            "z": 4,

            "elements": [
                "environmentaltech:lightning_rod_insulated@0"
            ]
        },
        {
            "x": -3,
            "y": 3,
            "z": 6,
            "elements": [
                "fluxnetworks:fluxblock@0"
            ]
        },
        {
            "x": 9,
            "y": 5,
            "z": 4,
            "elements": [
                "fluxnetworks:fluxblock@0"
            ]
        },
        {
            "x": 6,
            "y": 1,
            "z": 0,
            "elements": [
                "rpsideas:dark_plate@3"
            ]
        },
        {
            "x": 8,
            "y": 8,
            "z": 3,
            "elements": [
                "immersiveintelligence:metal_decoration@6"
            ]
        },
        {
            "x": 8,
            "y": 7,
            "z": 4,
            "elements": [
                "immersiveintelligence:metal_decoration@6"
            ]
        },
        {
            "x": 5,
            "y": 8,
            "z": 0,
            "elements": [
                "appliedenergistics2:quartz_vibrant_glass@0"
            ]
        },
        {
            "x": 0,
            "y": 2,
            "z": 6,
            "elements": [
                "psicosts:material_glassy@0"
            ]
        },
        {
            "x": -3,
            "y": 3,
            "z": 1,
            "elements": [
                "psicosts:material_glassy@0"
            ]
        },
        {
            "x": 0,
            "y": 1,
            "z": 6,
            "elements": [
                "rpsideas:dark_plate@3"
            ]
        },
        {
            "x": 0,
            "y": 1,
            "z": 1,
            "elements": [
                "sonarcore:reinforcedstonebrickfence@0"
            ]
        },
        {
            "x": 7,
            "y": 1,
            "z": 3,

            "elements": [
                "environmentaltech:structure_frame_5@0"
            ]
        },
        {
            "x": -1,
            "y": 0,
            "z": 1,
            "elements": [
                "fluxnetworks:fluxblock@0"
            ]
        },
        {
            "x": 3,
            "y": 5,
            "z": 0,
            "elements": [
                "fluxnetworks:fluxblock@0"
            ]
        },
        {
            "x": 9,
            "y": 9,
            "z": 4,
            "elements": [
                "fluxnetworks:fluxblock@0"
            ]
        },
        {
            "x": -3,
            "y": 5,
            "z": 1,
            "elements": [
                "fluxnetworks:fluxblock@0"
            ]
        },
        {
            "x": 5,
            "y": 9,
            "z": 0,
            "elements": [
                "fluxnetworks:fluxblock@0"
            ]
        },
        {
            "x": 6,
            "y": 7,
            "z": 0,
            "elements": [
                "appliedenergistics2:quartz_vibrant_glass@0"
            ]
        },
        {
            "x": 5,
            "y": 7,
            "z": 3,
            "elements": [
                "immersiveintelligence:metal_decoration@6"
            ]
        },
        {
            "x": 9,
            "y": 2,
            "z": 0,
            "elements": [
                "fluxnetworks:fluxblock@0"
            ]
        },
        {
            "x": 0,
            "y": 3,
            "z": 6,
            "elements": [
                "psicosts:material_glassy@0"
            ]
        },
        {
            "x": 8,
            "y": 5,
            "z": 3,
            "elements": [
                "astralsorcery:fluidblockliquidstarlight@0"
            ]
        },
        {
            "x": 3,
            "y": 6,
            "z": 0,
            "elements": [
                "fluxnetworks:fluxblock@0"
            ]
        },
        {
            "x": 8,
            "y": 8,
            "z": 4,
            "elements": [
                "immersiveintelligence:metal_decoration@6"
            ]
        },
        {
            "x": -3,
            "y": 4,
            "z": 1,
            "elements": [
                "rpsideas:dark_plate@3"
            ]
        },
        {
            "x": -1,
            "y": 1,
            "z": 1,
            "elements": [
                "sonarcore:reinforcedstonebrickfence@0"
            ]
        },
        {
            "x": 9,
            "y": 1,
            "z": 0,
            "elements": [
                "fluxnetworks:fluxblock@0"
            ]
        },
        {
            "x": 5,
            "y": 8,
            "z": 3,
            "elements": [
                "immersiveintelligence:metal_decoration@6"
            ]
        },
        {
            "x": 9,
            "y": 7,
            "z": 4,
            "elements": [
                "appliedenergistics2:quartz_vibrant_glass@0"
            ]
        },
        {
            "x": 8,
            "y": 6,
            "z": 3,
            "elements": [
                "immersiveintelligence:metal_decoration@6"
            ]
        },
        {
            "x": 6,
            "y": 8,
            "z": 0,
            "elements": [
                "appliedenergistics2:quartz_vibrant_glass@0"
            ]
        },
        {
            "x": -2,
            "y": 0,
            "z": 1,
            "elements": [
                "fluxnetworks:fluxblock@0"
            ]
        },
        {
            "x": 9,
            "y": 3,
            "z": 0,
            "elements": [
                "fluxnetworks:fluxblock@0"
            ]
        },
        {
            "x": 8,
            "y": 4,
            "z": 3,
            "elements": [
                "astralsorcery:fluidblockliquidstarlight@1"
            ]
        },
        {
            "x": 0,
            "y": 4,
            "z": 6,
            "elements": [
                "rpsideas:dark_plate@3"
            ]
        },
        {
            "x": 3,
            "y": 7,
            "z": 0,
            "elements": [
                "fluxnetworks:fluxblock@0"
            ]
        },
        {
            "x": 6,
            "y": 5,
            "z": 0,
            "elements": [
                "fluxnetworks:fluxblock@0"
            ]
        },
        {
            "x": 8,
            "y": 9,
            "z": 4,
            "elements": [
                "fluxnetworks:fluxblock@0"
            ]
        },
        {
            "x": 5,
            "y": 9,
            "z": 3,
            "elements": [
                "fluxnetworks:fluxblock@0"
            ]
        },
        {
            "x": 7,
            "y": 5,
            "z": 3,
            "elements": [
                "libvulpes:structuremachine@0"
            ]
        },
        {
            "x": 9,
            "y": 4,
            "z": 0,
            "elements": [
                "fluxnetworks:fluxblock@0"
            ]
        },
        {
            "x": 8,
            "y": 3,
            "z": 3,
            "elements": [
                "astralsorcery:fluidblockliquidstarlight@1"
            ]
        },
        {
            "x": 9,
            "y": 8,
            "z": 4,
            "elements": [
                "appliedenergistics2:quartz_vibrant_glass@0"
            ]
        },
        {
            "x": 5,
            "y": 10,
            "z": 3,

            "elements": [
                "environmentaltech:lightning_rod_insulated@0"
            ]
        },
        {
            "x": 6,
            "y": 6,
            "z": 0,
            "elements": [
                "appliedenergistics2:quartz_vibrant_glass@0"
            ]
        },
        {
            "x": 3,
            "y": 8,
            "z": 0,
            "elements": [
                "fluxnetworks:fluxblock@0"
            ]
        },
        {
            "x": -2,
            "y": 1,
            "z": 1,
            "elements": [
                "sonarcore:reinforcedstonebrickfence@0"
            ]
        },
        {
            "x": 7,
            "y": 6,
            "z": 3,
            "elements": [
                "immersiveintelligence:metal_decoration@6"
            ]
        },
        {
            "x": 6,
            "y": 1,
            "z": 2,

            "elements": [
                "environmentaltech:structure_frame_5@0"
            ]
        },
        {
            "x": 1,
            "y": 0,
            "z": 5,
            "elements": [
                "fluxnetworks:fluxblock@0"
            ]
        },
        {
            "x": 8,
            "y": 1,
            "z": 4,

            "elements": [
                "environmentaltech:structure_frame_5@0"
            ]
        },
        {
            "x": 4,
            "y": 9,
            "z": 5,
            "elements": [
                "fluxnetworks:fluxblock@0"
            ]
        },
        {
            "x": 3,
            "y": 2,
            "z": 0,
            "elements": [
                "fluxnetworks:fluxblock@0"
            ]
        },
        {
            "x": 7,
            "y": 7,
            "z": 3,
            "elements": [
                "immersiveintelligence:metal_decoration@6"
            ]
        },
        {
            "x": -1,
            "y": 0,
            "z": 6,
            "elements": [
                "fluxnetworks:fluxblock@0"
            ]
        },
        {
            "x": 3,
            "y": 5,
            "z": 1,
            "elements": [
                "fluxnetworks:fluxblock@0"
            ]
        },
        {
            "x": -2,
            "y": 2,
            "z": 6,
            "elements": [
                "psicosts:material_glassy@0"
            ]
        },
        {
            "x": 4,
            "y": 6,
            "z": 2,
            "elements": [
                "immersiveintelligence:metal_decoration@6"
            ]
        },
        {
            "x": -2,
            "y": 3,
            "z": 6,
            "elements": [
                "psicosts:material_glassy@0"
            ]
        },
        {
            "x": 7,
            "y": 5,
            "z": 5,
            "elements": [
