{
    "registryname": "plastic",
    "localizedname": "§e大型塑料混合机",
    "failure-action": "still",
    "requires-blueprint": false,
    "color": "BEBEBE",
    "parts": [
        {
            "x": 1,
            "y": 3,
            "z": 4,

            "elements": [
                "pneumaticcraft:compressed_iron_block@0"
            ]
        },
        {
            "x": 1,
            "y": 1,
            "z": 3,
            "elements": [
                "ebwizardry:crystal_block@1"
            ]
        },
        {
            "x": 0,
            "y": 3,
            "z": 1,
            "elements": [
                "ebwizardry:crystal_block@1"
            ]
        },
        {
            "x": -1,
            "y": 2,
            "z": 0,

            "elements": [
                "pneumaticcraft:compressed_iron_block@0"
            ]
        },
        {
            "x": 2,
            "y": 1,
            "z": 2,

            "elements": [
                "pneumaticcraft:compressed_iron_block@0"
            ]
        },
        {
            "x": 0,
            "y": 6,
            "z": 2,

            "elements": [
                "modularmachinery:blockfluidinputhatch",
                "modularmachinery:blockmefluidinputbus",
                "modularmachinery:blockmepatternprovider"
            ]
        },
        {
            "x": 0,
            "y": 2,
            "z": 1,
            "elements": [
                "ebwizardry:crystal_block@1"
            ]
        },
        {
            "x": -1,
            "y": 1,
            "z": 0,

            "elements": [
                "pneumaticcraft:compressed_iron_block@0"
            ]
        },
        {
            "x": 1,
            "y": 4,
            "z": 4,

            "elements": [
                "pneumaticcraft:pressure_chamber_glass@0"
            ]
        },
        {
            "x": -2,
            "y": 3,
            "z": 0,

            "elements": [
                "pneumaticcraft:pressure_chamber_wall@0"
            ]
        },
        {
            "x": -1,
            "y": 0,
            "z": 4,

            "elements": [
                "pneumaticcraft:pressure_chamber_wall@0"
            ]
        },
        {
            "x": -2,
            "y": 5,
            "z": 3,

            "elements": [
                "pneumaticcraft:pressure_chamber_glass@0"
            ]
        },
        {
            "x": 1,
            "y": 3,
            "z": 3,
            "elements": [
                "ebwizardry:crystal_block@1"
            ]
        },
        {
            "x": 2,
            "y": 0,
            "z": 2,

            "elements": [
                "modularmachinery:blockinputbus",
                "modularmachinery:blockmeiteminputbus",
                "modularmachinery:blockmepatternprovider"
            ]
        },
        {
            "x": 1,
            "y": 0,
            "z": 0,

            "elements": [
                "pneumaticcraft:pressure_chamber_wall@0"
            ]
        },
        {
            "x": -2,
            "y": 3,
            "z": 4,

            "elements": [
                "pneumaticcraft:pressure_chamber_wall@0"
            ]
        },
        {
            "x": -2,
            "y": 2,
            "z": 0,

            "elements": [
                "pneumaticcraft:pressure_chamber_wall@0"
            ]
        },
        {
            "x": 1,
            "y": 6,
            "z": 3,

            "elements": [
                "pneumaticcraft:pressure_chamber_glass@0"
            ]
        },
        {
            "x": 2,
            "y": 3,
            "z": 2,

            "elements": [
                "pneumaticcraft:compressed_iron_block@0"
            ]
        },
        {
            "x": -1,
            "y": 1,
            "z": 4,

            "elements": [
                "pneumaticcraft:compressed_iron_block@0"
            ]
        },
        {
            "x": -1,
            "y": 4,
            "z": 0,

            "elements": [
                "pneumaticcraft:pressure_chamber_glass@0"
            ]
        },
        {
            "x": -1,
            "y": 6,
            "z": 2,

            "elements": [
                "pneumaticcraft:pressure_chamber_glass@0"
            ]
        },
        {
            "x": 2,
            "y": 5,
            "z": 1,

            "elements": [
                "pneumaticcraft:pressure_chamber_glass@0"
            ]
        },
        {
            "x": -2,
            "y": 4,
            "z": 3,

            "elements": [
                "pneumaticcraft:pressure_chamber_glass@0"
            ]
        },
        {
            "x": 0,
            "y": 0,
            "z": 1,

            "elements": [
                "pneumaticcraft:pressure_chamber_wall@0"
            ]
        },
        {
            "x": 2,
            "y": 4,
            "z": 1,

            "elements": [
                "pneumaticcraft:pressure_chamber_glass@0"
            ]
        },
        {
            "x": -2,
            "y": 1,
            "z": 0,

            "elements": [
                "pneumaticcraft:pressure_chamber_wall@0"
            ]
        },
        {
            "x": 2,
            "y": 2,
            "z": 2,

            "elements": [
                "pneumaticcraft:compressed_iron_block@0"
            ]
        },
        {
            "x": 1,
            "y": 0,
            "z": 3,

            "elements": [
                "pneumaticcraft:pressure_chamber_wall@0"
            ]
        },
        {
            "x": -1,
            "y": 3,
            "z": 0,

            "elements": [
                "pneumaticcraft:compressed_iron_block@0"
            ]
        },
        {
            "x": 1,
            "y": 5,
            "z": 4,

            "elements": [
                "pneumaticcraft:pressure_chamber_glass@0"
            ]
        },
        {
            "x": -1,
            "y": 2,
            "z": 4,

            "elements": [
                "pneumaticcraft:compressed_iron_block@0"
            ]
        },
        {
            "x": 0,
            "y": 1,
            "z": 1,
            "elements": [
                "ebwizardry:crystal_block@1"
            ]
        },
        {
            "x": -1,
            "y": 6,
            "z": 1,

            "elements": [
                "pneumaticcraft:pressure_chamber_glass@0"
            ]
        },
        {
            "x": -2,
            "y": 3,
            "z": 3,

            "elements": [
                "pneumaticcraft:compressed_iron_block@0"
            ]
        },
        {
            "x": -1,
            "y": 0,
            "z": 1,

            "elements": [
                "pneumaticcraft:pressure_chamber_wall@0"
            ]
        },
        {
            "x": 2,
            "y": 0,
            "z": 0,

            "elements": [
                "pneumaticcraft:pressure_chamber_wall@0"
            ]
        },
        {
            "x": 0,
            "y": 6,
            "z": 3,

            "elements": [
                "pneumaticcraft:pressure_chamber_glass@0"
            ]
        },
        {
            "x": 1,
            "y": 2,
            "z": 0,

            "elements": [
                "pneumaticcraft:compressed_iron_block@0"
            ]
        },
        {
            "x": -2,
            "y": 1,
            "z": 4,

            "elements": [
                "pneumaticcraft:pressure_chamber_wall@0"
            ]
        },
        {
            "x": -2,
            "y": 2,
            "z": 1,

            "elements": [
                "pneumaticcraft:compressed_iron_block@0"
            ]
        },
        {
            "x": 2,
            "y": 2,
            "z": 3,

            "elements": [
                "pneumaticcraft:compressed_iron_block@0"
            ]
        },
        {
            "x": 0,
            "y": 1,
            "z": 2,
            "elements": [
                "ebwizardry:crystal_block@1"
            ]
        },
        {
            "x": 1,
            "y": 1,
            "z": 0,

            "elements": [
                "pneumaticcraft:compressed_iron_block@0"
            ]
        },
        {
            "x": 2,
            "y": 4,
            "z": 2,

            "elements": [
                "pneumaticcraft:pressure_chamber_glass@0"
            ]
        },
        {
            "x": 2,
            "y": 0,
            "z": 3,

            "elements": [
                "pneumaticcraft:pressure_chamber_wall@0"
            ]
        },
        {
            "x": -2,
            "y": 3,
            "z": 1,

            "elements": [
                "pneumaticcraft:compressed_iron_block@0"
            ]
        },
        {
            "x": -1,
            "y": 1,
            "z": 1,
            "elements": [
                "ebwizardry:crystal_block@1"
            ]
        },
        {
            "x": -1,
            "y": 3,
            "z": 3,
            "elements": [
                "ebwizardry:crystal_block@1"
            ]
        },
        {
            "x": 0,
            "y": 0,
            "z": 2,

            "elements": [
                "pneumaticcraft:pressure_chamber_wall@0"
            ]
        },
        {
            "x": -2,
            "y": 2,
            "z": 4,

            "elements": [
                "pneumaticcraft:pressure_chamber_wall@0"
            ]
        },
        {
            "x": -1,
            "y": 0,
            "z": 0,

            "elements": [
                "pneumaticcraft:pressure_chamber_wall@0"
            ]
        },
        {
            "x": -2,
            "y": 0,
            "z": 1,

            "elements": [
                "pneumaticcraft:pressure_chamber_wall@0"
            ]
        },
        {
            "x": 2,
            "y": 1,
            "z": 3,

            "elements": [
                "pneumaticcraft:compressed_iron_block@0"
            ]
        },
        {
            "x": 0,
            "y": 3,
            "z": 2,
            "elements": [
                "ebwizardry:crystal_block@1"
            ]
        },
        {
            "x": -1,
            "y": 3,
            "z": 1,
            "elements": [
                "ebwizardry:crystal_block@1"
            ]
        },
        {
            "x": -1,
            "y": 6,
            "z": 3,

            "elements": [
                "pneumaticcraft:pressure_chamber_glass@0"
            ]
        },
        {
            "x": -1,
            "y": 2,
            "z": 1,
            "elements": [
                "ebwizardry:crystal_block@1"
            ]
        },
        {
            "x": 1,
            "y": 4,
            "z": 0,

            "elements": [
                "pneumaticcraft:pressure_chamber_glass@0"
            ]
        },
        {
            "x": 1,
            "y": 2,
            "z": 3,
            "elements": [
                "ebwizardry:crystal_block@1"
            ]
        },
        {
            "x": -2,
            "y": 0,
            "z": 4,

            "elements": [
                "pneumaticcraft:pressure_chamber_wall@0"
            ]
        },
        {
            "x": 1,
            "y": 3,
            "z": 0,

            "elements": [
                "pneumaticcraft:compressed_iron_block@0"
            ]
        },
        {
            "x": 0,
            "y": 2,
            "z": 2,
            "elements": [
                "ebwizardry:crystal_block@1"
            ]
        },
        {
            "x": 2,
            "y": 5,
            "z": 2,

            "elements": [
                "pneumaticcraft:pressure_chamber_glass@0"
            ]
        },
        {
            "x": -2,
            "y": 1,
            "z": 1,

            "elements": [
                "pneumaticcraft:compressed_iron_block@0"
            ]
        },
        {
            "x": 0,
            "y": 3,
            "z": 3,
            "elements": [
                "ebwizardry:crystal_block@1"
            ]
        },
        {
            "x": -2,
            "y": 0,
            "z": 2,

            "elements": [
                "modularmachinery:blockoutputbus",
                "modularmachinery:blockmeitemoutputbus",
                "modularmachinery:blockmepatternprovider"
            ]
        },
        {
            "x": -1,
            "y": 3,
            "z": 2,
            "elements": [
                "ebwizardry:crystal_block@1"
            ]
        },
        {
            "x": -2,
            "y": 1,
            "z": 2,

            "elements": [
                "pneumaticcraft:compressed_iron_block@0"
            ]
        },
        {
            "x": 0,
            "y": 1,
            "z": 4,

            "elements": [
                "pneumaticcraft:compressed_iron_block@0"
            ]
        },
        {
            "x": 1,
            "y": 0,
            "z": 1,

            "elements": [
                "pneumaticcraft:pressure_chamber_wall@0"
            ]
        },
        {
            "x": 0,
            "y": 0,
            "z": 3,

            "elements": [
                "pneumaticcraft:pressure_chamber_wall@0"
            ]
        },
        {
            "x": 2,
            "y": 5,
            "z": 3,

            "elements": [
                "pneumaticcraft:pressure_chamber_glass@0"
            ]
        },
        {
            "x": -1,
            "y": 2,
            "z": 2,
            "elements": [
                "ebwizardry:crystal_block@1"
            ]
        },
        {
            "x": 1,
            "y": 1,
            "z": 1,
            "elements": [
                "ebwizardry:crystal_block@1"
            ]
        },
        {
            "x": 2,
            "y": 3,
            "z": 0,

            "elements": [
                "pneumaticcraft:pressure_chamber_wall@0"
            ]
        },
        {
            "x": 0,
            "y": 2,
            "z": 4,

            "elements": [
                "pneumaticcraft:compressed_iron_block@0"
            ]
        },
        {
            "x": 1,
            "y": 5,
            "z": 0,

            "elements": [
                "pneumaticcraft:pressure_chamber_glass@0"
            ]
        },
        {
            "x": -2,
            "y": 5,
            "z": 1,

            "elements": [
                "pneumaticcraft:pressure_chamber_glass@0"
            ]
        },
        {
            "x": 0,
            "y": 1,
            "z": 3,
            "elements": [
                "ebwizardry:crystal_block@1"
            ]
        },
        {
            "x": 2,
            "y": 3,
            "z": 4,

            "elements": [
                "pneumaticcraft:pressure_chamber_wall@0"
            ]
        },
        {
            "x": 1,
            "y": 3,
            "z": 1,
            "elements": [
                "ebwizardry:crystal_block@1"
            ]
        },
        {
            "x": 2,
            "y": 2,
            "z": 0,

            "elements": [
                "pneumaticcraft:pressure_chamber_wall@0"
            ]
        },
        {
            "x": 1,
            "y": 2,
            "z": 1,
            "elements": [
                "ebwizardry:crystal_block@1"
            ]
        },
        {
            "x": -2,
            "y": 3,
            "z": 2,

            "elements": [
                "pneumaticcraft:compressed_iron_block@0"
            ]
        },
        {
            "x": 2,
            "y": 4,
            "z": 3,

            "elements": [
                "pneumaticcraft:pressure_chamber_glass@0"
            ]
        },
        {
            "x": -1,
            "y": 1,
            "z": 2,
            "elements": [
                "ebwizardry:crystal_block@1"
            ]
        },
        {
            "x": 0,
            "y": 2,
            "z": 3,
            "elements": [
                "ebwizardry:crystal_block@1"
            ]
        },
        {
            "x": -2,
            "y": 4,
            "z": 1,

            "elements": [
                "pneumaticcraft:pressure_chamber_glass@0"
            ]
        },
        {
            "x": 2,
            "y": 1,
            "z": 0,

            "elements": [
                "pneumaticcraft:pressure_chamber_wall@0"
            ]
        },
        {
            "x": 2,
            "y": 3,
            "z": 3,

            "elements": [
                "pneumaticcraft:compressed_iron_block@0"
            ]
        },
        {
            "x": -2,
            "y": 2,
            "z": 2,

            "elements": [
                "pneumaticcraft:compressed_iron_block@0"
            ]
        },
        {
            "x": 0,
            "y": 0,
            "z": 4,

            "elements": [
                "gugu-utils:pressurehatch@0"
            ]
        },
        {
            "x": -1,
            "y": 0,
            "z": 2,

            "elements": [
                "pneumaticcraft:pressure_chamber_wall@0"
            ]
        },
        {
            "x": -2,
            "y": 0,
            "z": 0,

            "elements": [
                "pneumaticcraft:pressure_chamber_wall@0"
            ]
        },
        {
            "x": 0,
            "y": 5,
            "z": 0,

            "elements": [
                "pneumaticcraft:pressure_chamber_glass@0"
            ]
        },
        {
            "x": -1,
            "y": 3,
            "z": 4,

            "elements": [
                "pneumaticcraft:compressed_iron_block@0"
            ]
        },
        {
            "x": 2,
            "y": 3,
            "z": 1,

            "elements": [
                "pneumaticcraft:compressed_iron_block@0"
            ]
        },
        {
            "x": 1,
            "y": 3,
            "z": 2,
            "elements": [
                "ebwizardry:crystal_block@1"
            ]
        },
        {
            "x": -2,
            "y": 5,
            "z": 2,

            "elements": [
                "pneumaticcraft:pressure_chamber_glass@0"
            ]
        },
        {
            "x": -1,
            "y": 1,
            "z": 3,
            "elements": [
                "ebwizardry:crystal_block@1"
            ]
        },
        {
            "x": 0,
            "y": 4,
            "z": 0,

            "elements": [
                "pneumaticcraft:pressure_chamber_glass@0"
            ]
        },
        {
            "x": 2,
            "y": 1,
            "z": 4,

            "elements": [
                "pneumaticcraft:pressure_chamber_wall@0"
            ]
        },
        {
            "x": -2,
            "y": 4,
            "z": 2,

            "elements": [
                "pneumaticcraft:pressure_chamber_glass@0"
            ]
        },
        {
            "x": 2,
            "y": 2,
            "z": 4,

            "elements": [
                "pneumaticcraft:pressure_chamber_wall@0"
            ]
        },
        {
            "x": -1,
            "y": 2,
            "z": 3,
            "elements": [
                "ebwizardry:crystal_block@1"
            ]
        },
        {
            "x": 2,
            "y": 2,
            "z": 1,

            "elements": [
                "pneumaticcraft:compressed_iron_block@0"
            ]
        },
        {
            "x": -1,
            "y": 4,
            "z": 4,

            "elements": [
                "pneumaticcraft:pressure_chamber_glass@0"
            ]
        },
        {
            "x": 0,
            "y": 5,
            "z": 4,

            "elements": [
                "pneumaticcraft:pressure_chamber_glass@0"
            ]
        },
        {
            "x": 0,
            "y": 3,
            "z": 0,

            "elements": [
                "pneumaticcraft:compressed_iron_block@0"
            ]
        },
        {
            "x": 1,
            "y": 0,
            "z": 4,

            "elements": [
                "pneumaticcraft:pressure_chamber_wall@0"
            ]
        },
        {
            "x": 1,
            "y": 2,
            "z": 2,
            "elements": [
                "ebwizardry:crystal_block@1"
            ]
        },
        {
            "x": -2,
            "y": 0,
            "z": 3,

            "elements": [
                "pneumaticcraft:pressure_chamber_wall@0"
            ]
        },
        {
            "x": -1,
            "y": 5,
            "z": 0,

            "elements": [
                "pneumaticcraft:pressure_chamber_glass@0"
            ]
        },
        {
            "x": 0,
            "y": 6,
            "z": 1,

            "elements": [
                "pneumaticcraft:pressure_chamber_glass@0"
            ]
        },
        {
            "x": 0,
            "y": 3,
            "z": 4,

            "elements": [
                "pneumaticcraft:compressed_iron_block@0"
            ]
        },
        {
            "x": -1,
            "y": 5,
            "z": 4,

            "elements": [
                "pneumaticcraft:pressure_chamber_glass@0"
            ]
        },
        {
            "x": 0,
            "y": 2,
            "z": 0,

            "elements": [
                "pneumaticcraft:compressed_iron_block@0"
            ]
        },
        {
            "x": -2,
            "y": 1,
            "z": 3,

            "elements": [
                "pneumaticcraft:compressed_iron_block@0"
            ]
        },
        {
            "x": 1,
            "y": 1,
            "z": 2,
            "elements": [
                "ebwizardry:crystal_block@1"
            ]
        },
        {
            "x": 1,
            "y": 6,
            "z": 2,

            "elements": [
                "pneumaticcraft:pressure_chamber_glass@0"
            ]
        },
        {
            "x": 2,
            "y": 0,
            "z": 1,

            "elements": [
                "pneumaticcraft:pressure_chamber_wall@0"
            ]
        },
        {
            "x": 1,
            "y": 1,
            "z": 4,

            "elements": [
                "pneumaticcraft:compressed_iron_block@0"
            ]
        },
        {
            "x": -2,
            "y": 2,
            "z": 3,

            "elements": [
                "pneumaticcraft:compressed_iron_block@0"
            ]
        },
        {
            "x": 0,
            "y": 1,
            "z": 0,
            "selector-tag": "biaojiwu",
            "elements": [
                "modularmachinery:blockinputbus@0"
            ]
        },
        {
            "x": 1,
            "y": 2,
            "z": 4,

            "elements": [
                "pneumaticcraft:compressed_iron_block@0"
            ]
        },
        {
            "x": -1,
            "y": 0,
            "z": 3,

            "elements": [
                "pneumaticcraft:pressure_chamber_wall@0"
            ]
        },
        {
            "x": 0,
            "y": 4,
            "z": 4,

            "elements": [
                "pneumaticcraft:pressure_chamber_glass@0"
            ]
        },
        {
            "x": 2,
            "y": 1,
            "z": 1,

            "elements": [
                "pneumaticcraft:compressed_iron_block@0"
            ]
        },
        {
            "x": 2,
            "y": 0,
            "z": 4,

            "elements": [
                "pneumaticcraft:pressure_chamber_wall@0"
            ]
        },
        {
            "x": 1,
            "y": 6,
            "z": 1,

            "elements": [
                "pneumaticcraft:pressure_chamber_glass@0"
            ]
        },
        {
            "x": 1,
            "y": 0,
            "z": 2,

            "elements": [
                "pneumaticcraft:pressure_chamber_wall@0"
            ]
        }
    ]}