{
    "registryname": "uu",
    "localizedname": "§d物质扭曲仪",
    "failure-action": "still",
    "requires-blueprint": false,
    "color": "FFFFFF",
    "modifiers": [
        {
            "elements": "modularmachinery:blockenergyinputhatch@6",
            "x": 0,
            "y": 5,
            "z": 5,
            "description": "将此能量输入仓换为超级能源输入仓以降低7%能量消耗",
            "modifier": {
                "io": "input",
                "target": "modularmachinery:energy",
                "operation": 1,
                "multiplier": 0.93
            }
        },
        {
            "elements": "modularmachinery:blockenergyinputhatch@7",
            "x": 0,
            "y": 5,
            "z": 5,
            "description": "将此能量输入仓换为终极能源输入仓以降低18%能量消耗",
            "modifier": {
                "io": "input",
                "target": "modularmachinery:energy",
                "operation": 1,
                "multiplier": 0.82
            }
        },
        {
            "elements": "modularmachinery:blockenergyinputhatch@6",
            "x": 0,
            "y": 5,
            "z": -5,
            "description": "将此能量输入仓换为超级能源输入仓以降低7%能量消耗",
            "modifier": {
                "io": "input",
                "target": "modularmachinery:energy",
                "operation": 1,
                "multiplier": 0.93
            }
        },
        {
            "elements": "modularmachinery:blockenergyinputhatch@7",
            "x": 0,
            "y": 5,
            "z": -5,
            "description": "将此能量输入仓换为终极能源输入仓以降低18%能量消耗",
            "modifier": {
                "io": "input",
                "target": "modularmachinery:energy",
                "operation": 1,
                "multiplier": 0.82
            }
        }
    ],
    "parts": [
        {
            "x": 2,
            "y": 1,
            "z": -5,
            "elements": [
                "appliedenergistics2:quartz_pillar@1"
            ]
        },
        {
            "x": -3,
            "y": -2,
            "z": 5,
            "elements": [
                "appliedenergistics2:sky_stone_small_brick@0"
            ]
        },
        {
            "x": 3,
            "y": 6,
            "z": -4,
            "elements": [
                "botania:quartzslabsunnyhalf@8"
            ]
        },
        {
            "x": 2,
            "y": -1,
            "z": -5,
            "elements": [
                "appliedenergistics2:quartz_pillar@1"
            ]
        },
        {
            "x": 0,
            "y": -2,
            "z": 0,
            "elements": [
                "modularmachinery:blockfluidoutputhatch",
                "modularmachinery:blockmefluidoutputbus",
                "modularmachinery:blockmepatternprovider"
            ]
        },
        {
            "x": -3,
            "y": 0,
            "z": 5,
            "elements": [
                "extrautils2:decorativeglass@0"
            ]
        },
        {
            "x": -5,
            "y": 6,
            "z": 5,
            "elements": [
                "botania:quartztypesunny@2"
            ]
        },
        {
            "x": -4,
            "y": 4,
            "z": 5,
            "elements": [
                "calculator:flawlessglass@0"
            ]
        },
        {
            "x": -3,
            "y": 2,
            "z": 5,
            "elements": [
                "appliedenergistics2:chiseled_quartz_block@0"
            ]
        },
        {
            "x": -3,
            "y": 6,
            "z": 0,
            "elements": [
                "botania:quartzslabsunnyhalf@8"
            ]
        },
        {
            "x": 5,
            "y": -2,
            "z": 1,
            "elements": [
                "modularmachinery:blockcasing@4"
            ]
        },
        {
            "x": -4,
            "y": 8,
            "z": 0,
            "elements": [
                "botania:quartzstairssunny@0"
            ]
        },
        {
            "x": -2,
            "y": 7,
            "z": -5,
            "elements": [
                "botania:quartzstairssunny@0"
            ]
        },
        {
            "x": 3,
            "y": 7,
            "z": 4,
            "elements": [
                "botania:quartzstairssunny@1"
            ]
        },
        {
            "x": 0,
            "y": 3,
            "z": -5,
            "elements": [
                "appliedenergistics2:fluix_slab@0"
            ]
        },
        {
            "x": 5,
            "y": -1,
            "z": 1,
            "elements": [
                "extrautils2:decorativeglass@0"
            ]
        },
        {
            "x": 6,
            "y": 6,
            "z": 3,
            "elements": [
                "botania:quartztypesunny@2"
            ]
        },
        {
            "x": 3,
            "y": 1,
            "z": -5,
            "elements": [
                "extrautils2:decorativeglass@0"
            ]
        },
        {
            "x": -4,
            "y": -2,
            "z": 5,
            "elements": [
                "appliedenergistics2:sky_stone_small_brick_stairs@3"
            ]
        },
        {
            "x": 1,
            "y": -2,
            "z": 0,
            "elements": [
                "ic2:uu_matter@0"
            ]
        },
        {
            "x": -6,
            "y": 3,
            "z": -1,
            "elements": [
                "calculator:flawlessglass@0"
            ]
        },
        {
            "x": 6,
            "y": 4,
            "z": 3,
            "elements": [
                "botania:quartztypesunny@2"
            ]
        },
        {
            "x": -4,
            "y": 6,
            "z": 5,
            "elements": [
                "calculator:flawlessglass@0"
            ]
        },
        {
            "x": -2,
            "y": 0,
            "z": 5,
            "elements": [
                "appliedenergistics2:quartz_pillar@1"
            ]
        },
        {
            "x": -5,
            "y": 4,
            "z": 5,
            "elements": [
                "botania:quartztypesunny@2"
            ]
        },
        {
            "x": -4,
            "y": 6,
            "z": 0,
            "elements": [
                "botania:quartzslabsunnyhalf@8"
            ]
        },
        {
            "x": 0,
            "y": 7,
            "z": 4,
            "elements": [
                "botania:quartztypesunny@1"
            ]
        },
        {
            "x": -3,
            "y": 8,
            "z": 0,
            "elements": [
                "botania:quartztypesunny@1"
            ]
        },
        {
            "x": -2,
            "y": 2,
            "z": 5,
            "elements": [
                "appliedenergistics2:quartz_pillar@1"
            ]
        },
        {
            "x": -6,
            "y": 2,
            "z": -1,
            "elements": [
                "botania:quartztypesunny@2"
            ]
        },
        {
            "x": -3,
            "y": 7,
            "z": -5,
            "elements": [
                "botania:quartzslabsunnyhalf@0"
            ]
        },
        {
            "x": 0,
            "y": 5,
            "z": -5,
            "elements": [
                "modularmachinery:blockenergyinputhatch"
            ]
        },
        {
            "x": -3,
            "y": 6,
            "z": 5,
            "elements": [
                "minecraft:glowstone@0"
            ]
        },
        {
            "x": 0,
            "y": 8,
            "z": 3,
            "elements": [
                "botania:quartztypesunny@1"
            ]
        },
        {
            "x": 5,
            "y": 6,
            "z": -4,
            "elements": [
                "calculator:flawlessglass@0"
            ]
        },
        {
            "x": 3,
            "y": 9,
            "z": -1,
            "elements": [
                "botania:quartzstairssunny@1"
            ]
        },
        {
            "x": -1,
            "y": 3,
            "z": -5,
            "elements": [
                "appliedenergistics2:fluix_slab@0"
            ]
        },
        {
            "x": 6,
            "y": 3,
            "z": 1,
            "elements": [
                "calculator:flawlessglass@0"
            ]
        },
        {
            "x": 0,
            "y": 6,
            "z": 3,
            "elements": [
                "botania:quartzslabsunnyhalf@8"
            ]
        },
        {
            "x": -5,
            "y": 0,
            "z": 5,
            "elements": [
                "botania:quartztypesunny@2"
            ]
        },
        {
            "x": -2,
            "y": -2,
            "z": 0,
            "elements": [
                "ic2:uu_matter@0"
            ]
        },
        {
            "x": -1,
            "y": -2,
            "z": 5,
            "elements": [
                "modularmachinery:blockcasing@4"
            ]
        },
        {
            "x": 2,
            "y": 7,
            "z": -3,
            "elements": [
                "botania:quartztypesunny@1"
            ]
        },
        {
            "x": 6,
            "y": 2,
            "z": -1,
            "elements": [
                "botania:quartztypesunny@2"
            ]
        },
        {
            "x": -5,
            "y": 6,
            "z": 0,
            "elements": [
                "minecraft:glowstone@0"
            ]
        },
        {
            "x": 6,
            "y": 3,
            "z": -1,
            "elements": [
                "calculator:flawlessglass@0"
            ]
        },
        {
            "x": 6,
            "y": 2,
            "z": 1,
            "elements": [
                "botania:quartztypesunny@2"
            ]
        },
        {
            "x": 3,
            "y": 8,
            "z": -1,
            "elements": [
                "botania:quartztypesunny@1"
            ]
        },
        {
            "x": -5,
            "y": 2,
            "z": 5,
            "elements": [
                "botania:quartztypesunny@2"
            ]
        },
        {
            "x": -2,
            "y": 8,
            "z": 0,
            "elements": [
                "ic2:uu_matter@0"
            ]
        },
        {
            "x": -4,
            "y": 7,
            "z": -5,
            "elements": [
                "botania:quartzslabsunnyhalf@0"
            ]
        },
        {
            "x": 2,
            "y": 3,
            "z": -5,
            "elements": [
                "appliedenergistics2:quartz_pillar@1"
            ]
        },
        {
            "x": 3,
            "y": -2,
            "z": 0,
            "elements": [
                "ic2:uu_matter@0"
            ]
        },
        {
            "x": 5,
            "y": 1,
            "z": -5,
            "elements": [
                "botania:quartztypesunny@2"
            ]
        },
        {
            "x": -7,
            "y": -2,
            "z": -1,
            "elements": [
                "appliedenergistics2:sky_stone_small_brick_stairs@0"
            ]
        },
        {
            "x": 0,
            "y": 0,
            "z": 5,
            "elements": [
                "extrautils2:decorativeglass@0"
            ]
        },
        {
            "x": 0,
            "y": 2,
            "z": 5,
            "elements": [
                "appliedenergistics2:chiseled_quartz_block@0"
            ]
        },
        {
            "x": -2,
            "y": 6,
            "z": 0,
            "elements": [
                "botania:quartzslabsunnyhalf@8"
            ]
        },
        {
            "x": 2,
            "y": 7,
            "z": 4,
            "elements": [
                "botania:quartzstairssunny@3"
            ]
        },
        {
            "x": -1,
            "y": 7,
            "z": -5,
            "elements": [
                "botania:quartzstairssunny@2"
            ]
        },
        {
            "x": -1,
            "y": 9,
            "z": -3,
            "elements": [
                "botania:quartzstairssunny@2"
            ]
        },
        {
            "x": 2,
            "y": 5,
            "z": -5,
            "elements": [
                "appliedenergistics2:quartz_pillar@1"
            ]
        },
        {
            "x": -7,
            "y": -2,
            "z": 1,
            "elements": [
                "appliedenergistics2:sky_stone_small_brick_stairs@0"
            ]
        },
        {
            "x": 3,
            "y": 7,
            "z": 6,
            "elements": [
                "botania:quartztypesunny@2"
            ]
        },
        {
            "x": 4,
            "y": -2,
            "z": 0,
            "elements": [
                "ic2:uu_matter@0"
            ]
        },
        {
            "x": -5,
            "y": 2,
            "z": 0,
            "elements": [
                "appliedenergistics2:chiseled_quartz_block@0"
            ]
        },
        {
            "x": 1,
            "y": -2,
            "z": 5,
            "elements": [
                "modularmachinery:blockcasing@4"
            ]
        },
        {
            "x": -2,
            "y": 1,
            "z": -5,
            "elements": [
                "appliedenergistics2:quartz_pillar@1"
            ]
        },
        {
            "x": 6,
            "y": 7,
            "z": -1,
            "elements": [
                "botania:quartzslabsunnyhalf@0"
            ]
        },
        {
            "x": -6,
            "y": -2,
            "z": 3,
            "elements": [
                "botania:quartztypesunny@2"
            ]
        },
        {
            "x": 5,
            "y": 1,
            "z": -3,
            "elements": [
                "extrautils2:decorativeglass@0"
            ]
        },
        {
            "x": -1,
            "y": 6,
            "z": 5,
            "elements": [
                "minecraft:glowstone@0"
            ]
        },
        {
            "x": -3,
            "y": 9,
            "z": -1,
            "elements": [
                "botania:quartzstairssunny@0"
            ]
        },
        {
            "x": -1,
            "y": -2,
            "z": -4,
            "elements": [
                "modularmachinery:blockcasing@1"
            ]
        },
        {
            "x": -3,
            "y": 8,
            "z": -1,
            "elements": [
                "botania:quartztypesunny@1"
            ]
        },
        {
            "x": 2,
            "y": 7,
            "z": -5,
            "elements": [
                "botania:quartzstairssunny@1"
            ]
        },
        {
            "x": 0,
            "y": 10,
            "z": -1,
            "elements": [
                "botania:quartzslabsunnyhalf@0"
            ]
        },
        {
            "x": 6,
            "y": 6,
            "z": -1,
            "elements": [
                "calculator:flawlessglass@0"
            ]
        },
        {
            "x": -1,
            "y": 10,
            "z": 0,
            "elements": [
                "botania:quartzslabsunnyhalf@0"
            ]
        },
        {
            "x": 4,
            "y": 3,
            "z": -5,
            "elements": [
                "calculator:flawlessglass@0"
            ]
        },
        {
            "x": 3,
            "y": 6,
            "z": 6,
            "elements": [
                "botania:quartztypesunny@2"
            ]
        },
        {
            "x": -6,
            "y": 3,
            "z": -3,
            "elements": [
                "botania:quartztypesunny@2"
            ]
        },
        {
            "x": -5,
            "y": 5,
            "z": -5,
            "elements": [
                "botania:quartztypesunny@2"
            ]
        },
        {
            "x": 5,
            "y": 3,
            "z": -3,
            "elements": [
                "appliedenergistics2:fluix_slab@0"
            ]
        },
        {
            "x": 0,
            "y": 9,
            "z": -1,
            "elements": [
                "extendedcrafting:storage@2"
            ]
        },
        {
            "x": 5,
            "y": 0,
            "z": 0,
            "elements": [
                "extrautils2:decorativeglass@0"
            ]
        },
        {
            "x": 0,
            "y": 6,
            "z": 5,
            "elements": [
                "minecraft:glowstone@0"
            ]
        },
        {
            "x": 3,
            "y": 7,
            "z": -1,
            "elements": [
                "ic2:uu_matter@0"
            ]
        },
        {
            "x": -3,
            "y": -2,
            "z": 0,
            "elements": [
                "ic2:uu_matter@0"
            ]
        },
        {
            "x": 3,
            "y": 6,
            "z": -1,
            "elements": [
                "botania:quartzslabsunnyhalf@8"
            ]
        },
        {
            "x": -4,
            "y": -2,
            "z": -4,
            "elements": [
                "appliedenergistics2:sky_stone_small_brick@0"
            ]
        },
        {
            "x": 2,
            "y": 2,
            "z": 5,
            "elements": [
                "appliedenergistics2:quartz_pillar@1"
            ]
        },
        {
            "x": 6,
            "y": 4,
            "z": -1,
            "elements": [
                "calculator:flawlessglass@0"
            ]
        },
        {
            "x": 2,
            "y": 0,
            "z": 5,
            "elements": [
                "appliedenergistics2:quartz_pillar@1"
            ]
        },
        {
            "x": -3,
            "y": -1,
            "z": -5,
            "elements": [
                "extrautils2:decorativeglass@0"
            ]
        },
        {
            "x": 4,
            "y": 5,
            "z": -5,
            "elements": [
                "calculator:flawlessglass@0"
            ]
        },
        {
            "x": 1,
            "y": 7,
            "z": -5,
            "elements": [
                "botania:quartzstairssunny@2"
            ]
        },
        {
            "x": 5,
            "y": -2,
            "z": 3,
            "elements": [
                "appliedenergistics2:sky_stone_small_brick@0"
            ]
        },
        {
            "x": -6,
            "y": 1,
            "z": -3,
            "elements": [
                "botania:quartztypesunny@2"
            ]
        },
        {
            "x": -4,
            "y": -1,
            "z": 4,
            "elements": [
                "extrautils2:decorativeglass@0"
            ]
        },
        {
            "x": 0,
            "y": 8,
            "z": -1,
            "elements": [
                "ic2:uu_matter@0"
            ]
        },
        {
            "x": 6,
            "y": 5,
            "z": -1,
            "elements": [
                "calculator:flawlessglass@0"
            ]
        },
        {
            "x": -5,
            "y": -2,
            "z": 5,
            "elements": [
                "botania:quartztypesunny@2"
            ]
        },
        {
            "x": -5,
            "y": 3,
            "z": -5,
            "elements": [
                "botania:quartztypesunny@2"
            ]
        },
        {
            "x": 6,
            "y": 2,
            "z": 3,
            "elements": [
                "botania:quartztypesunny@2"
            ]
        },
        {
            "x": -6,
            "y": -2,
            "z": 0,
            "elements": [
                "appliedenergistics2:sky_stone_small_brick@0"
            ]
        },
        {
            "x": 5,
            "y": 2,
            "z": 0,
            "elements": [
                "appliedenergistics2:chiseled_quartz_block@0"
            ]
        },
        {
            "x": -1,
            "y": 0,
            "z": 5,
            "elements": [
                "extrautils2:decorativeglass@0"
            ]
        },
        {
            "x": 0,
            "y": 6,
            "z": -1,
            "elements": [
                "botania:quartzslabsunnyhalf@8"
            ]
        },
        {
            "x": -6,
            "y": 2,
            "z": 1,
            "elements": [
                "botania:quartztypesunny@2"
            ]
        },
        {
            "x": -1,
            "y": 6,
            "z": 0,
            "elements": [
                "botania:quartzslabsunnyhalf@8"
            ]
        },
        {
            "x": -1,
            "y": 2,
            "z": 5,
            "elements": [
                "appliedenergistics2:chiseled_quartz_block@0"
            ]
        },
        {
            "x": 6,
            "y": 0,
            "z": 3,
            "elements": [
                "botania:quartztypesunny@2"
            ]
        },
        {
            "x": 5,
            "y": 7,
            "z": -3,
            "elements": [
                "botania:quartzslabsunnyhalf@0"
            ]
        },
        {
            "x": -3,
            "y": 7,
            "z": 4,
            "elements": [
                "botania:quartzstairssunny@3"
            ]
        },
        {
            "x": -6,
            "y": 4,
            "z": -1,
            "elements": [
                "calculator:flawlessglass@0"
            ]
        },
        {
            "x": -4,
            "y": -2,
            "z": 1,
            "elements": [
                "modularmachinery:blockcasing@1"
            ]
        },
        {
            "x": 0,
            "y": 7,
            "z": -1,
            "elements": [
                "ic2:uu_matter@0"
            ]
        },
        {
            "x": 2,
            "y": 8,
            "z": 0,
            "elements": [
                "ic2:uu_matter@0"
            ]
        },
        {
            "x": -5,
            "y": 0,
            "z": 0,
            "elements": [
                "extrautils2:decorativeglass@0"
            ]
        },
        {
            "x": -6,
            "y": 3,
            "z": 1,
            "elements": [
                "calculator:flawlessglass@0"
            ]
        },
        {
            "x": -2,
            "y": -2,
            "z": 5,
            "elements": [
                "appliedenergistics2:sky_stone_small_brick@0"
            ]
        },
        {
            "x": 3,
            "y": 2,
            "z": 6,
            "elements": [
                "botania:quartztypesunny@2"
            ]
        },
        {
            "x": -2,
            "y": 3,
            "z": -5,
            "elements": [
                "appliedenergistics2:quartz_pillar@1"
            ]
        },
        {
            "x": 3,
            "y": 6,
            "z": 3,
            "elements": [
                "botania:quartzslabsunnyhalf@8"
            ]
        },
        {
            "x": 5,
            "y": -1,
            "z": -1,
            "elements": [
                "extrautils2:decorativeglass@0"
            ]
        },
        {
            "x": 3,
            "y": -1,
            "z": -5,
            "elements": [
                "extrautils2:decorativeglass@0"
            ]
        },
        {
            "x": 0,
            "y": 7,
            "z": 6,
            "elements": [
                "botania:quartzslabsunnyhalf@0"
            ]
        },
        {
            "x": 3,
            "y": 5,
            "z": 6,
            "elements": [
                "botania:quartztypesunny@2"
            ]
        },
        {
            "x": 2,
            "y": -2,
            "z": 7,
            "elements": [
                "appliedenergistics2:sky_stone_small_brick_stairs@1"
            ]
        },
        {
            "x": -4,
            "y": 2,
            "z": 5,
            "elements": [
                "botania:quartztypesunny@2"
            ]
        },
        {
            "x": 5,
            "y": -2,
            "z": -4,
            "elements": [
                "appliedenergistics2:sky_stone_small_brick_stairs@2"
            ]
        },
        {
            "x": 5,
            "y": -2,
            "z": -1,
            "elements": [
                "modularmachinery:blockcasing@4"
            ]
        },
        {
            "x": 2,
            "y": 6,
            "z": 0,
            "elements": [
                "botania:quartzslabsunnyhalf@8"
            ]
        },
        {
            "x": 3,
            "y": 3,
            "z": 6,
            "elements": [
                "botania:quartztypesunny@2"
            ]
        },
        {
            "x": -1,
            "y": 8,
            "z": 0,
            "elements": [
                "ic2:uu_matter@0"
            ]
        },
        {
            "x": -5,
            "y": 7,
            "z": -5,
            "elements": [
                "botania:quartztypesunny@2"
            ]
        },
        {
            "x": -2,
            "y": 5,
            "z": -5,
            "elements": [
                "appliedenergistics2:quartz_pillar@1"
            ]
        },
        {
            "x": 3,
            "y": 4,
            "z": 6,
            "elements": [
                "botania:quartztypesunny@2"
            ]
        },
        {
            "x": 1,
            "y": 3,
            "z": -5,
            "elements": [
                "appliedenergistics2:fluix_slab@0"
            ]
        },
        {
            "x": 0,
            "y": 6,
            "z": 6,
            "elements": [
                "calculator:flawlessglass@0"
            ]
        },
        {
            "x": 3,
            "y": 6,
            "z": 5,
            "elements": [
                "minecraft:glowstone@0"
            ]
        },
        {
            "x": 0,
            "y": 8,
            "z": -4,
            "elements": [
                "botania:quartzstairssunny@2"
            ]
        },
        {
            "x": 6,
            "y": 3,
            "z": -3,
            "elements": [
                "botania:quartztypesunny@2"
            ]
        },
        {
            "x": -2,
            "y": 6,
            "z": 3,
            "elements": [
                "botania:quartzslabsunnyhalf@8"
            ]
        },
        {
            "x": 5,
            "y": 2,
            "z": 5,
            "elements": [
                "botania:quartztypesunny@2"
            ]
        },
        {
            "x": 5,
            "y": -2,
            "z": 5,
            "elements": [
                "botania:quartztypesunny@2"
            ]
        },
        {
            "x": 0,
            "y": 7,
            "z": -3,
            "elements": [
                "ic2:uu_matter@0"
            ]
        },
        {
            "x": -4,
            "y": 1,
            "z": 4,
            "elements": [
                "extrautils2:decorativeglass@0"
            ]
        },
        {
            "x": 5,
            "y": 0,
            "z": 5,
            "elements": [
                "botania:quartztypesunny@2"
            ]
        },
        {
            "x": 3,
            "y": -2,
            "z": -4,
            "elements": [
                "ic2:uu_matter@0"
            ]
        },
        {
            "x": -5,
            "y": -1,
            "z": -3,
            "elements": [
                "extrautils2:decorativeglass@0"
            ]
        },
        {
            "x": 6,
            "y": -2,
            "z": 3,
            "elements": [
                "botania:quartztypesunny@2"
            ]
        },
        {
            "x": -5,
            "y": 7,
            "z": 4,
            "elements": [
                "botania:quartzslabsunnyhalf@0"
            ]
        },
        {
            "x": 4,
            "y": 0,
            "z": -4,
            "elements": [
                "extrautils2:decorativeglass@0"
            ]
        },
        {
            "x": 0,
            "y": 9,
            "z": -3,
            "elements": [
                "botania:quartzstairssunny@2"
            ]
        },
        {
            "x": 3,
            "y": 7,
            "z": -3,
            "elements": [
                "botania:quartzstairssunny@1"
            ]
        },
        {
            "x": 4,
            "y": 8,
            "z": 0,
            "elements": [
                "botania:quartzstairssunny@1"
            ]
        },
        {
            "x": -5,
            "y": 6,
            "z": -4,
            "elements": [
                "calculator:flawlessglass@0"
            ]
        },
        {
            "x": 7,
            "y": -2,
            "z": 0,
            "elements": [
                "appliedenergistics2:sky_stone_small_brick_stairs@1"
            ]
        },
        {
            "x": 6,
            "y": 1,
            "z": -3,
            "elements": [
                "botania:quartztypesunny@2"
            ]
        },
        {
            "x": 1,
            "y": 6,
            "z": 3,
            "elements": [
                "botania:quartzslabsunnyhalf@8"
            ]
        },
        {
            "x": 0,
            "y": 6,
            "z": -4,
            "elements": [
                "botania:quartzslabsunnyhalf@8"
            ]
        },
        {
            "x": 4,
            "y": -2,
            "z": 5,
            "elements": [
                "appliedenergistics2:sky_stone_small_brick_stairs@1"
            ]
        },
        {
            "x": -5,
            "y": 1,
            "z": -5,
            "elements": [
                "botania:quartztypesunny@2"
            ]
        },
        {
            "x": 0,
            "y": -2,
            "z": -4,
            "elements": [
                "ic2:uu_matter@0"
            ]
        },
        {
            "x": 4,
            "y": 6,
            "z": 0,
            "elements": [
                "botania:quartzslabsunnyhalf@8"
            ]
        },
        {
            "x": -6,
            "y": 7,
            "z": -3,
            "elements": [
                "botania:quartztypesunny@2"
            ]
        },
        {
            "x": 2,
            "y": 4,
            "z": 5,
            "elements": [
                "appliedenergistics2:quartz_pillar@1"
            ]
        },
        {
            "x": 3,
            "y": 2,
            "z": 5,
            "elements": [
                "appliedenergistics2:chiseled_quartz_block@0"
            ]
        },
        {
            "x": 1,
            "y": -2,
            "z": -4,
            "elements": [
                "modularmachinery:blockcasing@1"
            ]
        },
        {
            "x": -5,
            "y": 3,
            "z": 4,
            "elements": [
                "calculator:flawlessglass@0"
            ]
        },
        {
            "x": 3,
            "y": 0,
            "z": 5,
            "elements": [
                "extrautils2:decorativeglass@0"
            ]
        },
        {
            "x": -5,
            "y": 2,
            "z": 3,
            "elements": [
                "appliedenergistics2:chiseled_quartz_block@0"
            ]
        },
        {
            "x": -3,
            "y": 6,
            "z": -4,
            "elements": [
                "minecraft:glowstone@0"
            ]
        },
        {
            "x": -4,
            "y": -2,
            "z": 3,
            "elements": [
                "ic2:uu_matter@0"
            ]
        },
        {
            "x": 2,
            "y": 6,
            "z": 5,
            "elements": [
                "extendedcrafting:storage@1"
            ]
        },
        {
            "x": 5,
            "y": -1,
            "z": -3,
            "elements": [
                "extrautils2:decorativeglass@0"
            ]
        },
        {
            "x": -6,
            "y": 0,
            "z": 3,
            "elements": [
                "botania:quartztypesunny@2"
            ]
        },
        {
            "x": -5,
            "y": 5,
            "z": 4,
            "elements": [
                "calculator:flawlessglass@0"
            ]
        },
        {
            "x": -2,
            "y": 8,
            "z": 3,
            "elements": [
                "botania:quartzstairssunny@3"
            ]
        },
        {
            "x": 2,
            "y": -2,
            "z": 5,
            "elements": [
                "appliedenergistics2:sky_stone_small_brick@0"
            ]
        },
        {
            "x": -6,
            "y": 5,
            "z": -3,
            "elements": [
                "botania:quartztypesunny@2"
            ]
        },
        {
            "x": -3,
            "y": 1,
            "z": -5,
            "elements": [
                "extrautils2:decorativeglass@0"
            ]
        },
        {
            "x": 5,
            "y": 4,
            "z": 5,
            "elements": [
                "botania:quartztypesunny@2"
            ]
        },
        {
            "x": -5,
            "y": -2,
            "z": 0,
            "elements": [
                "ic2:uu_matter@0"
            ]
        },
        {
            "x": 2,
            "y": -2,
            "z": -4,
            "elements": [
                "modularmachinery:blockcasing@4"
            ]
        },
        {
            "x": -4,
            "y": 3,
            "z": 4,
            "elements": [
                "appliedenergistics2:fluix_slab@0"
            ]
        },
        {
            "x": -6,
            "y": 2,
            "z": 3,
            "elements": [
                "botania:quartztypesunny@2"
            ]
        },
        {
            "x": -5,
            "y": 0,
            "z": 3,
            "elements": [
                "extrautils2:decorativeglass@0"
            ]
        },
        {
            "x": -2,
            "y": 6,
            "z": -4,
            "elements": [
                "botania:quartzslabsunnyhalf@8"
            ]
        },
        {
            "x": 5,
            "y": 6,
            "z": 5,
            "elements": [
                "botania:quartztypesunny@2"
            ]
        },
        {
            "x": 3,
            "y": -2,
            "z": 3,
            "elements": [
                "modularmachinery:blockcasing@4"
            ]
        },
        {
            "x": 6,
            "y": -2,
            "z": 0,
            "elements": [
                "appliedenergistics2:sky_stone_small_brick@0"
            ]
        },
        {
            "x": -3,
            "y": 3,
            "z": -5,
            "elements": [
                "appliedenergistics2:fluix_slab@0"
            ]
        },
        {
            "x": -1,
            "y": 6,
            "z": -4,
            "elements": [
                "botania:quartzslabsunnyhalf@8"
            ]
        },
        {
            "x": -6,
            "y": 6,
            "z": 3,
            "elements": [
                "botania:quartztypesunny@2"
            ]
        },
        {
            "x": -4,
            "y": 7,
            "z": -3,
            "elements": [
                "botania:quartzstairssunny@2"
            ]
        },
        {
            "x": 1,
            "y": 6,
            "z": 0,
            "elements": [
                "botania:quartzslabsunnyhalf@8"
            ]
        },
        {
            "x": -1,
            "y": 7,
            "z": 4,
            "elements": [
                "botania:quartztypesunny@1"
            ]
        },
        {
            "x": -6,
            "y": 4,
            "z": 3,
            "elements": [
                "botania:quartztypesunny@2"
            ]
        },
        {
            "x": 5,
            "y": 2,
            "z": -4,
            "elements": [
                "botania:quartztypesunny@2"
            ]
        },
        {
            "x": 6,
            "y": 6,
            "z": 1,
            "elements": [
                "calculator:flawlessglass@0"
            ]
        },
        {
            "x": 2,
            "y": -2,
            "z": 3,
            "elements": [
                "modularmachinery:blockcasing@1"
            ]
        },
        {
            "x": -1,
            "y": 8,
            "z": -4,
            "elements": [
                "botania:quartzstairssunny@2"
            ]
        },
        {
            "x": 5,
            "y": 4,
            "z": -4,
            "elements": [
                "calculator:flawlessglass@0"
            ]
        },
        {
            "x": 3,
            "y": 8,
            "z": 1,
            "elements": [
                "botania:quartztypesunny@1"
            ]
        },
        {
            "x": 3,
            "y": 8,
            "z": -2,
            "elements": [
                "botania:quartzstairssunny@1"
            ]
        },
        {
            "x": 5,
            "y": -1,
            "z": -5,
            "elements": [
                "botania:quartztypesunny@2"
            ]
        },
        {
            "x": 6,
            "y": 5,
            "z": 1,
            "elements": [
                "calculator:flawlessglass@0"
            ]
        },
        {
            "x": -3,
            "y": 6,
            "z": 3,
            "elements": [
                "botania:quartzslabsunnyhalf@8"
            ]
        },
        {
            "x": -1,
            "y": 7,
            "z": -3,
            "elements": [
                "ic2:uu_matter@0"
            ]
        },
        {
            "x": 4,
            "y": -2,
            "z": -4,
            "elements": [
                "appliedenergistics2:sky_stone_small_brick@0"
            ]
        },
        {
            "x": 6,
            "y": 3,
            "z": -2,
            "elements": [
                "calculator:flawlessglass@0"
            ]
        },
        {
            "x": -4,
            "y": 7,
            "z": 4,
            "elements": [
                "botania:quartzslabsunnyhalf@0"
            ]
        },
        {
            "x": 1,
            "y": 8,
            "z": 0,
            "elements": [
                "ic2:uu_matter@0"
            ]
        },
        {
            "x": 6,
            "y": 7,
            "z": 1,
            "elements": [
                "botania:quartzslabsunnyhalf@0"
            ]
        },
        {
            "x": 3,
            "y": 9,
            "z": 1,
            "elements": [
                "botania:quartzstairssunny@1"
            ]
        },
        {
            "x": -2,
            "y": 10,
            "z": 0,
            "elements": [
                "botania:quartzslabsunnyhalf@0"
            ]
        },
        {
            "x": -3,
            "y": -2,
            "z": 3,
            "elements": [
                "modularmachinery:blockcasing@4"
            ]
        },
        {
            "x": 6,
            "y": 4,
            "z": 1,
            "elements": [
                "calculator:flawlessglass@0"
            ]
        },
        {
            "x": 3,
            "y": 3,
            "z": -5,
            "elements": [
                "appliedenergistics2:fluix_slab@0"
            ]
        },
        {
            "x": 6,
            "y": 4,
            "z": -2,
            "elements": [
                "calculator:flawlessglass@0"
            ]
        },
        {
            "x": 0,
            "y": 9,
            "z": -2,
            "elements": [
                "botania:quartztypesunny@1"
            ]
        },
        {
            "x": 3,
            "y": 6,
            "z": -2,
            "elements": [
                "botania:quartzslabsunnyhalf@8"
            ]
        },
        {
            "x": -4,
            "y": 6,
            "z": 3,
            "elements": [
                "botania:quartzslabsunnyhalf@8"
            ]
        },
        {
            "x": 0,
            "y": 8,
            "z": -2,
            "elements": [
                "ic2:uu_matter@0"
            ]
        },
        {
            "x": -3,
            "y": -2,
            "z": -4,
            "elements": [
                "ic2:uu_matter@0"
            ]
        },
        {
            "x": -2,
            "y": 7,
            "z": -3,
            "elements": [
                "botania:quartztypesunny@1"
            ]
        },
        {
            "x": -5,
            "y": 2,
            "z": -4,
            "elements": [
                "botania:quartztypesunny@2"
            ]
        },
        {
            "x": 0,
            "y": 10,
            "z": -2,
            "elements": [
                "botania:quartzslabsunnyhalf@0"
            ]
        },
        {
            "x": 0,
            "y": 7,
            "z": -5,
            "elements": [
                "botania:quartzstairssunny@2"
            ]
        },
        {
            "x": 6,
            "y": 5,
            "z": -2,
            "elements": [
                "calculator:flawlessglass@0"
            ]
        },
        {
            "x": 3,
            "y": 7,
            "z": -2,
            "elements": [
                "botania:quartztypesunny@1"
            ]
        },
        {
            "x": 6,
            "y": 2,
            "z": -2,
            "elements": [
                "botania:quartztypesunny@2"
            ]
        },
        {
            "x": 1,
            "y": 10,
            "z": 0,
            "elements": [
                "botania:quartzslabsunnyhalf@0"
            ]
        },
        {
            "x": 0,
            "y": -2,
            "z": 3,
            "elements": [
                "ic2:uu_matter@0"
            ]
        },
        {
            "x": 2,
            "y": 6,
            "z": -4,
            "elements": [
                "botania:quartzslabsunnyhalf@8"
            ]
        },
        {
            "x": -2,
            "y": -2,
            "z": -4,
            "elements": [
                "modularmachinery:blockcasing@4"
            ]
        },
        {
            "x": -7,
            "y": -2,
            "z": 2,
            "elements": [
                "appliedenergistics2:sky_stone_small_brick_stairs@0"
            ]
        },
        {
            "x": 6,
            "y": 6,
            "z": -2,
            "elements": [
                "calculator:flawlessglass@0"
            ]
        },
        {
            "x": -5,
            "y": 6,
            "z": 3,
            "elements": [
                "minecraft:glowstone@0"
            ]
        },
        {
            "x": -3,
            "y": 7,
            "z": -3,
            "elements": [
                "botania:quartzstairssunny@0"
            ]
        },
        {
            "x": 3,
            "y": 7,
            "z": -5,
            "elements": [
                "botania:quartzslabsunnyhalf@0"
            ]
        },
        {
            "x": -4,
            "y": 2,
            "z": -4,
            "elements": [
                "appliedenergistics2:chiseled_quartz_block@0"
            ]
        },
        {
            "x": -5,
            "y": 4,
            "z": -4,
            "elements": [
                "calculator:flawlessglass@0"
            ]
        },
        {
            "x": -1,
            "y": -2,
            "z": 3,
            "elements": [
                "modularmachinery:blockcasing@5"
            ]
        },
        {
            "x": 6,
            "y": 7,
            "z": -2,
            "elements": [
                "botania:quartzslabsunnyhalf@0"
            ]
        },
        {
            "x": 2,
            "y": 2,
            "z": 6,
            "elements": [
                "botania:quartztypesunny@2"
            ]
        },
        {
            "x": -5,
            "y": -2,
            "z": -4,
            "elements": [
                "appliedenergistics2:sky_stone_small_brick_stairs@0"
            ]
        },
        {
            "x": 4,
            "y": 8,
            "z": 1,
            "elements": [
                "botania:quartzstairssunny@1"
            ]
        },
        {
            "x": 1,
            "y": 6,
            "z": -2,
            "elements": [
                "botania:quartzslabsunnyhalf@8"
            ]
        },
        {
            "x": 1,
            "y": 9,
            "z": -1,
            "elements": [
                "extendedcrafting:storage@2"
            ]
        },
        {
            "x": 4,
            "y": 1,
            "z": 4,
            "elements": [
                "extrautils2:decorativeglass@0"
            ]
        },
        {
            "x": -2,
            "y": 8,
            "z": -2,
            "elements": [
                "botania:quartztypesunny@1"
            ]
        },
        {
            "x": 2,
            "y": 7,
            "z": -1,
            "elements": [
                "ic2:uu_matter@0"
            ]
        },
        {
            "x": 5,
            "y": -2,
            "z": -2,
            "elements": [
                "appliedenergistics2:sky_stone_small_brick@0"
            ]
        },
        {
            "x": 4,
            "y": 2,
            "z": 4,
            "elements": [
                "appliedenergistics2:chiseled_quartz_block@0"
            ]
        },
        {
            "x": -1,
            "y": 6,
            "z": 6,
            "elements": [
                "calculator:flawlessglass@0"
            ]
        },
        {
            "x": -6,
            "y": -2,
            "z": 1,
            "elements": [
                "appliedenergistics2:sky_stone_small_brick@0"
            ]
        },
        {
            "x": 5,
            "y": 1,
            "z": -1,
            "elements": [
                "extrautils2:decorativeglass@0"
            ]
        },
        {
            "x": -6,
            "y": 6,
            "z": -2,
            "elements": [
                "calculator:flawlessglass@0"
            ]
        },
        {
            "x": 0,
            "y": 7,
            "z": 2,
            "elements": [
                "ic2:uu_matter@0"
            ]
        },
        {
            "x": 0,
            "y": 6,
            "z": -2,
            "elements": [
                "botania:quartzslabsunnyhalf@8"
            ]
        },
        {
            "x": -4,
            "y": -2,
            "z": -2,
            "elements": [
                "modularmachinery:blockcasing@4"
            ]
        },
        {
            "x": -4,
            "y": 0,
            "z": -4,
            "elements": [
                "extrautils2:decorativeglass@0"
            ]
        },
        {
            "x": 1,
            "y": 6,
            "z": 4,
            "elements": [
                "botania:quartzslabsunnyhalf@8"
            ]
        },
        {
            "x": -6,
            "y": 3,
            "z": 2,
            "elements": [
                "calculator:flawlessglass@0"
            ]
        },
        {
            "x": -2,
            "y": 9,
            "z": 2,
            "elements": [
                "botania:quartzslabsunnyfull@0"
            ]
        },
        {
            "x": -6,
            "y": 4,
            "z": -2,
            "elements": [
                "calculator:flawlessglass@0"
            ]
        },
        {
            "x": -5,
            "y": -1,
            "z": 2,
            "elements": [
                "appliedenergistics2:quartz_pillar@1"
            ]
        },
        {
            "x": 2,
            "y": 6,
            "z": 6,
            "elements": [
                "calculator:flawlessglass@0"
            ]
        },
        {
            "x": 5,
            "y": 3,
            "z": -1,
            "elements": [
                "appliedenergistics2:fluix_slab@0"
            ]
        },
        {
            "x": 4,
            "y": 0,
            "z": 4,
            "elements": [
                "extrautils2:decorativeglass@0"
            ]
        },
        {
            "x": -6,
            "y": 5,
            "z": 2,
            "elements": [
                "calculator:flawlessglass@0"
            ]
        },
        {
            "x": 0,
            "y": -2,
            "z": -7,
            "elements": [
                "appliedenergistics2:sky_stone_small_brick_stairs@2"
            ]
        },
        {
            "x": 4,
            "y": 7,
            "z": -1,
            "elements": [
                "botania:quartztypesunny@1"
            ]
        },
        {
            "x": 1,
            "y": 10,
            "z": 1,
            "elements": [
                "botania:quartzslabsunnyhalf@0"
            ]
        },
        {
            "x": -1,
            "y": 4,
            "z": 6,
            "elements": [
                "calculator:flawlessglass@0"
            ]
        },
        {
            "x": 1,
            "y": 8,
            "z": 4,
            "elements": [
                "botania:quartzstairssunny@3"
            ]
        },
        {
            "x": 4,
            "y": 6,
            "z": 4,
            "elements": [
                "minecraft:glowstone@0"
            ]
        },
        {
            "x": -1,
            "y": -2,
            "z": -2,
            "elements": [
                "modularmachinery:blockcasing@5"
            ]
        },
        {
            "x": -6,
            "y": 2,
            "z": -2,
            "elements": [
                "botania:quartztypesunny@2"
            ]
        },
        {
            "x": 1,
            "y": 7,
            "z": 4,
            "elements": [
                "botania:quartztypesunny@1"
            ]
        },
        {
            "x": 1,
            "y": -2,
            "z": 6,
            "elements": [
                "appliedenergistics2:sky_stone_small_brick@0"
            ]
        },
        {
            "x": 4,
            "y": 6,
            "z": 1,
            "elements": [
                "botania:quartzslabsunnyhalf@8"
            ]
        },
        {
            "x": 5,
            "y": 7,
            "z": -1,
            "elements": [
                "botania:quartzstairssunny@1"
            ]
        },
        {
            "x": 2,
            "y": 9,
            "z": -1,
            "elements": [
                "botania:quartztypesunny@1"
            ]
        },
        {
            "x": 1,
            "y": 8,
            "z": 1,
            "elements": [
                "ic2:uu_matter@0"
            ]
        },
        {
            "x": -6,
            "y": 7,
            "z": 2,
            "elements": [
                "botania:quartzslabsunnyhalf@0"
            ]
        },
        {
            "x": 4,
            "y": 3,
            "z": 4,
            "elements": [
                "appliedenergistics2:fluix_slab@0"
            ]
        },
        {
            "x": 5,
            "y": -1,
            "z": 2,
            "elements": [
                "appliedenergistics2:quartz_pillar@1"
            ]
        },
        {
            "x": 1,
            "y": 8,
            "z": -2,
            "elements": [
                "ic2:uu_matter@0"
            ]
        },
        {
            "x": -1,
            "y": 2,
            "z": 6,
            "elements": [
                "botania:quartztypesunny@2"
            ]
        },
        {
            "x": 2,
            "y": -2,
            "z": -2,
            "elements": [
                "modularmachinery:blockcasing@5"
            ]
        },
        {
            "x": -3,
            "y": -1,
            "z": -6,
            "elements": [
                "botania:quartztypesunny@2"
            ]
        },
        {
            "x": 1,
            "y": 10,
            "z": -2,
            "elements": [
                "botania:quartzslabsunnyhalf@0"
            ]
        },
        {
            "x": -3,
            "y": 7,
            "z": 2,
            "elements": [
                "botania:quartztypesunny@1"
            ]
        },
        {
            "x": 6,
            "y": -2,
            "z": 4,
            "elements": [
                "appliedenergistics2:sky_stone_small_brick_stairs@3"
            ]
        },
        {
            "x": 1,
            "y": -2,
            "z": -2,
            "elements": [
                "modularmachinery:blockcasing@5"
            ]
        },
        {
            "x": -2,
            "y": 6,
            "z": 1,
            "elements": [
                "botania:quartzslabsunnyhalf@8"
            ]
        },
        {
            "x": -4,
            "y": 7,
            "z": 2,
            "elements": [
                "botania:quartzstairssunny@0"
            ]
        },
        {
            "x": 0,
            "y": -2,
            "z": -2,
            "elements": [
                "ic2:uu_matter@0"
            ]
        },
        {
            "x": -5,
            "y": -1,
            "z": -1,
            "elements": [
                "extrautils2:decorativeglass@0"
            ]
        },
        {
            "x": 3,
            "y": 7,
            "z": -6,
            "elements": [
                "botania:quartztypesunny@2"
            ]
        },
        {
            "x": 6,
            "y": -2,
            "z": 1,
            "elements": [
                "appliedenergistics2:sky_stone_small_brick@0"
            ]
        },
        {
            "x": 4,
            "y": 7,
            "z": 3,
            "elements": [
                "botania:quartzstairssunny@1"
            ]
        },
        {
            "x": -5,
            "y": 6,
            "z": 1,
            "elements": [
                "minecraft:glowstone@0"
            ]
        },
        {
            "x": -5,
            "y": 7,
            "z": 2,
            "elements": [
                "botania:quartzstairssunny@3"
            ]
        },
        {
            "x": 4,
            "y": 7,
            "z": 4,
            "elements": [
                "botania:quartzslabsunnyhalf@0"
            ]
        },
        {
            "x": -3,
            "y": 6,
            "z": -2,
            "elements": [
                "botania:quartzslabsunnyhalf@8"
            ]
        },
        {
            "x": 4,
            "y": 6,
            "z": 3,
            "elements": [
                "botania:quartzslabsunnyhalf@8"
            ]
        },
        {
            "x": 3,
            "y": -2,
            "z": 1,
            "elements": [
                "modularmachinery:blockcasing@5"
            ]
        },
        {
            "x": -5,
            "y": 0,
            "z": 1,
            "elements": [
                "extrautils2:decorativeglass@0"
            ]
        },
        {
            "x": 1,
            "y": 7,
            "z": 3,
            "elements": [
                "ic2:uu_matter@0"
            ]
        },
        {
            "x": 3,
            "y": -2,
            "z": -2,
            "elements": [
                "modularmachinery:blockcasing@1"
            ]
        },
        {
            "x": -2,
            "y": 7,
            "z": 2,
            "elements": [
                "ic2:uu_matter@0"
            ]
        },
        {
            "x": 2,
            "y": 4,
            "z": 6,
            "elements": [
                "calculator:flawlessglass@0"
            ]
        },
        {
            "x": -5,
            "y": 4,
            "z": -2,
            "elements": [
                "appliedenergistics2:quartz_pillar@1"
            ]
        },
        {
            "x": 1,
            "y": 8,
            "z": 3,
            "elements": [
                "botania:quartztypesunny@1"
            ]
        },
        {
            "x": -2,
            "y": 10,
            "z": 1,
            "elements": [
                "botania:quartzslabsunnyhalf@0"
            ]
        },
        {
            "x": -5,
            "y": 5,
            "z": 2,
            "elements": [
                "appliedenergistics2:quartz_pillar@1"
            ]
        },
        {
            "x": 6,
            "y": -1,
            "z": 3,
            "elements": [
                "botania:quartztypesunny@2"
            ]
        },
        {
            "x": -2,
            "y": 6,
            "z": -2,
            "elements": [
                "botania:quartzslabsunnyhalf@8"
            ]
        },
        {
            "x": -3,
            "y": 8,
            "z": -2,
            "elements": [
                "botania:quartzstairssunny@0"
            ]
        },
        {
            "x": 4,
            "y": -2,
            "z": 6,
            "elements": [
                "appliedenergistics2:sky_stone_small_brick_stairs@3"
            ]
        },
        {
            "x": 6,
            "y": 5,
            "z": -3,
            "elements": [
                "botania:quartztypesunny@2"
            ]
        },
        {
            "x": -2,
            "y": -2,
            "z": -2,
            "elements": [
                "modularmachinery:blockcasing@5"
            ]
        },
        {
            "x": 1,
            "y": 9,
            "z": 3,
            "elements": [
                "botania:quartzstairssunny@3"
            ]
        },
        {
            "x": -5,
            "y": 2,
            "z": 1,
            "elements": [
                "appliedenergistics2:chiseled_quartz_block@0"
            ]
        },
        {
            "x": -2,
            "y": 7,
            "z": 4,
            "elements": [
                "botania:quartzstairssunny@0"
            ]
        },
        {
            "x": 1,
            "y": 6,
            "z": 1,
            "elements": [
                "botania:quartzslabsunnyhalf@8"
            ]
        },
        {
            "x": -2,
            "y": 8,
            "z": 1,
            "elements": [
                "ic2:uu_matter@0"
            ]
        },
        {
            "x": -5,
            "y": 6,
            "z": -2,
            "elements": [
                "extendedcrafting:storage@1"
            ]
        },
        {
            "x": -3,
            "y": 4,
            "z": 6,
            "elements": [
                "botania:quartztypesunny@2"
            ]
        },
        {
            "x": 5,
            "y": 5,
            "z": 0,
            "elements": [
                "modularmachinery:blockupgradebus"
            ]
        },
        {
            "x": 4,
            "y": 4,
            "z": 5,
            "elements": [
                "calculator:flawlessglass@0"
            ]
        },
        {
            "x": 6,
            "y": 6,
            "z": -3,
            "elements": [
                "botania:quartztypesunny@2"
            ]
        },
        {
            "x": -2,
            "y": -2,
            "z": -7,
            "elements": [
                "appliedenergistics2:sky_stone_small_brick_stairs@0"
            ]
        },
        {
            "x": -3,
            "y": -2,
            "z": 1,
            "elements": [
                "modularmachinery:blockcasing@5"
            ]
        },
        {
            "x": -5,
            "y": 3,
            "z": 2,
            "elements": [
                "appliedenergistics2:quartz_pillar@1"
            ]
        },
        {
            "x": 3,
            "y": 0,
            "z": 6,
            "elements": [
                "botania:quartztypesunny@2"
            ]
        },
        {
            "x": 5,
            "y": 6,
            "z": 0,
            "elements": [
                "minecraft:glowstone@0"
            ]
        },
        {
            "x": -1,
            "y": -2,
            "z": 6,
            "elements": [
                "appliedenergistics2:sky_stone_small_brick@0"
            ]
        },
        {
            "x": -6,
            "y": 6,
            "z": 1,
            "elements": [
                "calculator:flawlessglass@0"
            ]
        },
        {
            "x": 4,
            "y": 3,
            "z": 5,
            "elements": [
                "calculator:flawlessglass@0"
            ]
        },
        {
            "x": -6,
            "y": 7,
            "z": -1,
            "elements": [
                "botania:quartzslabsunnyhalf@0"
            ]
        },
        {
            "x": 5,
            "y": 6,
            "z": -5,
            "elements": [
                "botania:quartztypesunny@2"
            ]
        },
        {
            "x": 2,
            "y": -2,
            "z": 1,
            "elements": [
                "modularmachinery:blockcasing@5"
            ]
        },
        {
            "x": 4,
            "y": 6,
            "z": 5,
            "elements": [
                "calculator:flawlessglass@0"
            ]
        },
        {
            "x": -1,
            "y": 8,
            "z": -2,
            "elements": [
                "ic2:uu_matter@0"
            ]
        },
        {
            "x": 2,
            "y": -2,
            "z": 6,
            "elements": [
                "appliedenergistics2:sky_stone_small_brick_stairs@3"
            ]
        },
        {
            "x": -6,
            "y": 4,
            "z": 1,
            "elements": [
                "calculator:flawlessglass@0"
            ]
        },
        {
            "x": 2,
            "y": 9,
            "z": 0,
            "elements": [
                "botania:quartztypesunny@1"
            ]
        },
        {
            "x": 5,
            "y": 7,
            "z": 0,
            "elements": [
                "botania:quartzstairssunny@1"
            ]
        },
        {
            "x": -3,
            "y": 1,
            "z": -6,
            "elements": [
                "botania:quartztypesunny@2"
            ]
        },
        {
            "x": -3,
            "y": 2,
            "z": 6,
            "elements": [
                "botania:quartztypesunny@2"
            ]
        },
        {
            "x": 4,
            "y": 5,
            "z": 5,
            "elements": [
                "calculator:flawlessglass@0"
            ]
        },
        {
            "x": -1,
            "y": 10,
            "z": -2,
            "elements": [
                "botania:quartzslabsunnyhalf@0"
            ]
        },
        {
            "x": 5,
            "y": 7,
            "z": -5,
            "elements": [
                "botania:quartztypesunny@2"
            ]
        },
        {
            "x": 4,
            "y": -2,
            "z": -2,
            "elements": [
                "modularmachinery:blockcasing@4"
            ]
        },
        {
            "x": 1,
            "y": 7,
            "z": 5,
            "elements": [
                "botania:quartzstairssunny@3"
            ]
        },
        {
            "x": -5,
            "y": 1,
            "z": 2,
            "elements": [
                "appliedenergistics2:quartz_pillar@1"
            ]
        },
        {
            "x": -6,
            "y": 5,
            "z": -1,
            "elements": [
                "calculator:flawlessglass@0"
            ]
        },
        {
            "x": 6,
            "y": 7,
            "z": -3,
            "elements": [
                "botania:quartztypesunny@2"
            ]
        },
        {
            "x": -4,
            "y": 8,
            "z": 1,
            "elements": [
                "botania:quartzstairssunny@0"
            ]
        },
        {
            "x": -1,
            "y": 7,
            "z": -1,
            "elements": [
                "ic2:uu_matter@0"
            ]
        },
        {
            "x": -1,
            "y": 6,
            "z": 1,
            "elements": [
                "botania:quartzslabsunnyhalf@8"
            ]
        },
        {
            "x": 2,
            "y": 10,
            "z": 0,
            "elements": [
                "botania:quartzslabsunnyhalf@0"
            ]
        },
        {
            "x": 0,
            "y": 2,
            "z": 6,
            "elements": [
                "botania:quartztypesunny@2"
            ]
        },
        {
            "x": -1,
            "y": 6,
            "z": -2,
            "elements": [
                "botania:quartzslabsunnyhalf@8"
            ]
        },
        {
            "x": -1,
            "y": -2,
            "z": 1,
            "elements": [
                "modularmachinery:blockcasing@5"
            ]
        },
        {
            "x": 5,
            "y": 4,
            "z": -5,
            "elements": [
                "botania:quartztypesunny@2"
            ]
        },
        {
            "x": 3,
            "y": 5,
            "z": -6,
            "elements": [
                "botania:quartztypesunny@2"
            ]
        },
        {
            "x": -4,
            "y": 6,
            "z": 1,
            "elements": [
                "botania:quartzslabsunnyhalf@8"
            ]
        },
        {
            "x": 7,
            "y": -2,
            "z": -2,
            "elements": [
                "appliedenergistics2:sky_stone_small_brick_stairs@2"
            ]
        },
        {
            "x": 5,
            "y": 5,
            "z": -5,
            "elements": [
                "botania:quartztypesunny@2"
            ]
        },
        {
            "x": 5,
            "y": 0,
            "z": -2,
            "elements": [
                "appliedenergistics2:quartz_pillar@1"
            ]
        },
        {
            "x": -3,
            "y": 6,
            "z": 6,
            "elements": [
                "botania:quartztypesunny@2"
            ]
        },
        {
            "x": -4,
            "y": 6,
            "z": -2,
            "elements": [
                "botania:quartzslabsunnyhalf@8"
            ]
        },
        {
            "x": -4,
            "y": 7,
            "z": -1,
            "elements": [
                "botania:quartztypesunny@1"
            ]
        },
        {
            "x": -3,
            "y": 3,
            "z": -6,
            "elements": [
                "botania:quartztypesunny@2"
            ]
        },
        {
            "x": 0,
            "y": 4,
            "z": 6,
            "elements": [
                "calculator:flawlessglass@0"
            ]
        },
        {
            "x": 0,
            "y": -2,
            "z": 1,
            "elements": [
                "ic2:uu_matter@0"
            ]
        },
        {
            "x": 2,
            "y": 6,
            "z": -2,
            "elements": [
                "botania:quartzslabsunnyhalf@8"
            ]
        },
        {
            "x": 1,
            "y": 7,
            "z": -6,
            "elements": [
                "botania:quartzslabsunnyhalf@0"
            ]
        },
        {
            "x": 5,
            "y": 2,
            "z": -5,
            "elements": [
                "botania:quartztypesunny@2"
            ]
        },
        {
            "x": -3,
            "y": 5,
            "z": -6,
            "elements": [
                "botania:quartztypesunny@2"
            ]
        },
        {
            "x": -3,
            "y": 6,
            "z": 1,
            "elements": [
                "botania:quartzslabsunnyhalf@8"
            ]
        },
        {
            "x": 5,
            "y": 3,
            "z": -5,
            "elements": [
                "botania:quartztypesunny@2"
            ]
        },
        {
            "x": 5,
            "y": 2,
            "z": -2,
            "elements": [
                "appliedenergistics2:quartz_pillar@1"
            ]
        },
        {
            "x": -3,
            "y": 7,
            "z": -1,
            "elements": [
                "ic2:uu_matter@0"
            ]
        },
        {
            "x": 2,
            "y": -2,
            "z": -7,
            "elements": [
                "appliedenergistics2:sky_stone_small_brick_stairs@1"
            ]
        },
        {
            "x": 1,
            "y": -2,
            "z": 1,
            "elements": [
                "modularmachinery:blockcasing@5"
            ]
        },
        {
            "x": 1,
            "y": 0,
            "z": 5,
            "elements": [
                "extrautils2:decorativeglass@0"
            ]
        },
        {
            "x": 5,
            "y": 6,
            "z": -2,
            "elements": [
                "extendedcrafting:storage@1"
            ]
        },
        {
            "x": 2,
            "y": 8,
            "z": -2,
            "elements": [
                "botania:quartztypesunny@1"
            ]
        },
        {
            "x": -7,
            "y": -2,
            "z": -2,
            "elements": [
                "appliedenergistics2:sky_stone_small_brick_stairs@2"
            ]
        },
        {
            "x": -2,
            "y": -1,
            "z": -5,
            "elements": [
                "appliedenergistics2:quartz_pillar@1"
            ]
        },
        {
            "x": 0,
            "y": 7,
            "z": -6,
            "elements": [
                "botania:quartzslabsunnyhalf@0"
            ]
        },
        {
            "x": -2,
            "y": 2,
            "z": 6,
            "elements": [
                "botania:quartztypesunny@2"
            ]
        },
        {
            "x": 1,
            "y": 2,
            "z": 5,
            "elements": [
                "appliedenergistics2:chiseled_quartz_block@0"
            ]
        },
        {
            "x": -2,
            "y": 7,
            "z": 5,
            "elements": [
                "botania:quartzstairssunny@0"
            ]
        },
        {
            "x": 3,
            "y": 3,
            "z": -6,
            "elements": [
                "botania:quartztypesunny@2"
            ]
        },
        {
            "x": -2,
            "y": 5,
            "z": -6,
            "elements": [
                "calculator:flawlessglass@0"
            ]
        },
        {
            "x": 1,
            "y": 9,
            "z": 2,
            "elements": [
                "botania:quartztypesunny@1"
            ]
        },
        {
            "x": -4,
            "y": 4,
            "z": -5,
            "elements": [
                "calculator:flawlessglass@0"
            ]
        },
        {
            "x": 4,
            "y": 7,
            "z": 2,
            "elements": [
                "botania:quartzstairssunny@3"
            ]
        },
        {
            "x": -2,
            "y": 7,
            "z": -1,
            "elements": [
                "ic2:uu_matter@0"
            ]
        },
        {
            "x": 1,
            "y": 1,
            "z": 5,
            "elements": [
                "extrautils2:decorativeglass@0"
            ]
        },
        {
            "x": -2,
            "y": -2,
            "z": -5,
            "elements": [
                "appliedenergistics2:sky_stone_small_brick@0"
            ]
        },
        {
            "x": -3,
            "y": 8,
            "z": 1,
            "elements": [
                "botania:quartztypesunny@1"
            ]
        },
        {
            "x": 5,
            "y": 4,
            "z": -2,
            "elements": [
                "appliedenergistics2:quartz_pillar@1"
            ]
        },
        {
            "x": -4,
            "y": 3,
            "z": -5,
            "elements": [
                "calculator:flawlessglass@0"
            ]
        },
        {
            "x": 6,
            "y": 3,
            "z": 2,
            "elements": [
                "calculator:flawlessglass@0"
            ]
        },
        {
            "x": -2,
            "y": 4,
            "z": 6,
            "elements": [
                "calculator:flawlessglass@0"
            ]
        },
        {
            "x": 0,
            "y": -2,
            "z": 5,
            "elements": [
                "ic2:uu_matter@0"
            ]
        },
        {
            "x": 1,
            "y": -2,
            "z": -7,
            "elements": [
                "appliedenergistics2:sky_stone_small_brick_stairs@2"
            ]
        },
        {
            "x": -2,
            "y": -2,
            "z": 1,
            "elements": [
                "modularmachinery:blockcasing@5"
            ]
        },
        {
            "x": 0,
            "y": 10,
            "z": 1,
            "elements": [
                "botania:quartzslabsunnyhalf@0"
            ]
        },
        {
            "x": 4,
            "y": 7,
            "z": 5,
            "elements": [
                "botania:quartzslabsunnyhalf@0"
            ]
        },
        {
            "x": -2,
            "y": -2,
            "z": 6,
            "elements": [
                "appliedenergistics2:sky_stone_small_brick_stairs@3"
            ]
        },
        {
            "x": -4,
            "y": 2,
            "z": -5,
            "elements": [
                "botania:quartztypesunny@2"
            ]
        },
        {
            "x": 3,
            "y": -1,
            "z": -6,
            "elements": [
                "botania:quartztypesunny@2"
            ]
        },
        {
            "x": 0,
            "y": -1,
            "z": 5,
            "elements": [
                "extrautils2:decorativeglass@0"
            ]
        },
        {
            "x": 3,
            "y": 6,
            "z": 1,
            "elements": [
                "botania:quartzslabsunnyhalf@8"
            ]
        },
        {
            "x": -5,
            "y": -2,
            "z": 1,
            "elements": [
                "modularmachinery:blockcasing@4"
            ]
        },
        {
            "x": -4,
            "y": 5,
            "z": -5,
            "elements": [
                "calculator:flawlessglass@0"
            ]
        },
        {
            "x": 0,
            "y": 8,
            "z": 1,
            "elements": [
                "ic2:uu_matter@0"
            ]
        },
        {
            "x": 3,
            "y": 7,
            "z": 2,
            "elements": [
                "botania:quartztypesunny@1"
            ]
        },
        {
            "x": -2,
            "y": 3,
            "z": -6,
            "elements": [
                "calculator:flawlessglass@0"
            ]
        },
        {
            "x": -5,
            "y": 7,
            "z": -1,
            "elements": [
                "botania:quartzstairssunny@0"
            ]
        },
        {
            "x": 1,
            "y": 6,
            "z": 5,
            "elements": [
                "minecraft:glowstone@0"
            ]
        },
        {
            "x": -5,
            "y": 3,
            "z": -1,
            "elements": [
                "appliedenergistics2:fluix_slab@0"
            ]
        },
        {
            "x": -1,
            "y": 9,
            "z": -1,
            "elements": [
                "extendedcrafting:storage@2"
            ]
        },
        {
            "x": -3,
            "y": 0,
            "z": 6,
            "elements": [
                "botania:quartztypesunny@2"
            ]
        },
        {
            "x": -2,
            "y": 4,
            "z": 5,
            "elements": [
                "appliedenergistics2:quartz_pillar@1"
            ]
        },
        {
            "x": -5,
            "y": -2,
            "z": -2,
            "elements": [
                "appliedenergistics2:sky_stone_small_brick@0"
            ]
        },
        {
            "x": 3,
            "y": -2,
            "z": 5,
            "elements": [
                "appliedenergistics2:sky_stone_small_brick@0"
            ]
        },
        {
            "x": -2,
            "y": 7,
            "z": -6,
            "elements": [
                "botania:quartzslabsunnyhalf@0"
            ]
        },
        {
            "x": 6,
            "y": 7,
            "z": 2,
            "elements": [
                "botania:quartzslabsunnyhalf@0"
            ]
        },
        {
            "x": 1,
            "y": 3,
            "z": -6,
            "elements": [
                "calculator:flawlessglass@0"
            ]
        },
        {
            "x": -3,
            "y": -2,
            "z": 6,
            "elements": [
                "botania:quartztypesunny@2"
            ]
        },
        {
            "x": 0,
            "y": 5,
            "z": -6,
            "elements": [
                "calculator:flawlessglass@0"
            ]
        },
        {
            "x": 3,
            "y": -1,
            "z": 5,
            "elements": [
                "extrautils2:decorativeglass@0"
            ]
        },
        {
            "x": -2,
            "y": 3,
            "z": 5,
            "elements": [
                "appliedenergistics2:quartz_pillar@1"
            ]
        },
        {
            "x": 0,
            "y": 6,
            "z": 1,
            "elements": [
                "botania:quartzslabsunnyhalf@8"
            ]
        },
        {
            "x": 4,
            "y": -2,
            "z": 1,
            "elements": [
                "modularmachinery:blockcasing@1"
            ]
        },
        {
            "x": -5,
            "y": 1,
            "z": -1,
            "elements": [
                "extrautils2:decorativeglass@0"
            ]
        },
        {
            "x": -5,
            "y": -2,
            "z": -5,
            "elements": [
                "botania:quartztypesunny@2"
            ]
        },
        {
            "x": -2,
            "y": 6,
            "z": 5,
            "elements": [
                "extendedcrafting:storage@1"
            ]
        },
        {
            "x": -2,
            "y": 9,
            "z": -1,
            "elements": [
                "botania:quartztypesunny@1"
            ]
        },
        {
            "x": -1,
            "y": -2,
            "z": -7,
            "elements": [
                "appliedenergistics2:sky_stone_small_brick_stairs@2"
            ]
        },
        {
            "x": 4,
            "y": 2,
            "z": 5,
            "elements": [
                "botania:quartztypesunny@2"
            ]
        },
        {
            "x": -3,
            "y": 7,
            "z": -6,
            "elements": [
                "botania:quartztypesunny@2"
            ]
        },
        {
            "x": -5,
            "y": -1,
            "z": -5,
            "elements": [
                "botania:quartztypesunny@2"
            ]
        },
        {
            "x": 3,
            "y": 1,
            "z": -6,
            "elements": [
                "botania:quartztypesunny@2"
            ]
        },
        {
            "x": 0,
            "y": 9,
            "z": 2,
            "elements": [
                "botania:quartztypesunny@1"
            ]
        },
        {
            "x": -4,
            "y": -2,
            "z": 6,
            "elements": [
                "appliedenergistics2:sky_stone_small_brick_stairs@0"
            ]
        },
        {
            "x": 0,
            "y": 3,
            "z": -6,
            "elements": [
                "calculator:flawlessglass@0"
            ]
        },
        {
            "x": -5,
            "y": 7,
            "z": 5,
            "elements": [
                "botania:quartztypesunny@2"
            ]
        },
        {
            "x": 1,
            "y": 5,
            "z": -6,
            "elements": [
                "calculator:flawlessglass@0"
            ]
        },
        {
            "x": 1,
            "y": 7,
            "z": -1,
            "elements": [
                "ic2:uu_matter@0"
            ]
        },
        {
            "x": 1,
            "y": 3,
            "z": 5,
            "elements": [
                "appliedenergistics2:fluix_slab@0"
            ]
        },
        {
            "x": -2,
            "y": 5,
            "z": 5,
            "elements": [
                "appliedenergistics2:quartz_pillar@1"
            ]
        },
        {
            "x": 1,
            "y": 7,
            "z": 2,
            "elements": [
                "ic2:uu_matter@0"
            ]
        },
        {
            "x": 6,
            "y": 5,
            "z": 2,
            "elements": [
                "calculator:flawlessglass@0"
            ]
        },
        {
            "x": -1,
            "y": 10,
            "z": 1,
            "elements": [
                "botania:quartzslabsunnyhalf@0"
            ]
        },
        {
            "x": -4,
            "y": 3,
            "z": 5,
            "elements": [
                "calculator:flawlessglass@0"
            ]
        },
        {
            "x": -6,
            "y": -2,
            "z": -1,
            "elements": [
                "appliedenergistics2:sky_stone_small_brick@0"
            ]
        },
        {
            "x": 5,
            "y": 1,
            "z": 1,
            "elements": [
                "extrautils2:decorativeglass@0"
            ]
        },
        {
            "x": 2,
            "y": 4,
            "z": -6,
            "elements": [
                "calculator:flawlessglass@0"
            ]
        },
        {
            "x": -2,
            "y": 6,
            "z": -5,
            "elements": [
                "extendedcrafting:storage@1"
            ]
        },
        {
            "x": 2,
            "y": 7,
            "z": 1,
            "elements": [
                "ic2:uu_matter@0"
            ]
        },
        {
            "x": 5,
            "y": 0,
            "z": 1,
            "elements": [
                "extrautils2:decorativeglass@0"
            ]
        },
        {
            "x": 0,
            "y": 9,
            "z": 3,
            "elements": [
                "botania:quartzstairssunny@3"
            ]
        },
        {
            "x": 3,
            "y": 7,
            "z": 3,
            "elements": [
                "botania:quartzstairssunny@3"
            ]
        },
        {
            "x": -1,
            "y": 2,
            "z": -6,
            "elements": [
                "botania:quartztypesunny@2"
            ]
        },
        {
            "x": 0,
            "y": -1,
            "z": 0,
            "elements": [
                "modularmachinery:blockinputbus",
                "modularmachinery:blockmeiteminputbus",
                "modularmachinery:blockmepatternprovider"
            ]
        },
        {
            "x": 1,
            "y": 2,
            "z": -5,
            "elements": [
                "appliedenergistics2:chiseled_quartz_block@0"
            ]
        },
        {
            "x": 6,
            "y": 5,
            "z": 3,
            "elements": [
                "botania:quartztypesunny@2"
            ]
        },
        {
            "x": 2,
            "y": 5,
            "z": -6,
            "elements": [
                "calculator:flawlessglass@0"
            ]
        },
        {
            "x": 5,
            "y": 7,
            "z": 1,
            "elements": [
                "botania:quartzstairssunny@1"
            ]
        },
        {
            "x": 2,
            "y": 0,
            "z": -5,
            "elements": [
                "appliedenergistics2:quartz_pillar@1"
            ]
        },
        {
            "x": -3,
            "y": -1,
            "z": 5,
            "elements": [
                "extrautils2:decorativeglass@0"
            ]
        },
        {
            "x": -3,
            "y": 1,
            "z": 5,
            "elements": [
                "extrautils2:decorativeglass@0"
            ]
        },
        {
            "x": 2,
            "y": -2,
            "z": -5,
            "elements": [
                "appliedenergistics2:sky_stone_small_brick@0"
            ]
        },
        {
            "x": 4,
            "y": -2,
            "z": -6,
            "elements": [
                "appliedenergistics2:sky_stone_small_brick_stairs@1"
            ]
        },
        {
            "x": -1,
            "y": 3,
            "z": -6,
            "elements": [
                "calculator:flawlessglass@0"
            ]
        },
        {
            "x": -4,
            "y": 7,
            "z": 0,
            "elements": [
                "botania:quartztypesunny@1"
            ]
        },
        {
            "x": -5,
            "y": 5,
            "z": 5,
            "elements": [
                "botania:quartztypesunny@2"
            ]
        },
        {
            "x": 2,
            "y": 6,
            "z": 1,
            "elements": [
                "botania:quartzslabsunnyhalf@8"
            ]
        },
        {
            "x": 5,
            "y": 3,
            "z": 1,
            "elements": [
                "appliedenergistics2:fluix_slab@0"
            ]
        },
        {
            "x": -1,
            "y": 4,
            "z": -6,
            "elements": [
                "calculator:flawlessglass@0"
            ]
        },
        {
            "x": -3,
            "y": 7,
            "z": 0,
            "elements": [
                "ic2:uu_matter@0"
            ]
        },
        {
            "x": -5,
            "y": 3,
            "z": 5,
            "elements": [
                "botania:quartztypesunny@2"
            ]
        },
        {
            "x": -1,
            "y": 7,
            "z": -6,
            "elements": [
                "botania:quartzslabsunnyhalf@0"
            ]
        },
        {
            "x": 2,
            "y": 2,
            "z": -6,
            "elements": [
                "botania:quartztypesunny@2"
            ]
        },
        {
            "x": 0,
            "y": 8,
            "z": 4,
            "elements": [
                "botania:quartzstairssunny@3"
            ]
        },
        {
            "x": 3,
            "y": 7,
            "z": -4,
            "elements": [
                "botania:quartzstairssunny@1"
            ]
        },
        {
            "x": 0,
            "y": 2,
            "z": -5,
            "elements": [
                "appliedenergistics2:chiseled_quartz_block@0"
            ]
        },
        {
            "x": 2,
            "y": 3,
            "z": -6,
            "elements": [
                "calculator:flawlessglass@0"
            ]
        },
        {
            "x": -1,
            "y": 9,
            "z": 1,
            "elements": [
                "extendedcrafting:storage@2"
            ]
        },
        {
            "x": 0,
            "y": 7,
            "z": 3,
            "elements": [
                "ic2:uu_matter@0"
            ]
        },
        {
            "x": -4,
            "y": 5,
            "z": 5,
            "elements": [
                "calculator:flawlessglass@0"
            ]
        },
        {
            "x": 3,
            "y": 0,
            "z": -5,
            "elements": [
                "extrautils2:decorativeglass@0"
            ]
        },
        {
            "x": 5,
            "y": 2,
            "z": 1,
            "elements": [
                "appliedenergistics2:chiseled_quartz_block@0"
            ]
        },
        {
            "x": -1,
            "y": 5,
            "z": -6,
            "elements": [
                "calculator:flawlessglass@0"
            ]
        },
        {
            "x": 1,
            "y": -2,
            "z": -5,
            "elements": [
                "modularmachinery:blockcasing@4"
            ]
        },
        {
            "x": -2,
            "y": 1,
            "z": 5,
            "elements": [
                "appliedenergistics2:quartz_pillar@1"
            ]
        },
        {
            "x": 6,
            "y": 3,
            "z": 3,
            "elements": [
                "botania:quartztypesunny@2"
            ]
        },
        {
            "x": -4,
            "y": -2,
            "z": -3,
            "elements": [
                "ic2:uu_matter@0"
            ]
        },
        {
            "x": 2,
            "y": 8,
            "z": 1,
            "elements": [
                "ic2:uu_matter@0"
            ]
        },
        {
            "x": -2,
            "y": 7,
            "z": 0,
            "elements": [
                "ic2:uu_matter@0"
            ]
        },
        {
            "x": -3,
            "y": 9,
            "z": 0,
            "elements": [
                "botania:quartzstairssunny@0"
            ]
        },
        {
            "x": -4,
            "y": 6,
            "z": -5,
            "elements": [
                "calculator:flawlessglass@0"
            ]
        },
        {
            "x": 7,
            "y": -2,
            "z": 1,
            "elements": [
                "appliedenergistics2:sky_stone_small_brick_stairs@1"
            ]
        },
        {
            "x": 2,
            "y": 7,
            "z": -6,
            "elements": [
                "botania:quartzslabsunnyhalf@0"
            ]
        },
        {
            "x": -1,
            "y": 2,
            "z": -5,
            "elements": [
                "appliedenergistics2:chiseled_quartz_block@0"
            ]
        },
        {
            "x": 5,
            "y": 5,
            "z": -4,
            "elements": [
                "calculator:flawlessglass@0"
            ]
        },
        {
            "x": -4,
            "y": 7,
            "z": 5,
            "elements": [
                "botania:quartzslabsunnyhalf@0"
            ]
        },
        {
            "x": -3,
            "y": 7,
            "z": 3,
            "elements": [
                "botania:quartzstairssunny@0"
            ]
        },
        {
            "x": -1,
            "y": -1,
            "z": 5,
            "elements": [
                "extrautils2:decorativeglass@0"
            ]
        },
        {
            "x": 2,
            "y": 6,
            "z": -6,
            "elements": [
                "calculator:flawlessglass@0"
            ]
        },
        {
            "x": 2,
            "y": 9,
            "z": 1,
            "elements": [
                "botania:quartztypesunny@1"
            ]
        },
        {
            "x": -5,
            "y": 5,
            "z": 0,
            "elements": [
                "modularmachinery:blockparallelcontroller"
            ]
        },
        {
            "x": -5,
            "y": 1,
            "z": 5,
            "elements": [
                "botania:quartztypesunny@2"
            ]
        },
        {
            "x": 4,
            "y": -2,
            "z": -5,
            "elements": [
                "appliedenergistics2:sky_stone_small_brick_stairs@2"
            ]
        },
        {
            "x": -2,
            "y": -2,
            "z": -6,
            "elements": [
                "appliedenergistics2:sky_stone_small_brick_stairs@0"
            ]
        },
        {
            "x": 2,
            "y": 10,
            "z": 1,
            "elements": [
                "botania:quartzslabsunnyhalf@0"
            ]
        },
        {
            "x": -1,
            "y": 6,
            "z": -5,
            "elements": [
                "minecraft:glowstone@0"
            ]
        },
        {
            "x": 2,
            "y": 4,
            "z": -5,
            "elements": [
                "appliedenergistics2:quartz_pillar@1"
            ]
        },
        {
            "x": 3,
            "y": 6,
            "z": 4,
            "elements": [
                "botania:quartzslabsunnyhalf@8"
            ]
        },
        {
            "x": 6,
            "y": 7,
            "z": 3,
            "elements": [
                "botania:quartztypesunny@2"
            ]
        },
        {
            "x": 5,
            "y": 0,
            "z": -5,
            "elements": [
                "botania:quartztypesunny@2"
            ]
        },
        {
            "x": 2,
            "y": 2,
            "z": -5,
            "elements": [
                "appliedenergistics2:quartz_pillar@1"
            ]
        },
        {
            "x": 0,
            "y": -2,
            "z": 6,
            "elements": [
                "appliedenergistics2:sky_stone_small_brick@0"
            ]
        },
        {
            "x": 2,
            "y": 6,
            "z": -3,
            "elements": [
                "botania:quartzslabsunnyhalf@8"
            ]
        },
        {
            "x": 5,
            "y": 6,
            "z": 1,
            "elements": [
                "minecraft:glowstone@0"
            ]
        },
        {
            "x": -3,
            "y": 3,
            "z": 5,
            "elements": [
                "appliedenergistics2:fluix_slab@0"
            ]
        },
        {
            "x": -5,
            "y": 7,
            "z": 0,
            "elements": [
                "botania:quartzstairssunny@0"
            ]
        },
        {
            "x": 0,
            "y": 1,
            "z": 5,
            "elements": [
                "extrautils2:decorativeglass@0"
            ]
        },
        {
            "x": -1,
            "y": -2,
            "z": -5,
            "elements": [
                "modularmachinery:blockcasing@4"
            ]
        },
        {
            "x": 5,
            "y": 7,
            "z": -4,
            "elements": [
                "botania:quartzslabsunnyhalf@0"
            ]
        },
        {
            "x": 1,
            "y": 4,
            "z": 6,
            "elements": [
                "calculator:flawlessglass@0"
            ]
        },
        {
            "x": 2,
            "y": 6,
            "z": -5,
            "elements": [
                "extendedcrafting:storage@1"
            ]
        },
        {
            "x": 2,
            "y": -2,
            "z": 4,
            "elements": [
                "modularmachinery:blockcasing@4"
            ]
        },
        {
            "x": 3,
            "y": -2,
            "z": 6,
            "elements": [
                "botania:quartztypesunny@2"
            ]
        },
        {
            "x": -6,
            "y": 4,
            "z": -3,
            "elements": [
                "botania:quartztypesunny@2"
            ]
        },
        {
            "x": -1,
            "y": 9,
            "z": 0,
            "elements": [
                "extendedcrafting:storage@2"
            ]
        },
        {
            "x": 4,
            "y": 2,
            "z": -5,
            "elements": [
                "botania:quartztypesunny@2"
            ]
        },
        {
            "x": 5,
            "y": 2,
            "z": -3,
            "elements": [
                "appliedenergistics2:chiseled_quartz_block@0"
            ]
        },
        {
            "x": -2,
            "y": 0,
            "z": -5,
            "elements": [
                "appliedenergistics2:quartz_pillar@1"
            ]
        },
        {
            "x": -4,
            "y": -1,
            "z": -4,
            "elements": [
                "extrautils2:decorativeglass@0"
            ]
        },
        {
            "x": 5,
            "y": -2,
            "z": 4,
            "elements": [
                "appliedenergistics2:sky_stone_small_brick_stairs@1"
            ]
        },
        {
            "x": 1,
            "y": -1,
            "z": 5,
            "elements": [
                "extrautils2:decorativeglass@0"
            ]
        },
        {
            "x": 3,
            "y": -1,
            "z": 6,
            "elements": [
                "botania:quartztypesunny@2"
            ]
        },
        {
            "x": 0,
            "y": 3,
            "z": 5,
            "elements": [
                "appliedenergistics2:fluix_slab@0"
            ]
        },
        {
            "x": 1,
            "y": 2,
            "z": 6,
            "elements": [
                "botania:quartztypesunny@2"
            ]
        },
        {
            "x": 1,
            "y": 6,
            "z": -5,
            "elements": [
                "minecraft:glowstone@0"
            ]
        },
        {
            "x": 2,
            "y": 8,
            "z": -3,
            "elements": [
                "botania:quartzstairssunny@2"
            ]
        },
        {
            "x": 1,
            "y": 5,
            "z": 6,
            "elements": [
                "calculator:flawlessglass@0"
            ]
        },
        {
            "x": 4,
            "y": 4,
            "z": -5,
            "elements": [
                "calculator:flawlessglass@0"
            ]
        },
        {
            "x": -3,
            "y": 6,
            "z": 4,
            "elements": [
                "botania:quartzslabsunnyhalf@8"
            ]
        },
        {
            "x": -6,
            "y": 2,
            "z": -3,
            "elements": [
                "botania:quartztypesunny@2"
            ]
        },
        {
            "x": -5,
            "y": 1,
            "z": 0,
            "elements": [
                "extrautils2:decorativeglass@0"
            ]
        },
        {
            "x": -2,
            "y": 7,
            "z": 6,
            "elements": [
                "botania:quartzslabsunnyhalf@0"
            ]
        },
        {
            "x": -5,
            "y": 3,
            "z": 0,
            "elements": [
                "appliedenergistics2:fluix_slab@0"
            ]
        },
        {
            "x": 0,
            "y": 5,
            "z": 5,
            "elements": [
                "modularmachinery:blockenergyinputhatch"
            ]
        },
        {
            "x": 1,
            "y": 3,
            "z": 6,
            "elements": [
                "calculator:flawlessglass@0"
            ]
        },
        {
            "x": -3,
            "y": 7,
            "z": 5,
            "elements": [
                "botania:quartzslabsunnyhalf@0"
            ]
        },
        {
            "x": -2,
            "y": 6,
            "z": 6,
            "elements": [
                "calculator:flawlessglass@0"
            ]
        },
        {
            "x": -3,
            "y": -2,
            "z": -5,
            "elements": [
                "appliedenergistics2:sky_stone_small_brick@0"
            ]
        },
        {
            "x": 2,
            "y": 1,
            "z": 5,
            "elements": [
                "appliedenergistics2:quartz_pillar@1"
            ]
        },
        {
            "x": -1,
            "y": 3,
            "z": 5,
            "elements": [
                "appliedenergistics2:fluix_slab@0"
            ]
        },
        {
            "x": -6,
            "y": 0,
            "z": -3,
            "elements": [
                "botania:quartztypesunny@2"
            ]
        },
        {
            "x": 5,
            "y": -1,
            "z": 3,
            "elements": [
                "extrautils2:decorativeglass@0"
            ]
        },
        {
            "x": -4,
